Workbook

Sheet Intro
A1: ="Broker Fung is pleased to present the reinsurance underwriting information for the Insurer Atlanta Umbrella XOL reinsurance program effective "&TEXT(C7,"mm/dd/yyyy") -> Broker Fung is pleased to present the reinsurance underwriting information for the Insurer Atlanta Umbrella XOL reinsurance program effective 04/01/2024
A2: In recent years we have already seen meaningful improvements such as:
A5: Umbrella XOL Structure
A6: Basis: | B6: ="Risk attaching, new & renewal policies on or after "&TEXT(C7,"Mmmm dd, yyyy") -> Risk attaching, new & renewal policies on or after April 01, 2024
A7: Term: | B7: From | C7: 45383 | D7: To | E7: 45747
A8: ="Estimated " &TEXT(C7,"yyyy")& " Subject Written Premium" -> Estimated 2024 Subject Written Premium
A9: Retention & Limit: | B9: $10,000,000 xs $1,000,000
A10: Reinstatements: | B10: 1 free; 1 @ 100%
A11: Commission | B11: 10% broker B; 5% on reinstatements
A13: Sublines
A14: Subline 1 | B14: Retail / Main Street Commercial Umbrella
A15: Subline 2 | B15: Middle Market Umbrella
A16: Subline 3 | B16: Wholesale / E&S Umbrella

Sheet WP by State & Segment
A1: Insurer NJ Umbrella
A2: Umbrella Excess of Loss reinsurance program
A3: ="Effective: "&TEXT(Intro!C7,"mm/dd/yyyy") -> Effective: 04/01/2024
A4: Data as of: 11/30/2023
A6: Combined Umbrella Historical Written premium by state
A7: State | B7: 2015 | C7: =B7+1 -> 2016 | D7: =C7+1 -> 2017 | E7: =D7+1 -> 2018 | F7: =E7+1 -> 2019 | G7: =F7+1 -> 2020 | H7: =G7+1 -> 2021 | I7: =H7+1 -> 2022 | J7: =I7+1 -> 2023 | K7: Proj. 4/1/24- 3/31/25
A8: AK | B8: =SUM(B64,B174) -> 202670.72 | C8: =SUM(C64,C174) -> 197484.4 | D8: =SUM(D64,D174) -> 278329.95 | E8: =SUM(E64,E174) -> 305492.64 | F8: =SUM(F64,F174) -> 272018.88 | G8: =SUM(G64,G174,B119) -> 306806.3 | H8: =SUM(H64,H174,C119) -> 297071.46 | I8: =SUM(I64,I174,D119) -> 234937.61 | J8: =SUM(J64,J174,E119) -> 208000.98 | K8: =SUM(K64,K174,F119) -> 255652.17
A9: AL | B9: =SUM(B65,B175) -> 448096.76 | C9: =SUM(C65,C175) -> 641171.82 | D9: =SUM(D65,D175) -> 841090.83 | E9: =SUM(E65,E175) -> 824854.35 | F9: =SUM(F65,F175) -> 916249.98 | G9: =SUM(G65,G175,B120) -> 1134607.5 | H9: =SUM(H65,H175,C120) -> 1376366 | I9: =SUM(I65,I175,D120) -> 1506360.9 | J9: =SUM(J65,J175,E120) -> 1527112.5 | K9: =SUM(K65,K175,F120) -> 1739478.3
A10: AR | B10: =SUM(B66,B176) -> 181776.68 | C10: =SUM(C66,C176) -> 362160.89 | D10: =SUM(D66,D176) -> 476830.45 | E10: =SUM(E66,E176) -> 443318.15 | F10: =SUM(F66,F176) -> 483748.05 | G10: =SUM(G66,G176,B121) -> 805158.53 | H10: =SUM(H66,H176,C121) -> 957309.59 | I10: =SUM(I66,I176,D121) -> 955929.14 | J10: =SUM(J66,J176,E121) -> 1051410.7 | K10: =SUM(K66,K176,F121) -> 1154087
A11: AZ | B11: =SUM(B67,B177) -> 791136.72 | C11: =SUM(C67,C177) -> 1077785 | D11: =SUM(D67,D177) -> 1383698.5 | E11: =SUM(E67,E177) -> 1576676.3 | F11: =SUM(F67,F177) -> 1829193.1 | G11: =SUM(G67,G177,B122) -> 2585739.5 | H11: =SUM(H67,H177,C122) -> 3199389.4 | I11: =SUM(I67,I177,D122) -> 3484619.9 | J11: =SUM(J67,J177,E122) -> 3410223.9 | K11: =SUM(K67,K177,F122) -> 3824347.8
A12: CA | B12: =SUM(B68,B178) -> 6303495.8 | C12: =SUM(C68,C178) -> 7965531.5 | D12: =SUM(D68,D178) -> 10416892 | E12: =SUM(E68,E178) -> 11125429 | F12: =SUM(F68,F178) -> 12108454 | G12: =SUM(G68,G178,B123) -> 17154394 | H12: =SUM(H68,H178,C123) -> 19964095 | I12: =SUM(I68,I178,D123) -> 21768814 | J12: =SUM(J68,J178,E123) -> 22450603 | K12: =SUM(K68,K178,F123) -> 24831652
A13: CO | B13: =SUM(B69,B179) -> 826818.85 | C13: =SUM(C69,C179) -> 1136205.9 | D13: =SUM(D69,D179) -> 1306906.1 | E13: =SUM(E69,E179) -> 1553652.1 | F13: =SUM(F69,F179) -> 1739389.4 | G13: =SUM(G69,G179,B124) -> 2511389 | H13: =SUM(H69,H179,C124) -> 2852935.4 | I13: =SUM(I69,I179,D124) -> 3092430.2 | J13: =SUM(J69,J179,E124) -> 3143237.4 | K13: =SUM(K69,K179,F124) -> 3531130.4
A14: CT | B14: =SUM(B70,B180) -> 571092.54 | C14: =SUM(C70,C180) -> 780266.05 | D14: =SUM(D70,D180) -> 852101.04 | E14: =SUM(E70,E180) -> 909670.56 | F14: =SUM(F70,F180) -> 1014022.5 | G14: =SUM(G70,G180,B125) -> 1494251.3 | H14: =SUM(H70,H180,C125) -> 2040745.9 | I14: =SUM(I70,I180,D125) -> 2137153.4 | J14: =SUM(J70,J180,E125) -> 2273772.7 | K14: =SUM(K70,K180,F125) -> 2505391.3
A15: DC | B15: =SUM(B71,B181) -> 151727.01 | C15: =SUM(C71,C181) -> 119397.73 | D15: =SUM(D71,D181) -> 225936.57 | E15: =SUM(E71,E181) -> 188357.84 | F15: =SUM(F71,F181) -> 183562.93 | G15: =SUM(G71,G181,B126) -> 170594.68 | H15: =SUM(H71,H181,C126) -> 201956.06 | I15: =SUM(I71,I181,D126) -> 274899.87 | J15: =SUM(J71,J181,E126) -> 234419.22 | K15: =SUM(K71,K181,F126) -> 278608.7
A16: DE | B16: =SUM(B72,B182) -> 133303.67 | C16: =SUM(C72,C182) -> 172794.19 | D16: =SUM(D72,D182) -> 193373.65 | E16: =SUM(E72,E182) -> 192070.66 | F16: =SUM(F72,F182) -> 155056.2 | G16: =SUM(G72,G182,B127) -> 322915.08 | H16: =SUM(H72,H182,C127) -> 480583.16 | I16: =SUM(I72,I182,D127) -> 589983.39 | J16: =SUM(J72,J182,E127) -> 616259.19 | K16: =SUM(K72,K182,F127) -> 673043.48
A17: FL | B17: =SUM(B73,B183) -> 2316456.2 | C17: =SUM(C73,C183) -> 2999804.5 | D17: =SUM(D73,D183) -> 3509335.6 | E17: =SUM(E73,E183) -> 4159217.4 | F17: =SUM(F73,F183) -> 4168947 | G17: =SUM(G73,G183,B128) -> 6217568.1 | H17: =SUM(H73,H183,C128) -> 7289144.1 | I17: =SUM(I73,I183,D128) -> 7620754.1 | J17: =SUM(J73,J183,E128) -> 8048288 | K17: =SUM(K73,K183,F128) -> 8809043.5
A18: GA | B18: =SUM(B74,B184) -> 1434537.9 | C18: =SUM(C74,C184) -> 1623644.3 | D18: =SUM(D74,D184) -> 2146649.4 | E18: =SUM(E74,E184) -> 2450324.8 | F18: =SUM(F74,F184) -> 2523648.7 | G18: =SUM(G74,G184,B129) -> 3706495.5 | H18: =SUM(H74,H184,C129) -> 4460529.5 | I18: =SUM(I74,I184,D129) -> 5392787.4 | J18: =SUM(J74,J184,E129) -> 5404187.4 | K18: =SUM(K74,K184,F129) -> 6169043.5
A19: IA | B19: =SUM(B75,B185) -> 359973.51 | C19: =SUM(C75,C185) -> 495843.13 | D19: =SUM(D75,D185) -> 553799.29 | E19: =SUM(E75,E185) -> 733130.47 | F19: =SUM(F75,F185) -> 778627.29 | G19: =SUM(G75,G185,B130) -> 1078901.2 | H19: =SUM(H75,H185,C130) -> 1367024.7 | I19: =SUM(I75,I185,D130) -> 1445144.7 | J19: =SUM(J75,J185,E130) -> 1446283.4 | K19: =SUM(K75,K185,F130) -> 1632000
... A57: WY | B57: =SUM(B113,B223) -> 118480.17 | C57: =SUM(C113,C223) -> 177218.79 | D57: =SUM(D113,D223) -> 229088.26 | E57: =SUM(E113,E223) -> 223730.38 | F57: =SUM(F113,F223) -> 207010.51 | G57: =SUM(G113,G223,B168) -> 272353.32 | H57: =SUM(H113,H223,C168) -> 342720.81 | I57: =SUM(I113,I223,D168) -> 348614.76 | J57: =SUM(J113,J223,E168) -> 152678.69 | K57: =SUM(K113,K223,F168) -> 282782.61
A58: Total | B58: =SUM(B8:B57) -> 45499723 | C58: =SUM(C8:C57) -> 57404039 | D58: =SUM(D8:D57) -> 70594349 | E58: =SUM(E8:E57) -> 76839973 | F58: =SUM(F8:F57) -> 81966721 | G58: =SUM(G8:G57) -> 1.1520695e+08 | H58: =SUM(H8:H57) -> 1.3821272e+08 | I58: =SUM(I8:I57) -> 1.5048663e+08 | ... K58: =SUM(K8:K57) -> 1.7258191e+08
A60: (1) Premium is by Calendar Year unless stated
A62: Legacy Subline1 Historical Written Premium by State
A63: State | B63: 2015 | C63: =B63+1 -> 2016 | D63: =C63+1 -> 2017 | E63: =D63+1 -> 2018 | F63: =E63+1 -> 2019 | G63: =F63+1 -> 2020 | H63: =G63+1 -> 2021 | I63: =H63+1 -> 2022 | J63: =I63+1 -> 2023 | K63: =K7 -> Proj. 4/1/24- 3/31/25
A64: AK | B64: 174499.16 | C64: 149515.02 | D64: 165500.49 | E64: 177016.98 | F64: 174765.33 | G64: 113472.37 | H64: 127568.6 | I64: 63166.87 | J64: 77106.7 | K64: 77217.391
A65: AL | B65: 330234.25 | C65: 298900.22 | D65: 366308.09 | E65: 389495.73 | F65: 392553.06 | G65: 503271.07 | H65: 465264.08 | I65: 365791.45 | J65: 368747.29 | K65: 400695.65
A66: AR | B66: 88154.57 | C66: 144432.03 | D66: 200546.76 | E66: 176390.05 | F66: 191990.4 | G66: 416198.15 | H66: 412717.25 | I66: 319798.17 | J66: 362866.89 | K66: 374608.7
A67: AZ | B67: 516312.88 | C67: 500923.74 | D67: 782261.06 | E67: 941062.58 | F67: 1095115.8 | G67: 1352301.9 | H67: 1481391.6 | I67: 1504443.3 | J67: 1595636.3 | K67: 1647652.2
A68: CA | B68: 4757162.6 | C68: 4629743.1 | D68: 6427005.5 | E68: 6687595.8 | F68: 7276359.8 | G68: 9390488.7 | H68: 9349059.7 | I68: 8786450.2 | J68: 9541481.4 | K68: 9938087
A69: CO | B69: 537467.28 | C69: 633920.28 | D69: 731576.44 | E69: 819183.18 | F69: 910972.22 | G69: 1287202.9 | H69: 1326518 | I69: 1305632.1 | J69: 1347898.3 | K69: 1452521.7
A70: CT | B70: 350032.48 | C70: 324355.63 | D70: 435006.95 | E70: 479178.15 | F70: 636440.69 | G70: 778852.9 | H70: 929833.83 | I70: 960973.16 | J70: 983586.64 | K70: 1077913
A71: DC | B71: 113736.58 | C71: 45433.63 | D71: 124268.19 | E71: 124137.33 | F71: 126487.56 | G71: 95529.94 | H71: 118577.04 | I71: 153389.36 | J71: 147854.87 | K71: 161739.13
A72: DE | B72: 72072.05 | C72: 96188.42 | D72: 147985.78 | E72: 103739.82 | F72: 74415.77 | G72: 153520.61 | H72: 233921.17 | I72: 325733.17 | J72: 328947.27 | K72: 356869.57
A73: FL | B73: 1651382.6 | C73: 1544385 | D73: 1876206.6 | E73: 2220157 | F73: 2088281.3 | G73: 2919685.2 | H73: 2908710 | I73: 2769426.5 | J73: 3142051 | K73: 3269217.4
A74: GA | B74: 1051859.5 | C74: 958020.72 | D74: 1318955.6 | E74: 1461936.6 | F74: 1409492.5 | G74: 1779483.4 | H74: 1751606.7 | I74: 1736195.7 | J74: 1715788.6 | K74: 1902260.9
A75: IA | B75: 313600.45 | C75: 359852.72 | D75: 357430.1 | E75: 439741.65 | F75: 392351.58 | G75: 495241.49 | H75: 493491.9 | I75: 508627 | J75: 551372.11 | K75: 574956.52
... A113: WY | B113: 86856.04 | C113: 103598.98 | D113: 129698.8 | E113: 137387.41 | F113: 118936.56 | G113: 150452.08 | H113: 164577.83 | I113: 152392.81 | J113: 41650.09 | K113: 104347.83
A114: Total | B114: =SUM(B64:B113) -> 32646705 | C114: =SUM(C64:C113) -> 31260789 | D114: =SUM(D64:D113) -> 39880999 | E114: =SUM(E64:E113) -> 43025171 | F114: =SUM(F64:F113) -> 45283999 | G114: =SUM(G64:G113) -> 57797907 | H114: =SUM(H64:H113) -> 59077407 | I114: =SUM(I64:I113) -> 55810174 | ... K114: =SUM(K64:K113) -> 64515130
A115: (1) Premium is by Calendar Year unless stated
A117: subline2 Historical Written Premium by State
A118: State | B118: 2020 | C118: 2021 | D118: 2022 | E118: =D118+1 -> 2023 | F118: =K63 -> Proj. 4/1/24- 3/31/25
...

Sheet Large Claims (subline 1)
A1: ='WP by State & Segment'!A1 -> Insurer NJ Umbrella
A2: ='WP by State & Segment'!A2 -> Umbrella Excess of Loss reinsurance program
A3: ='WP by State & Segment'!A3 -> Effective: 04/01/2024
A4: ='WP by State & Segment'!A4 -> Data as of: 11/30/2023
A6: Subline1 Claims - Risks Attaching
A7: Claim Number | B7: Policy Number | C7: Company Name | D7: Claim Status | E7: Policy Eff Date | F7: Loss State | G7: Umbrella Limit | H7: Accident Date | I7: Accident Year | J7: ANO | K7: DCC | L7: Paid Loss | M7: Reserve Change | N7: Total Incurred | O7: Describtion
A8: C1--00436 | B8: P18-1-00715 | C8: 18-1-00110 | D8: Closed | E8: 43189 | F8: CA | G8: 1000000 | H8: 43476 | I8: 2019 | J8: 2887.1456 | K8: 10595.104 | L8: 92217.56 | M8: 0 | N8: 105699.81 | O8: Severe TBI allegation; future care demanded
A9: C1--00437 | B9: P18-1-02463 | C9: 15-1-02006 | D9: Closed | E9: 43402 | F9: TX | G9: 5000000 | H9: 43470 | I9: 2019 | J9: 52398.253 | K9: 132229.38 | L9: 644894.14 | M9: 0 | N9: 829521.77 | O9: Umbrella fully exposed; global settlement talks
A10: C1--00440 | B10: P18-1-01061 | C10: 15-1-00825 | D10: Closed | E10: 43231 | F10: CA | G10: 3000000 | H10: 43483 | I10: 2019 | J10: 5697.6917 | K10: 20374.428 | L10: 88081.14 | M10: 0 | N10: 114153.26 | O10: Multiple claimants; event liability; defense escalating
A11: C1--00452 | B11: P19-1-00025 | C11: 19-1-00005 | D11: Closed | E11: 43469 | F11: CT | G11: 1000000 | H11: 43508 | I11: 2019 | J11: 5426.13 | K11: 17867.11 | L11: 136294.27 | M11: 0 | N11: 159587.51 | O11: Permanent paralysis claim; life care plan presented
A12: C1--00453 | B12: P18-1-00722 | C12: 16-1-00092 | D12: Closed | E12: 43189 | F12: IL | G12: 1000000 | H12: 43477 | I12: 2019 | J12: 8909.95 | K12: 30440.68 | L12: 242341.53 | M12: 0 | N12: 281692.16 | O12: Multiple wrongful deaths; consolidated actions filed
A13: C1--00454 | B13: P18-1-02225 | C13: 18-1-00354 | D13: Closed | E13: 43374 | F13: VA | G13: 5000000 | H13: 43510 | I13: 2019 | J13: 56504.768 | K13: 161313.78 | L13: 1282992.6 | M13: 0 | N13: 1500811.2 | O13: Global resolution; umbrella exhausted; final settlement
A14: C1--00455 | B14: P18-1-00605 | C14: 17-1-00199 | D14: Closed | E14: 43175 | F14: TX | G14: 3000000 | H14: 43474 | I14: 2019 | J14: 6444.6443 | K14: 18116.766 | L14: 113088.32 | M14: 0 | N14: 137649.73 | O14: Amputation allegation; equipment guarding failure claimed
A15: C1--00458 | B15: P18-1-00363 | C15: 17-1-00123 | D15: Closed | E15: 43145 | F15: IA | G15: 2000000 | H15: 43500 | I15: 2019 | J15: 2433.5113 | K15: 5824.6987 | L15: 54840.98 | M15: 0 | N15: 63099.19 | O15: Auto in lot hit pedestrian; severe leg injury
A16: C1--00460 | B16: P18-1-02781 | C16: 15-1-02267 | D16: Closed | E16: 43439 | F16: FL | G16: 10000000 | H16: 43491 | I16: 2019 | J16: 60232.865 | K16: 199993.89 | L16: 1049079.1 | M16: 0 | N16: 1309305.8 | O16: Nuclear verdict risk; punitive plus catastrophics
A17: C1--00461 | B17: P19-1-00207 | C17: 15-1-00164 | D17: Closed | E17: 43491 | F17: CA | G17: 3000000 | H17: 43517 | I17: 2019 | J17: 4069.423 | K17: 10677.137 | L17: 84284.86 | M17: 0 | N17: 99031.42 | O17: Multiple claimants; event liability; defense escalating
A18: C1--00464 | B18: P18-1-00172 | C18: 17-1-00060 | D18: Closed | E18: 43122 | F18: CA | G18: 3000000 | H18: 43470 | I18: 2019 | J18: 2408.8942 | K18: 5944.8958 | L18: 61317.75 | M18: 0 | N18: 69671.54 | O18: Premises fire; severe burns; liability alleged
A19: C1--00465 | B19: P18-1-01670 | C19: 15-1-01343 | D19: Closed | E19: 43305 | F19: NY | G19: 5000000 | H19: 43492 | I19: 2019 | J19: 7391.3287 | K19: 24362.881 | L19: 132401.04 | M19: 0 | N19: 164155.25 | O19: Permanent paralysis claim; life care plan presented
... A461: C1--01321 | B461: P23-1-01168 | C461: 20-1-00328 | D461: Open | E461: 45031 | F461: TN | G461: 5000000 | H461: 45227 | I461: 2023 | J461: 0 | K461: 0 | L461: 0 | M461: 409893.72 | N461: 409893.72 | O461: Catastrophic TBI; guardianship; large lien stack

Sheet Large Claims (subline 2)
A1: ='WP by State & Segment'!A1 -> Insurer NJ Umbrella
A2: ='WP by State & Segment'!A2 -> Umbrella Excess of Loss reinsurance program
A3: ='WP by State & Segment'!A3 -> Effective: 04/01/2024
A4: ='WP by State & Segment'!A4 -> Data as of: 11/30/2023
A6: Subline2 Claims - Risks Attaching
A7: Claim Number | B7: Policy Number | C7: Company Name | D7: Claim Status | E7: Policy Eff Date | F7: Loss State | G7: Umbrella Limit | H7: Accident Date | I7: Accident Year | J7: ANO | K7: DCC | L7: Paid Loss | M7: Reserve Change | N7: Total Incurred | O7: Describtion
A8: C1--00005 | B8: P20-2-00035 | C8: 20-2-00035 | D8: Closed | E8: 43841 | F8: IL | G8: 1000000 | H8: 43999 | I8: 2020 | J8: 2714.1466 | K8: 8046.8434 | L8: 71539.53 | M8: 0 | N8: 82300.52 | O8: Product liability; high-venue counsel; trial set
A9: C1--00006 | B9: P20-2-00146 | C9: 20-2-00146 | D9: Closed | E9: 43868 | F9: UT | G9: 1000000 | H9: 44018 | I9: 2020 | J9: 3735.6033 | K9: 13809.577 | L9: 84563.23 | M9: 0 | N9: 102108.41 | O9: Punitive damages sought; internal emails produced
A10: C1--00007 | B10: P20-2-00217 | C10: 20-2-00217 | D10: Closed | E10: 43883 | F10: MI | G10: 5000000 | H10: 44034 | I10: 2020 | J10: 2156.7921 | K10: 7579.1379 | L10: 80104.96 | M10: 0 | N10: 89840.89 | O10: Reptile theory; corporate safety indifference alleged
A11: C1--00009 | B11: P20-2-00744 | C11: 20-2-00744 | D11: Closed | E11: 44007 | F11: FL | G11: 1000000 | H11: 44031 | I11: 2020 | J11: 4039.2198 | K11: 9673.9002 | L11: 120166.86 | M11: 0 | N11: 133879.98 | O11: Mass tort counsel; coordinated litigation filed
A12: C1--00010 | B12: P20-2-00422 | C12: 20-2-00422 | D12: Closed | E12: 43932 | F12: IN | G12: 1000000 | H12: 43960 | I12: 2020 | J12: 3224.8394 | K12: 7555.9506 | L12: 58734.46 | M12: 0 | N12: 69515.25 | O12: Wrongful death; negligent security; punitive demand
A13: C1--00011 | B13: P20-2-00546 | C13: 20-2-00546 | D13: Closed | E13: 43962 | F13: FL | G13: 1000000 | H13: 43977 | I13: 2020 | J13: 7922.3268 | K13: 20821.563 | L13: 102224.33 | M13: 0 | N13: 130968.22 | O13: Venue unfavorable; nuclear verdict risk flagged
A14: C1--00013 | B14: P20-2-00236 | C14: 20-2-00236 | D14: Closed | E14: 43887 | F14: NC | G14: 1000000 | H14: 44061 | I14: 2020 | J14: 4413.1164 | K14: 12768.074 | L14: 130137.98 | M14: 0 | N14: 147319.17 | O14: Mass tort counsel; coordinated litigation filed
A15: C1--00020 | B15: P20-2-00180 | C15: 20-2-00180 | D15: Closed | E15: 43876 | F15: DC | G15: 1000000 | H15: 44086 | I15: 2020 | J15: 8855.2641 | K15: 29379.906 | L15: 136157.35 | M15: 0 | N15: 174392.52 | O15: Catastrophic burn injury; long-term disability claimed
A16: C1--00021 | B16: P20-2-00124 | C16: 20-2-00124 | D16: Open | E16: 43864 | F16: PA | G16: 1000000 | H16: 44121 | I16: 2020 | J16: 4898.4862 | K16: 12192.794 | L16: 86448.08 | M16: 9225.25 | N16: 112764.61 | O16: Time-limit demand; excess exposure; mediation failed
A17: C1--00022 | B17: P20-2-00027 | C17: 20-2-00027 | D17: Closed | E17: 43839 | F17: NY | G17: 5000000 | H17: 44119 | I17: 2020 | J17: 23021.693 | K17: 60695.667 | L17: 325236.16 | M17: 0 | N17: 408953.52 | O17: Severe disfigurement; emotional distress claims added
A18: C1--00026 | B18: P20-2-00106 | C18: 20-2-00106 | D18: Closed | E18: 43859 | F18: AL | G18: 5000000 | H18: 44141 | I18: 2020 | J18: 7862.1025 | K18: 19487.788 | L18: 99973.07 | M18: 0 | N18: 127322.96 | O18: Venue unfavorable; nuclear verdict risk flagged
A19: C1--00027 | B19: P20-2-00570 | C19: 20-2-00570 | D19: Closed | E19: 43968 | F19: IL | G19: 1000000 | H19: 44171 | I19: 2020 | J19: 32263.938 | K19: 78408.212 | L19: 483876.28 | M19: 0 | N19: 594548.43 | O19: Catastrophic spinal injury; lifetime care; high demand
... A196: C1--00471 | B196: P23-2-00449 | C196: 23-2-00088 | D196: Open | E196: 44978 | F196: AR | G196: 1000000 | H196: 45202 | I196: 2023 | J196: 0 | K196: 0 | L196: 0 | M196: 39503.92 | N196: 39503.92 | O196: Product liability; high-venue counsel; trial set

Sheet Large Claims (subline 3)
A1: ='WP by State & Segment'!A1 -> Insurer NJ Umbrella
A2: ='WP by State & Segment'!A2 -> Umbrella Excess of Loss reinsurance program
A3: ='WP by State & Segment'!A3 -> Effective: 04/01/2024
A4: ='WP by State & Segment'!A4 -> Data as of: 11/30/2023
A6: Subline3 Claims - Risks Attaching
A7: Claim Number | B7: Policy Number | C7: Company Name | D7: Claim Status | E7: Policy Eff Date | F7: Loss State | G7: Umbrella Limit | H7: Accident Date | I7: Accident Year | J7: ANO | K7: DCC | L7: Paid Loss | M7: Reserve Change | N7: Total Incurred | O7: Describtion
A8: C1--00001 | B8: P20-3-00540 | C8: 17-3-00111 | D8: Closed | E8: 43899 | F8: DE | G8: 1000000 | H8: 43907 | I8: 2020 | J8: 10096.956 | K8: 29868.914 | L8: 159638.97 | M8: 0 | N8: 199604.84 | O8: Multiple catastrophics; layered limits threatened
A9: C1--00002 | B9: P20-3-00436 | C9: 15-3-00169 | D9: Closed | E9: 43886 | F9: AR | G9: 5000000 | H9: 43912 | I9: 2020 | J9: 30636.645 | K9: 88198.255 | L9: 430255.59 | M9: 0 | N9: 549090.49 | O9: Global settlement talks; layers near exhaustion
A10: C1--00009 | B10: P20-3-00618 | C10: 20-3-00136 | D10: Closed | E10: 43908 | F10: WA | G10: 5000000 | H10: 43948 | I10: 2020 | J10: 16810.592 | K10: 66003.638 | L10: 386366.12 | M10: 0 | N10: 469180.35 | O10: Global settlement talks; layers near exhaustion
A11: C1--00010 | B11: P20-3-00751 | C11: 19-3-00161 | D11: Closed | E11: 43924 | F11: CA | G11: 5000000 | H11: 44017 | I11: 2020 | J11: 12802.058 | K11: 39406.212 | L11: 324112.21 | M11: 0 | N11: 376320.48 | O11: Nuclear verdict risk; punitive plus catastrophics
A12: C1--00012 | B12: P20-3-01673 | C12: 17-3-00346 | D12: Closed | E12: 44033 | F12: CA | G12: 10000000 | H12: 44041 | I12: 2020 | J12: 15267.034 | K12: 56796.146 | L12: 270099.24 | M12: 0 | N12: 342162.42 | O12: Excess layers exposed; structured settlement discussed
A13: C1--00014 | B13: P20-3-01676 | C13: 20-3-00372 | D13: Closed | E13: 44034 | F13: NJ | G13: 4000000 | H13: 44036 | I13: 2020 | J13: 6290.4679 | K13: 17933.142 | L13: 227146.3 | M13: 0 | N13: 251369.91 | O13: Catastrophic brain injury; guardianship; liens escalating
A14: C1--00019 | B14: P20-3-00853 | C14: 18-3-00144 | D14: Closed | E14: 43936 | F14: TX | G14: 5000000 | H14: 44077 | I14: 2020 | J14: 6008.4775 | K14: 19198.562 | L14: 92216.3 | M14: 0 | N14: 117423.34 | O14: Multi-fatality incident; consolidated litigation filed
A15: C1--00025 | B15: P20-3-01512 | C15: 20-3-00338 | D15: Closed | E15: 44015 | F15: WA | G15: 4000000 | H15: 44116 | I15: 2020 | J15: 7257.7601 | K15: 21027.12 | L15: 97967.47 | M15: 0 | N15: 126252.35 | O15: Mass tort counsel engaged; coordinated discovery ordered
A16: C1--00029 | B16: P20-3-00166 | C16: 20-3-00038 | D16: Closed | E16: 43854 | F16: GA | G16: 2000000 | H16: 44143 | I16: 2020 | J16: 12422.745 | K16: 34560.995 | L16: 285938.93 | M16: 0 | N16: 332922.67 | O16: Excess layers exposed; structured settlement discussed
A17: C1--00031 | B17: P20-3-02522 | C17: 19-3-00484 | D17: Closed | E17: 44143 | F17: CA | G17: 2000000 | H17: 44156 | I17: 2020 | J17: 2635.0159 | K17: 9547.7541 | L17: 115145.07 | M17: 0 | N17: 127327.84 | O17: Punitive damages sought; bad facts; trial set
A18: C1--00032 | B18: P20-3-02021 | C18: 20-3-00446 | D18: Closed | E18: 44075 | F18: CA | G18: 2000000 | H18: 44175 | I18: 2020 | J18: 6612.1141 | K18: 21342.956 | L18: 123902.58 | M18: 0 | N18: 151857.65 | O18: Time-limit demand; excess exposure; mediation failed
A19: C1--00033 | B19: P20-3-01697 | C19: 19-3-00328 | D19: Closed | E19: 44036 | F19: IN | G19: 1000000 | H19: 44073 | I19: 2020 | J19: 22613.211 | K19: 61668.709 | L19: 364109.46 | M19: 0 | N19: 448391.38 | O19: Global settlement talks; layers near exhaustion
... A243: C1--00477 | B243: P22-3-02858 | C243: 20-3-00602 | D243: Open | E243: 44898 | F243: NV | G243: 5000000 | H243: 45210 | I243: 2023 | J243: 0 | K243: 0 | L243: 0 | M243: 280334.84 | N243: 280334.84 | O243: Excess layers exposed; structured settlement discussed

Sheet Rate Change (subline 1)
A1: ='WP by State & Segment'!A1 -> Insurer NJ Umbrella
A2: ='WP by State & Segment'!A2 -> Umbrella Excess of Loss reinsurance program
A3: ='WP by State & Segment'!A3 -> Effective: 04/01/2024
A4: ='WP by State & Segment'!A4 -> Data as of: 11/30/2023
A6: Subline1 Historical Rate Action by State & Product
C7: Rate change (%)
A8: State | B8: Year | C8: New business | D8: renewal business | E8: Combined
A9: AK | B9: 2015 | C9: 5.8 | D9: 2.8 | E9: 3.5
A10: AL | B10: 2015 | C10: 5.7 | D10: 2.6 | E10: 3.4
A11: AR | B11: 2015 | C11: 8.6 | D11: 5.5 | E11: 6.5
A12: AZ | B12: 2015 | C12: 8.8 | D12: 5.7 | E12: 6.6
A13: CA | B13: 2015 | C13: 8.5 | D13: 5.5 | E13: 6.7
A14: CO | B14: 2015 | C14: 8.5 | D14: 5.5 | E14: 6.5
A15: CT | B15: 2015 | C15: 7.1 | D15: 4.1 | E15: 4.9
A16: DC | B16: 2015 | C16: 8.7 | D16: 5.7 | E16: 6.4
A17: DE | B17: 2015 | C17: 8.7 | D17: 5.6 | E17: 6.2
A18: FL | B18: 2015 | C18: 7.2 | D18: 4.1 | E18: 4.8
A19: GA | B19: 2015 | C19: 5.5 | D19: 2.5 | E19: 3.1
A20: IA | B20: 2015 | C20: 7.6 | D20: 4.5 | E20: 5.5
... A458: WY | B458: 2023 | C458: 7.6 | D458: 5.3 | E458: 6.1

Sheet Rate Change (subline 2)
A1: ='WP by State & Segment'!A1 -> Insurer NJ Umbrella
A2: ='WP by State & Segment'!A2 -> Umbrella Excess of Loss reinsurance program
A3: ='WP by State & Segment'!A3 -> Effective: 04/01/2024
A4: ='WP by State & Segment'!A4 -> Data as of: 11/30/2023
A6: Subline2 Historical Rate Action by State & Product
C7: Rate change (%)
A8: State | B8: Year | C8: New business | D8: renewal business | E8: Combined
A9: AK | B9: 2015 | C9: 3.4 | D9: 2.9 | E9: 3.1
A10: AL | B10: 2015 | C10: 5.3 | D10: 4.9 | E10: 5
A11: AR | B11: 2015 | C11: 5.6 | D11: 5.1 | E11: 5.3
A12: AZ | B12: 2015 | C12: 2.3 | D12: 1.8 | E12: 1.9
A13: CA | B13: 2015 | C13: 1.1 | D13: 0.6 | E13: 0.7
A14: CO | B14: 2015 | C14: 3.7 | D14: 3.2 | E14: 3.4
A15: CT | B15: 2015 | C15: 4.7 | D15: 4.2 | E15: 4.3
A16: DC | B16: 2015 | C16: 2.5 | D16: 2 | E16: 2.2
A17: DE | B17: 2015 | C17: 3.2 | D17: 2.7 | E17: 2.9
A18: FL | B18: 2015 | C18: 0.3 | D18: -0.2 | E18: 0
A19: GA | B19: 2015 | C19: 5.9 | D19: 5.4 | E19: 5.5
A20: IA | B20: 2015 | C20: 4 | D20: 3.5 | E20: 3.6
... A458: WY | B458: 2023 | C458: 3.8 | D458: 3.7 | E458: 3.7

Sheet Rate Change (subline 3)
A1: ='WP by State & Segment'!A1 -> Insurer NJ Umbrella
A2: ='WP by State & Segment'!A2 -> Umbrella Excess of Loss reinsurance program
A3: ='WP by State & Segment'!A3 -> Effective: 04/01/2024
A4: ='WP by State & Segment'!A4 -> Data as of: 11/30/2023
A6: Subline3 Historical Rate Action by State & Product
C7: Rate change (%)
A8: State | B8: Year | C8: New business | D8: renewal business | E8: Combined
A9: AK | B9: 2015 | C9: 9.3 | D9: 5.9 | E9: 6.8
A10: AL | B10: 2015 | C10: 11 | D10: 7.7 | E10: 8.5
A11: AR | B11: 2015 | C11: 7.9 | D11: 4.5 | E11: 5.6
A12: AZ | B12: 2015 | C12: 7.1 | D12: 3.8 | E12: 5
A13: CA | B13: 2015 | C13: 9.9 | D13: 6.6 | E13: 7.4
A14: CO | B14: 2015 | C14: 10.5 | D14: 7.1 | E14: 8.1
A15: CT | B15: 2015 | C15: 10.9 | D15: 7.5 | E15: 8.6
A16: DC | B16: 2015 | C16: 11 | D16: 7.6 | E16: 8.3
A17: DE | B17: 2015 | C17: 8.9 | D17: 5.5 | E17: 6.7
A18: FL | B18: 2015 | C18: 9.1 | D18: 5.7 | E18: 6.8
A19: GA | B19: 2015 | C19: 9.8 | D19: 6.4 | E19: 7.7
A20: IA | B20: 2015 | C20: 7.6 | D20: 4.2 | E20: 5
... A458: WY | B458: 2023 | C458: -2.1 | D458: -1.7 | E458: -1.9

Sheet Limit Profile (in-force)
A1: ='WP by State & Segment'!A1 -> Insurer NJ Umbrella
A2: ='WP by State & Segment'!A2 -> Umbrella Excess of Loss reinsurance program
A3: ='WP by State & Segment'!A3 -> Effective: 04/01/2024
A4: ='WP by State & Segment'!A4 -> Data as of: 11/30/2023
A6: combined inforce limit profile
A7: limit | B7: inforce premium | C7: policy count
A8: =1000000 -> 1000000 | B8: =B17+B26+B35 -> 31748748 | C8: =C17+C26+C35 -> 4982 | D8: =B8/SUM($B$8:$B$13) -> 0.1889316
A9: =A8+1000000 -> 2000000 | B9: =B18+B27+B36 -> 20764822 | C9: =C18+C27+C36 -> 1728 | D9: =B9/SUM($B$8:$B$13) -> 0.12356806
A10: =A9+1000000 -> 3000000 | B10: =B19+B28+B37 -> 12487992 | C10: =C19+C28+C37 -> 686 | D10: =B10/SUM($B$8:$B$13) -> 0.074313999
A11: =A10+1000000 -> 4000000 | B11: =B20+B29+B38 -> 13731898 | C11: =C20+C29+C38 -> 559 | D11: =B11/SUM($B$8:$B$13) -> 0.081716275
A12: =A11+1000000 -> 5000000 | B12: =B21+B30+B39 -> 58334519 | C12: =C21+C30+C39 -> 2016 | D12: =B12/SUM($B$8:$B$13) -> 0.34713918
A13: 10000000 | B13: =B22+B31+B40 -> 30975627 | C13: =C22+C31+C40 -> 500 | D13: =B13/SUM($B$8:$B$13) -> 0.18433089
A15: legacy subline 1 inforce limit profile
A16: limit | B16: inforce premium | C16: policy count
A17: =1000000 -> 1000000 | B17: 8325914 | C17: 1478 | D17: =B17/SUM($B$17:$B$22) -> 0.12436572
A18: =A17+1000000 -> 2000000 | B18: 8099422.5 | C18: 711 | D18: =B18/SUM($B$17:$B$22) -> 0.12098258
A19: =A18+1000000 -> 3000000 | B19: 6171693.3 | C19: 365 | D19: =B19/SUM($B$17:$B$22) -> 0.092187727
A20: =A19+1000000 -> 4000000 | B20: 5245013.1 | C20: 230 | D20: =B20/SUM($B$17:$B$22) -> 0.078345733
A21: =A20+1000000 -> 5000000 | B21: 28219381 | C21: 992 | D21: =B21/SUM($B$17:$B$22) -> 0.42151812
A22: 10000000 | B22: 10885593 | C22: 191 | D22: =B22/SUM($B$17:$B$22) -> 0.16260012
A24: subline 2 inforce limit profile
A25: limit | B25: inforce premium | C25: policy count
A26: 1000000 | B26: 15752788 | C26: 2125 | D26: =B26/SUM($B$26:$B$31) -> 0.32012528
A27: =A26+1000000 -> 2000000 | B27: 5523252 | C27: 372 | D27: =B27/SUM($B$26:$B$31) -> 0.11224252
A28: =A27+1000000 -> 3000000 | B28: 3644805.7 | C28: 161 | D28: =B28/SUM($B$26:$B$31) -> 0.074069078
A29: =A28+1000000 -> 4000000 | B29: 4708399.7 | C29: 160 | D29: =B29/SUM($B$26:$B$31) -> 0.095683242
A30: =A29+1000000 -> 5000000 | B30: 7292037.8 | C30: 199 | D30: =B30/SUM($B$26:$B$31) -> 0.14818747
A31: 10000000 | B31: 12286913 | C31: 166 | D31: =B31/SUM($B$26:$B$31) -> 0.24969241
A33: legacy subline 3 inforce limit profile
A34: limit | B34: inforce premium | C34: policy count
A35: 1000000 | B35: 7670046.3 | C35: 1379 | D35: =B35/SUM($B$35:$B$40) -> 0.14781815
A36: =A35+1000000 -> 2000000 | B36: 7142147.4 | C36: 645 | D36: =B36/SUM($B$35:$B$40) -> 0.13764441
A37: =A36+1000000 -> 3000000 | B37: 2671493.3 | C37: 160 | D37: =B37/SUM($B$35:$B$40) -> 0.051485375
A38: =A37+1000000 -> 4000000 | B38: 3778484.6 | C38: 169 | D38: =B38/SUM($B$35:$B$40) -> 0.072819458
A39: =A38+1000000 -> 5000000 | B39: 22823100 | C39: 825 | D39: =B39/SUM($B$35:$B$40) -> 0.43984982
A40: 10000000 | B40: 7803120.7 | C40: 143 | D40: =B40/SUM($B$35:$B$40) -> 0.15038278
