Workbook

Sheet Intro
A2: Delta Re Broking
A3: GG Specialty Insurance Company
A4: Energy QS
A5: 1 Apr 2025 – 1 Apr 2026
A7: Quote Requested by 3 March 2025 for Energy QS
B10: =A4 -> Energy QS
A11: Layer Status | B11: Quote Requested
A12: Reinsurer Quote response
A13: Quote Requested by Date | B13: 45748
A14: Information
A15: Currency | B15: USD
A16: Coverage Effective Date | B16: 45748
A17: Coverage Expiration Date | B17: 45747
A18: Territorial Scope | B18: USA
A19: Treaty Basis | B19: Risks Attaching basis
A20: Class Of Business | B20: Energy
A21: Line Of Business | B21: Energy
A22: Contract Nature | B22: Treaty: Proportional Quota Share
A23: Coverage Type | B23: TPL/BI/PD
A25: Basis of Lines
A26: Basis Of Lines | B26: Percentage of Order
A27: Basis Of Lines Pot | B27: Percentage of Order
A28: Coverage Details
A29: Coverage Terms Currency | B29: USD
A30: Premium
A31: Est. Gross Ceded Premium | B31: ='Premium summary'!N11 -> 49400000
A32: Ceding Commission
A33: Type | B33: Flat
A34: Basis | B34: On Ceded Written Premium, net of brokerage and taxes
A35: Distribution: Set 1
A36: Brokerage
A37: Brokerage % | B37: 2.5
A38: Gross or Net | B38: Gross

Sheet Premium summary
A1: PREMIUM
A3: Client Name: | B3: =Intro!A3 -> GG Specialty Insurance Company
A4: Program Name: | B4: =Intro!A4 -> Energy QS
A5: Effective Date: | B5: =Intro!B16 -> 45748
A7: Subject Premium
A9: Total Treaty Year Subject Written Premium
A10: Treaty Year | B10: 2014 (4/1/14 – 3/31/15) | C10: 2015 (4/1/15 – 3/31/16) | D10: 2016 (4/1/16 – 3/31/17) | E10: 2017 (4/1/17 – 3/31/18) | F10: 2018 (4/1/18 – 3/31/19) | G10: 2019 (4/1/19 – 3/31/20) | H10: 2020 (4/1/20 – 3/31/21) | I10: 2021 (4/1/21 – 3/31/22) | J10: 2022 (4/1/22 – 3/31/23) | K10: 2023 (4/1/23 – 3/31/24) | L10: Original 2024 (4/1/24 – 3/31/25) | M10: Revised 2024 (4/1/24 – 3/31/25) | N10: 2025 Proj. (4/1/25 – 3/31/26)
A11: GWP | B11: 29688183 | C11: 36104942 | D11: 42996497 | E11: 43813632 | F11: 49063086 | G11: 58102403 | H11: 58849613 | I11: 67927992 | J11: 71287821 | K11: 81689136 | L11: 84600000 | M11: 85200000 | N11: 49400000
A13: Note:
A15: Historical Earned Premium
A16: CY | B16: Guaranteed Cost | C16: Loss Sensitive | D16: Total
A17: 2014 | B17: 7756736.8 | C17: 3903463.2 | D17: =B17+C17 -> 11660200
A18: =A17+1 -> 2015 | B18: 17248192 | C18: 9270408.5 | D18: =B18+C18 -> 26518600
A19: =A18+1 -> 2016 | B19: 22988481 | C19: 12184049 | D19: =B19+C19 -> 35172529
A20: =A19+1 -> 2017 | B20: 27841286 | C20: 14836468 | D20: =B20+C20 -> 42677754
A21: =A20+1 -> 2018 | B21: 29092085 | C21: 15856554 | D21: =B21+C21 -> 44948639
A22: =A21+1 -> 2019 | B22: 33367010 | C22: 18653446 | D22: =B22+C22 -> 52020456
A23: =A22+1 -> 2020 | B23: 37112797 | C23: 20234150 | D23: =B23+C23 -> 57346947
A24: =A23+1 -> 2021 | B24: 39854170 | C24: 22026472 | D24: =B24+C24 -> 61880642
A25: =A24+1 -> 2022 | B25: 43900188 | C25: 24818363 | D25: =B25+C25 -> 68718551
A26: =A25+1 -> 2023 | B26: 47731531 | C26: 26506379 | D26: =B26+C26 -> 74237910
A27: =A26+1 -> 2024 | B27: 48863449 | C27: 25851608 | D27: =B27+C27 -> 74715057
A30: Total | B30: =SUM(B17:B27) -> 3.5575592e+08 | C30: =SUM(C17:C27) -> 1.9414136e+08 | D30: =SUM(D17:D27) -> 5.4989729e+08
A32: Note:

Sheet Rate change
A1: RATE CHANGE
A3: Client Name: | B3: ='Premium summary'!B3 -> GG Specialty Insurance Company
A4: Program Name: | B4: ='Premium summary'!B4 -> Energy QS
A5: Effective Date: | B5: ='Premium summary'!B5 -> 45748
A6: Data as of: | B6: 45626
A8: Historical Rate Change
A9: Policy Year
A10: 2014 | B10: -1.9
A11: =A10+1 -> 2015 | B11: 0
A12: =A11+1 -> 2016 | B12: 7.2
A13: =A12+1 -> 2017 | B13: -2.6
A14: =A13+1 -> 2018 | B14: -1.3
A15: =A14+1 -> 2019 | B15: 7.2
A16: =A15+1 -> 2020 | B16: -2.3
A17: =A16+1 -> 2021 | B17: 9.3
A18: =A17+1 -> 2022 | B18: 2
A19: 2023 Revised | B19: 5
A20: 2024 Original | B20: 2.5
A21: 2024 Revised | B21: 1
A22: 2025 Projected | B22: -13.8
A24: Note:
A25: includes Guaranteed Cost only
A26: The above has been updated to reflect any mid-term policy cancelation, additional premium, or accounts shifting from guaranteed cost to loss sensitive

Sheet Exposure listing
A1: EXPOSURE INFORMATION
A3: Client Name: | B3: ='Premium summary'!B3 -> GG Specialty Insurance Company
A4: Program Name: | B4: ='Premium summary'!B4 -> Energy QS
A5: Effective Date: | B5: ='Premium summary'!B5 -> 45748
A6: Data as of: | B6: ='Rate change'!B6 -> 45626
A7: Currency: | B7: USD
A9: ="Policy Bordereau: Policies incepting between "&TEXT(EOMONTH(B6,-12)+1,"Mmmm dd, yyyy")&" and "&TEXT(B6,"Mmmm dd, yyyy") -> Policy Bordereau: Policies incepting between December 01, 2023 and November 30, 2024
A11: Notes:
A12: exclude policies from Alabama state (out of appetite)
A14: Policy ID | B14: Insured ID | C14: Policy Year | D14: Treaty Year | E14: Effective Date | F14: Expiration Date | G14: New/Renewed | H14: State | I14: GC/LS | J14: Written Premium | K14: Limit
A15: P-2023-04008 | B15: I-2023-00832 | C15: 2023 | D15: 2023 | E15: 45261 | F15: 45626 | G15: New | H15: NY | I15: LS | J15: 6684.59 | K15: 1000000
A16: P-2023-04009 | B16: I-2023-00833 | C16: 2023 | D16: 2023 | E16: 45261 | F16: 45626 | G16: New | H16: TX | I16: GC | J16: 6596.65 | K16: 1000000
A17: P-2023-04010 | B17: I-2017-00504 | C17: 2023 | D17: 2023 | E17: 45261 | F17: 45626 | G17: Renewed | H17: CT | I17: GC | J17: 3638.46 | K17: 500000
A18: P-2023-04011 | B18: I-2021-01054 | C18: 2023 | D18: 2023 | E18: 45261 | F18: 45626 | G18: Renewed | H18: IL | I18: LS | J18: 33028.16 | K18: 5000000
A19: P-2023-04012 | B19: I-2020-00576 | C19: 2023 | D19: 2023 | E19: 45261 | F19: 45626 | G19: Renewed | H19: IL | I19: LS | J19: 6889.29 | K19: 1000000
A20: P-2023-04013 | B20: I-2022-00705 | C20: 2023 | D20: 2023 | E20: 45261 | F20: 45626 | G20: Renewed | H20: DC | I20: GC | J20: 74578.09 | K20: 10000000
A21: P-2023-04014 | B21: I-2018-00675 | C21: 2023 | D21: 2023 | E21: 45261 | F21: 45626 | G21: Renewed | H21: OH | I21: LS | J21: 5483.37 | K21: 1000000
A22: P-2023-04015 | B22: I-2019-00923 | C22: 2023 | D22: 2023 | E22: 45261 | F22: 45626 | G22: Renewed | H22: CA | I22: GC | J22: 46881 | K22: 5000000
A23: P-2023-04016 | B23: I-2021-01055 | C23: 2023 | D23: 2023 | E23: 45261 | F23: 45626 | G23: Renewed | H23: VA | I23: LS | J23: 8856.76 | K23: 1500000
A24: P-2023-04017 | B24: I-2021-01053 | C24: 2023 | D24: 2023 | E24: 45261 | F24: 45626 | G24: Renewed | H24: DC | I24: LS | J24: 11983.69 | K24: 2000000
A25: P-2023-04018 | B25: I-2021-01051 | C25: 2023 | D25: 2023 | E25: 45261 | F25: 45626 | G25: Renewed | H25: CA | I25: LS | J25: 9679.25 | K25: 1500000
A26: P-2023-04019 | B26: I-2021-01052 | C26: 2023 | D26: 2023 | E26: 45261 | F26: 45626 | G26: Renewed | H26: CA | I26: GC | J26: 88249.27 | K26: 10000000
... A4611: P-2024-04355 | B4611: I-2017-00501 | C4611: 2024 | D4611: 2024 | E4611: 45626 | F4611: 45990 | G4611: Renewed | H4611: AZ | I4611: GC | J4611: 9125.13 | K4611: 1000000

Sheet Exposure summary
A1: EXPOSURE INFORMATION
A3: Client Name: | B3: ='Premium summary'!B3 -> GG Specialty Insurance Company
A4: Program Name: | B4: ='Premium summary'!B4 -> Energy QS
A5: Effective Date: | B5: ='Premium summary'!B5 -> 45748
A6: Data as of: | B6: ='Rate change'!B6 -> 45626
A8: In-force Portfolio Summary: Limit Profile
B9: Guaranteed cost | F9: Loss Sensitive | J9: total
A10: Limit Band | B10: Written Premium | C10: % of Total | D10: Count | E10: % of total | F10: Written Premium | G10: % of Total | H10: Count | I10: % of total | J10: Written Premium | K10: % of Total | L10: Count | M10: % of total
A11: 0-1,000,000 | B11: 7755051 | C11: =B11/B$15 -> 0.14130027 | D11: 1147 | E11: =D11/D$15 -> 0.40978921 | F11: 4257903 | G11: =F11/F$15 -> 0.14327505 | H11: 768 | I11: =H11/H$15 -> 0.40209424 | J11: =B11+F11 -> 12012954 | K11: =J11/J$15 -> 0.14199396 | L11: =D11+H11 -> 1915 | M11: =L11/L$15 -> 0.40666808
A12: 1,000,001-1,500,000 | B12: 6434536 | C12: =B12/B$15 -> 0.11723994 | D12: 554 | E12: =D12/D$15 -> 0.19792783 | F12: 3702519 | G12: =F12/F$15 -> 0.12458682 | H12: 397 | I12: =H12/H$15 -> 0.2078534 | J12: =B12+F12 -> 10137055 | K12: =J12/J$15 -> 0.1198207 | L12: =D12+H12 -> 951 | M12: =L12/L$15 -> 0.20195371
A13: 1,500,001-2,000,000 | B13: 8347739 | C13: =B13/B$15 -> 0.15209929 | D13: 537 | E13: =D13/D$15 -> 0.19185423 | F13: 4666494 | G13: =F13/F$15 -> 0.15702381 | H13: 374 | I13: =H13/H$15 -> 0.19581152 | J13: =B13+F13 -> 13014233 | K13: =J13/J$15 -> 0.15382915 | L13: =D13+H13 -> 911 | M13: =L13/L$15 -> 0.19345933
A14: > 2,000,000 | B14: 32346157 | C14: =B14/B$15 -> 0.5893605 | D14: 561 | E14: =D14/D$15 -> 0.20042872 | F14: 17091468 | G14: =F14/F$15 -> 0.57511431 | H14: 371 | I14: =H14/H$15 -> 0.19424084 | J14: =B14+F14 -> 49437625 | K14: =J14/J$15 -> 0.58435619 | L14: =D14+H14 -> 932 | M14: =L14/L$15 -> 0.19791888
A15: Grand total | B15: =SUM(B11:B14) -> 54883483 | D15: =SUM(D11:D14) -> 2799 | F15: =SUM(F11:F14) -> 29718384 | H15: =SUM(H11:H14) -> 1910 | J15: =SUM(J11:J14) -> 84601867 | L15: =SUM(L11:L14) -> 4709
A17: Note:
A18: ="Policies incepting between "&TEXT(EOMONTH(B6,-12)+1,"Mmmm dd, yyyy")&" and "&TEXT(B6,"Mmmm dd, yyyy") -> Policies incepting between December 01, 2023 and November 30, 2024

Sheet Claim listing
A1: LOSS INFORMATION
A3: Client Name: | B3: ='Premium summary'!B3 -> GG Specialty Insurance Company
A4: Program Name: | B4: ='Premium summary'!B4 -> Energy QS
A5: Effective Date: | B5: ='Premium summary'!B5 -> 45748
A6: Data as of: | B6: ='Rate change'!B6 -> 45626
A7: Currency: | B7: USD
A9: Individual Loss Listing
A11: Note:
A12: ="Claims with incurred loss over $100000 and loss AY between "&TEXT(EOMONTH(B6,-48)+1,"yyyy")&" and "&TEXT(B6,"yyyy") -> Claims with incurred loss over $100000 and loss AY between 2020 and 2024
A14: Claim ID | B14: Insured ID | C14: Loss Date | D14: Reporting Date | E14: AY | F14: Policy ID | G14: Policy Inception (YearMonth) | H14: PY | I14: GC/LS | J14: Policy Limit | K14: Paid Loss | L14: Outstanding Loss | M14: Incurred Loss | N14: Paid ALAE | O14: Outstanding ALAE | P14: Incurred ALAE | Q14: Total Incurred | R14: Description
A15: C--00468 | B15: I-2019-00939 | C15: 43841 | D15: 43879 | E15: 2020 | F15: P-2019-03519 | G15: 43808 | H15: 2019 | I15: LS | J15: 10000000 | K15: 1604535 | L15: 0 | M15: 1604535 | N15: 458717.24 | O15: 0 | P15: 458717.24 | Q15: 2063252.2 | R15: Severe arc-flash at 4160V MCC during cabinet racking; plant outage and third-party contractor injury claims.
A16: C--00469 | B16: I-2018-00694 | C16: 43855 | D16: 43880 | E16: 2020 | F16: P-2019-03579 | G16: 43814 | H16: 2019 | I16: GC | J16: 1000000 | K16: 278848.52 | L16: 0 | M16: 278848.52 | N16: 74832.55 | O16: 0 | P16: 74832.55 | Q16: 353681.07 | R16: Valve packing leak at wellhead; ground impact limited to pad; remediation.
A17: C--00476 | B17: I-2016-00100 | C17: 43840 | D17: 43905 | E17: 2020 | F17: P-2019-00502 | G17: 43517 | H17: 2019 | I17: GC | J17: 5000000 | K17: 531858.17 | L17: 0 | M17: 531858.17 | N17: 150323.71 | O17: 0 | P17: 150323.71 | Q17: 682181.88 | R17: Generator backfire ignited vapors in remote test separator shack; smoke and wiring loss.
A18: C--00479 | B18: I-2019-00123 | C18: 43866 | D18: 43909 | E18: 2020 | F18: P-2019-00468 | G18: 43513 | H18: 2019 | I18: GC | J18: 5000000 | K18: 525556.67 | L18: 0 | M18: 525556.67 | N18: 125253.25 | O18: 0 | P18: 125253.25 | Q18: 650809.92 | R18: Overflow from produced-water tank into secondary containment after transmitter failure; vacuum recovery only.
A19: C--00487 | B19: I-2019-00300 | C19: 43884 | D19: 43950 | E19: 2020 | F19: P-2019-01150 | G19: 43581 | H19: 2019 | I19: LS | J19: 2000000 | K19: 141977.32 | L19: 0 | M19: 141977.32 | N19: 23722.49 | O19: 0 | P19: 23722.49 | Q19: 165699.81 | R19: Small valve packing leak; stained soil removed from within pad.
A20: C--00489 | B20: I-2018-00692 | C20: 43917 | D20: 43954 | E20: 2020 | F20: P-2019-03563 | G20: 43813 | H20: 2019 | I20: GC | J20: 1500000 | K20: 151652.25 | L20: 0 | M20: 151652.25 | N20: 31197.83 | O20: 0 | P20: 31197.83 | Q20: 182850.08 | R20: Slip on wet mat at warehouse; sprain/strain alleged.
A21: C--00490 | B21: I-2015-00456 | C21: 43912 | D21: 43957 | E21: 2020 | F21: P-2019-02396 | G21: 43700 | H21: 2019 | I21: LS | J21: 1500000 | K21: 154044.78 | L21: 0 | M21: 154044.78 | N21: 28787.22 | O21: 0 | P21: 28787.22 | Q21: 182832 | R21: Slip on wet mat at warehouse; sprain/strain alleged.
A22: C--00502 | B22: I-2017-00464 | C22: 43975 | D22: 44019 | E22: 2020 | F22: P-2019-03164 | G22: 43772 | H22: 2019 | I22: LS | J22: 2000000 | K22: 186924.56 | L22: 0 | M22: 186924.56 | N22: 50145.8 | O22: 0 | P22: 50145.8 | Q22: 237070.36 | R22: Pinhole leak at methanol line flange inside containment; absorbents and gasket replacement.
A23: C--00504 | B23: I-2019-00302 | C23: 43845 | D23: 44028 | E23: 2020 | F23: P-2019-01170 | G23: 43584 | H23: 2019 | I23: LS | J23: 2000000 | K23: 448282.46 | L23: 0 | M23: 448282.46 | N23: 122367.35 | O23: 0 | P23: 122367.35 | Q23: 570649.81 | R23: Track-hoe flip on ROW slope; operator orthopedics and equipment retrieval.
A24: C--00507 | B24: I-2019-00474 | C24: 43849 | D24: 44033 | E24: 2020 | F24: P-2019-01840 | G24: 43647 | H24: 2019 | I24: LS | J24: 1500000 | K24: 138120.71 | L24: 0 | M24: 138120.71 | N24: 22430.45 | O24: 0 | P24: 22430.45 | Q24: 160551.16 | R24: Knocked-over safety bollard during skid steer turn; replace/paint.
A25: C--00512 | B25: I-2014-01610 | C25: 44002 | D25: 44044 | E25: 2020 | F25: P-2019-03002 | G25: 43756 | H25: 2019 | I25: LS | J25: 1000000 | K25: 110806.32 | L25: 0 | M25: 110806.32 | N25: 25166.74 | O25: 0 | P25: 25166.74 | Q25: 135973.06 | R25: Slow seep at chemical tote valve; absorbents and disposal.
A26: C--00513 | B26: I-2019-00318 | C26: 44002 | D26: 44045 | E26: 2020 | F26: P-2020-01221 | G26: 43956 | H26: 2020 | I26: LS | J26: 1500000 | K26: 191750.72 | L26: 0 | M26: 191750.72 | N26: 42638.25 | O26: 0 | P26: 42638.25 | Q26: 234388.97 | R26: Pinhole leak at methanol line flange inside containment; absorbents and gasket replacement.
... A239: C--01043 | B239: I-2021-00954 | C239: 45020 | D239: 45622 | E239: 2023 | F239: P-2022-03296 | G239: 44856 | H239: 2022 | I239: GC | J239: 5000000 | K239: 0 | L239: 234013.48 | M239: 234013.48 | N239: 0 | O239: 77631.5 | P239: 77631.5 | Q239: 311644.98 | R239: Small battery fire in chemical shed; smoke damage to contents.

Sheet Loss triangles
A1: LOSS INFORMATION
A3: Client Name: | B3: ='Premium summary'!B3 -> GG Specialty Insurance Company
A4: Program Name: | B4: ='Premium summary'!B4 -> Energy QS
A5: Effective Date: | B5: ='Premium summary'!B5 -> 45748
A6: Data as of: | B6: ='Rate change'!B6 -> 45626
A7: Currency: | B7: USD
A9: Ground-Up Loss Triangles
A11: Notes:
A12: Totals will not tie out exactly to loss listing
A14: Total Incurred Loss and ALAE
A15: AY | B15: Earned Premium | C15: 12 | D15: =C15+12 -> 24 | E15: =D15+12 -> 36 | F15: =E15+12 -> 48 | G15: =F15+12 -> 60 | H15: =G15+12 -> 72 | I15: =H15+12 -> 84 | J15: =I15+12 -> 96 | K15: =J15+12 -> 108 | ... M15: =L15+12 -> 132
A16: 2014 | B16: =B32 -> 11660200 | C16: =C32+C48 -> 2977278.1 | D16: =D32+D48 -> 18341216 | E16: =E32+E48 -> 21882730 | F16: =F32+F48 -> 22608879 | G16: =G32+G48 -> 22647241 | H16: =H32+H48 -> 22656846 | I16: =I32+I48 -> 22785361 | J16: =J32+J48 -> 22905307 | ... M16: =M32+M48 -> 22937800
A17: =A16+1 -> 2015 | B17: =B33 -> 26518600 | C17: =C33+C49 -> 5150628.1 | D17: =D33+D49 -> 12451707 | E17: =E33+E49 -> 15235419 | F17: =F33+F49 -> 15616094 | G17: =G33+G49 -> 16633796 | H17: =H33+H49 -> 16985081 | I17: =I33+I49 -> 19388087 | J17: =J33+J49 -> 19581588 | ... M17: =M33+M49 -> 0
A18: =A17+1 -> 2016 | B18: =B34 -> 35172529 | C18: =C34+C50 -> 7167060.9 | D18: =D34+D50 -> 28243851 | E18: =E34+E50 -> 38129918 | F18: =F34+F50 -> 41675155 | G18: =G34+G50 -> 43355723 | H18: =H34+H50 -> 44069032 | I18: =I34+I50 -> 44106375 | J18: =J34+J50 -> 44111432 | ... M18: =M34+M50 -> 0
A19: =A18+1 -> 2017 | B19: =B35 -> 42677754 | C19: =C35+C51 -> 6550215 | D19: =D35+D51 -> 20027920 | E19: =E35+E51 -> 26834375 | F19: =F35+F51 -> 29267924 | G19: =G35+G51 -> 30300771 | H19: =H35+H51 -> 31172570 | I19: =I35+I51 -> 31356250 | J19: =J35+J51 -> 31371696 | ... M19: =M35+M51 -> 0
A20: =A19+1 -> 2018 | B20: =B36 -> 44948639 | C20: =C36+C52 -> 13225155 | D20: =D36+D52 -> 24506305 | E20: =E36+E52 -> 31264908 | F20: =F36+F52 -> 31579501 | G20: =G36+G52 -> 32758857 | H20: =H36+H52 -> 32961891 | I20: =I36+I52 -> 36004820 | J20: =J36+J52 -> 0 | ... M20: =M36+M52 -> 0
A21: =A20+1 -> 2019 | B21: =B37 -> 52020456 | C21: =C37+C53 -> 10310486 | D21: =D37+D53 -> 25216963 | E21: =E37+E53 -> 49518616 | F21: =F37+F53 -> 51320704 | G21: =G37+G53 -> 52545638 | H21: =H37+H53 -> 53303232 | I21: =I37+I53 -> 0 | J21: =J37+J53 -> 0 | ... M21: =M37+M53 -> 0
A22: =A21+1 -> 2020 | B22: =B38 -> 57346947 | C22: =C38+C54 -> 8438856.9 | D22: =D38+D54 -> 18576307 | E22: =E38+E54 -> 24035367 | F22: =F38+F54 -> 25961482 | G22: =G38+G54 -> 26135043 | H22: =H38+H54 -> 0 | I22: =I38+I54 -> 0 | J22: =J38+J54 -> 0 | ... M22: =M38+M54 -> 0
A23: =A22+1 -> 2021 | B23: =B39 -> 61880642 | C23: =C39+C55 -> 4995927.6 | D23: =D39+D55 -> 17514418 | E23: =E39+E55 -> 23253459 | F23: =F39+F55 -> 28609883 | G23: =G39+G55 -> 0 | H23: =H39+H55 -> 0 | I23: =I39+I55 -> 0 | J23: =J39+J55 -> 0 | ... M23: =M39+M55 -> 0
A24: =A23+1 -> 2022 | B24: =B40 -> 68718551 | C24: =C40+C56 -> 11215969 | D24: =D40+D56 -> 36134222 | E24: =E40+E56 -> 40712041 | F24: =F40+F56 -> 0 | G24: =G40+G56 -> 0 | H24: =H40+H56 -> 0 | I24: =I40+I56 -> 0 | J24: =J40+J56 -> 0 | ... M24: =M40+M56 -> 0
A25: =A24+1 -> 2023 | B25: =B41 -> 74237910 | C25: =C41+C57 -> 17691486 | D25: =D41+D57 -> 33986020 | E25: =E41+E57 -> 0 | F25: =F41+F57 -> 0 | G25: =G41+G57 -> 0 | H25: =H41+H57 -> 0 | I25: =I41+I57 -> 0 | J25: =J41+J57 -> 0 | ... M25: =M41+M57 -> 0
A26: =A25+1 -> 2024 | B26: =B42 -> 74715057 | C26: =C42+C58 -> 8423744.3 | D26: =D42+D58 -> 0 | E26: =E42+E58 -> 0 | F26: =F42+F58 -> 0 | G26: =G42+G58 -> 0 | H26: =H42+H58 -> 0 | I26: =I42+I58 -> 0 | J26: =J42+J58 -> 0 | ... M26: =M42+M58 -> 0
A30: Incurred Loss
A31: AY | B31: Earned Premium | C31: 12 | D31: =C31+12 -> 24 | E31: =D31+12 -> 36 | F31: =E31+12 -> 48 | G31: =F31+12 -> 60 | H31: =G31+12 -> 72 | I31: =H31+12 -> 84 | J31: =I31+12 -> 96 | K31: =J31+12 -> 108 | ... M31: =L31+12 -> 132
A32: 2014 | B32: ='Premium summary'!D17 -> 11660200 | C32: 2375451 | D32: 14969534 | E32: 17675935 | F32: 18385496 | G32: 18411928 | H32: 18419198 | I32: 18534582 | J32: 18629548 | K32: 18647561 | L32: 18652001 | M32: 18655263
A33: =A32+1 -> 2015 | B33: ='Premium summary'!D18 -> 26518600 | C33: 4330782 | D33: 10409825 | E33: 12672128 | F33: 12986017 | G33: 13771728 | H33: 14113025 | I33: 16105885 | J33: 16197680 | K33: 16243221 | L33: 16247822
A34: =A33+1 -> 2016 | B34: ='Premium summary'!D19 -> 35172529 | C34: 5839090 | D34: 23276469 | E34: 31410224 | F34: 34481617 | G34: 35921551 | H34: 36527768 | I34: 36560825 | J34: 36564111 | K34: 36563235
A35: =A34+1 -> 2017 | B35: ='Premium summary'!D20 -> 42677754 | C35: 5499582 | D35: 16543096 | E35: 22236994 | F35: 24290896 | G35: 25125806 | H35: 25831694 | I35: 25993101 | J35: 26005794
A36: =A35+1 -> 2018 | B36: ='Premium summary'!D21 -> 44948639 | C36: 11090518 | D36: 20298144 | E36: 25710806 | F36: 25973427 | G36: 26943520 | H36: 27111127 | I36: 30028421
A37: =A36+1 -> 2019 | B37: ='Premium summary'!D22 -> 52020456 | C37: 8739302 | D37: 21000985 | E37: 41417478 | F37: 42734989 | G37: 43645588 | H37: 44158304
A38: =A37+1 -> 2020 | B38: ='Premium summary'!D23 -> 57346947 | C38: 6686039 | D38: 15153144 | E38: 19778017 | F38: 21367856 | G38: 21473814
A39: =A38+1 -> 2021 | B39: ='Premium summary'!D24 -> 61880642 | C39: 4223732 | D39: 14734493 | E39: 19771704 | F39: 23845039
A40: =A39+1 -> 2022 | B40: ='Premium summary'!D25 -> 68718551 | C40: 9610437 | D40: 31019277 | E40: 34180582
A41: =A40+1 -> 2023 | B41: ='Premium summary'!D26 -> 74237910 | C41: 14932750 | D41: 28550546
A42: =A41+1 -> 2024 | B42: ='Premium summary'!D27 -> 74715057 | C42: 7106452
A46: ALAE
A47: AY | B47: Earned Premium | C47: 12 | D47: =C47+12 -> 24 | E47: =D47+12 -> 36 | F47: =E47+12 -> 48 | G47: =F47+12 -> 60 | H47: =G47+12 -> 72 | I47: =H47+12 -> 84 | J47: =I47+12 -> 96 | K47: =J47+12 -> 108 | ... M47: =L47+12 -> 132
A48: 2014 | B48: =B32 -> 11660200 | C48: 601827.1 | D48: 3371682 | E48: 4206795 | F48: 4223383 | G48: 4235313 | H48: 4237648 | I48: 4250779 | J48: 4275759 | K48: 4280478 | L48: 4281665 | M48: 4282537
A49: =A48+1 -> 2015 | B49: =B33 -> 26518600 | C49: 819846.1 | D49: 2041882 | E49: 2563291 | F49: 2630077 | G49: 2862068 | H49: 2872056 | I49: 3282202 | J49: 3383908 | K49: 3419406 | L49: 3420230
A50: =A49+1 -> 2016 | B50: =B34 -> 35172529 | C50: 1327970.9 | D50: 4967382 | E50: 6719694 | F50: 7193538 | G50: 7434172 | H50: 7541264 | I50: 7545550 | J50: 7547321 | K50: 7548513
...
