Workbook

Sheet Email
B4: layer 1: 4M xs 1M | C4: layer 2: 5M xs 5M | D4: layer 3: 10M xs 10M
A5: Layer Status | B5: Authorization Requested
A6: Reinsurer Quote response
A7: Authorization Requested by Date
A8: Information
A9: Currency
A10: Coverage Effective Date | B10: ='Premium Information'!B3 -> 45689
A11: Coverage Expiration Date | B11: =B10+365-1 -> 46053
A12: Territorial Scope | B12: US (CA, NY, TX, FL, IL states)
A13: Treaty Basis | B13: Losses occurring or risk attaching
A14: Class Of Business | B14: Property
A15: Line Of Business | B15: Commercial and Personal
A16: Contract Nature | B16: non-proportional
A17: Coverage Type | B17: per risk excess of loss
A19: Basis of Lines
A20: Basis Of Lines | B20: 100% basis
A21: Basis Of Lines Pot | B21: 35% available
A22: Coverage Details
A23: unlimited | B23: No
A24: Coverage Terms Currency | B24: USD
A25: Risk Definition | B25: per risk
A26: coverage limit | B26: layer 1: 4M; layer 2: 5M; layer 3: 10M
A27: coverage retention | B27: layer 1: 1M; layer 2: 5M; layer 3: 10M
A28: Other Contract Limits
A29: type | B29: Occurrence limit
A30: other: description | B30: One event involving multiple risks capped at $20,000,000
A31: limit amount | B31: 20000000
A32: currency | B32: USD
A33: risk definition | B33: per occurrence per event
A34: description | B34: occurrence limit
A35: qualifying attachments
A36: type | B36: annual aggregate deductible
A37: amount | B37: 1000000
A38: currency | B38: USD
A39: risk definition | B39: occurrence
A40: pricing
A41: type | B41: adj rate
A42: adj rate % | B42: Layer 1: 5.50%; Layer 2: 3.25%; Layer 3: 1.85%
A43: subject base type | B43: estimated gross net premium income
A44: subject base amount | B44: ='Premium Information'!U26 -> 319121000
...

Sheet Premium Information
A1: Insurer We
A2: 2025 Property Per risk Excess of Loss
A3: effective date: | B3: 45689
A5: Premium Information - Gross Net Earned Premium Income
A7: Data as of: | B7: 45565
A8: Currency: | B8: USD
B10: Gross net earned premium income
B11: Class of business | D11: State/ Year | E11: 2010 | F11: =E11+1 -> 2011 | G11: =F11+1 -> 2012 | H11: =G11+1 -> 2013 | I11: =H11+1 -> 2014 | J11: =I11+1 -> 2015 | K11: =J11+1 -> 2016 | L11: =K11+1 -> 2017 | M11: =L11+1 -> 2018 | ... R11: =Q11+1 -> 2023 | S11: 2024 Projected | T11: 2024 Revised | U11: 2025 projected
B12: Commercial Property | D12: CA | E12: 11250524 | F12: 13804806 | G12: 16886488 | H12: 19350411 | I12: 22280986 | J12: 24722005 | K12: 27042923 | L12: 34435637 | M12: 36203453 | N12: 36140699 | O12: 45597540 | P12: 45830021 | Q12: 46724285 | R12: 53036945 | S12: 54870000 | T12: 5800000 | U12: 1000
D13: FL | E13: 10003211 | F13: 13877409 | G13: 16642161 | H13: 18116913 | I13: 21627839 | J13: 22133484 | K13: 24101982 | L13: 29799347 | M13: 31533403 | N13: 32949772 | O13: 45003588 | P13: 47716872 | Q13: 50262815 | R13: 58925026 | S13: 58410000 | T13: 6360000 | U13: 59180000
D14: IL | E14: 1826059.5 | F14: 2575252.1 | G14: 3636778.8 | H14: 4315221.5 | I14: 4882427.7 | J14: 5118916.4 | K14: 5738344.9 | L14: 6822095.9 | M14: 7631426.2 | N14: 7766717.8 | O14: 10504059 | P14: 10309699 | Q14: 10911181 | R14: 12108593 | S14: 12700000 | T14: 3110000 | U14: 13770000
D15: NY | E15: 4855881.4 | F15: 7317284.5 | G15: 9382592.8 | H15: 10444962 | I15: 12526646 | J15: 12732735 | K15: 14407143 | L15: 18371312 | M15: 18134106 | N15: 18710418 | O15: 23625161 | P15: 24394074 | Q15: 24982873 | R15: 29316658 | S15: 30660000 | T15: 9480000 | U15: 30950000
D16: TX | E16: 8810428.7 | F16: 11660529 | G16: 13657298 | H16: 15699794 | I16: 19136047 | J16: 19624877 | K16: 21959862 | L16: 26852374 | M16: 28458131 | N16: 28244334 | O16: 35411276 | P16: 36864621 | Q16: 36679257 | R16: 43408873 | S16: 46760000 | T16: 5040000 | U16: 47290000
D17: LoB Total | E17: =SUM(E12:E16) -> 36746104 | F17: =SUM(F12:F16) -> 49235280 | G17: =SUM(G12:G16) -> 60205319 | H17: =SUM(H12:H16) -> 67927301 | I17: =SUM(I12:I16) -> 80453946 | J17: =SUM(J12:J16) -> 84332017 | K17: =SUM(K12:K16) -> 93250255 | L17: =SUM(L12:L16) -> 1.1628077e+08 | ... U17: =SUM(U12:U16) -> 151191000
B19: Personal Property | D19: CA | E19: 1670258.1 | F19: 2351547.1 | G19: 3052862.9 | H19: 4301219.9 | I19: 6227373.4 | J19: 7766690.3 | K19: 11992876 | L19: 14895546 | M19: 19973554 | N19: 23226845 | O19: 29120289 | P19: 31951143 | Q19: 40568605 | R19: 42522609 | S19: 45770000 | T19: 4960000 | U19: 57710000
D20: FL | E20: 1801618.6 | F20: 2240008.8 | G20: 3198506 | H20: 3533289.7 | I20: 5650779 | J20: 7653707.5 | K20: 11338597 | L20: 13722266 | M20: 17812099 | N20: 20207799 | O20: 23485455 | P20: 26447557 | Q20: 32327075 | R20: 34708772 | S20: 37080000 | T20: 3360000 | U20: 45530000
D21: IL | E21: 369793.93 | F21: 488267.87 | G21: 688829.01 | H21: 879509.38 | I21: 1348693.6 | J21: 2104141.8 | K21: 2902114.5 | L21: 3942396.4 | M21: 4935939.8 | N21: 5418757.9 | O21: 6157252.9 | P21: 6467371.6 | Q21: 8536367.1 | R21: 8821811.7 | S21: 8990000 | T21: 1100000 | U21: 11660000
D22: NY | E22: 1032137.6 | F22: 1123487.2 | G22: 1687781.4 | H22: 2048319.7 | I22: 3204112.1 | J22: 3876605.7 | K22: 5566843.2 | L22: 6942297.2 | M22: 9286256.1 | N22: 10276961 | O22: 13092987 | P22: 13293965 | Q22: 16331649 | R22: 16084928 | S22: 16560000 | T22: 340000 | U22: 21360000
D23: TX | E23: 1500410.5 | F23: 1677754.6 | G23: 2470750.9 | H23: 3318160.8 | I23: 4998552.6 | J23: 6611475.5 | K23: 9720822.9 | L23: 11254544 | M23: 13400885 | N23: 15104884 | O23: 17492501 | P23: 19449098 | Q23: 25463472 | R23: 24728749 | S23: 25230000 | T23: 160000 | U23: 31670000
D24: LoB Total | E24: =SUM(E19:E23) -> 6374218.7 | F24: =SUM(F19:F23) -> 7881065.5 | G24: =SUM(G19:G23) -> 11098730 | H24: =SUM(H19:H23) -> 14080499 | I24: =SUM(I19:I23) -> 21429511 | J24: =SUM(J19:J23) -> 28012621 | K24: =SUM(K19:K23) -> 41521254 | L24: =SUM(L19:L23) -> 50757050 | ... U24: =SUM(U19:U23) -> 167930000
B26: total subject GNEPI | E26: =E17+E24 -> 43120323 | F26: =F17+F24 -> 57116346 | G26: =G17+G24 -> 71304049 | H26: =H17+H24 -> 82007801 | I26: =I17+I24 -> 1.0188346e+08 | J26: =J17+J24 -> 1.1234464e+08 | K26: =K17+K24 -> 1.3477151e+08 | L26: =L17+L24 -> 1.6703782e+08 | ... U26: =U17+U24 -> 319121000
B27: % change total | F27: =F26/E26-1 -> 0.32458065 | G27: =G26/F26-1 -> 0.24840005 | H27: =H26/G26-1 -> 0.15011422 | I27: =I26/H26-1 -> 0.24236299 | J27: =J26/I26-1 -> 0.10267792 | K27: =K26/J26-1 -> 0.19962564 | L27: =L26/K26-1 -> 0.23941489 | M27: =M26/L26-1 -> 0.12171758 | ... R27: =R26/Q26-1 -> 0.1054532

Sheet Premium Projection
A1: ='Premium Information'!A1 -> Insurer We
A2: ='Premium Information'!A2 -> 2025 Property Per risk Excess of Loss
A3: ='Premium Information'!A3 -> effective date: | B3: ='Premium Information'!B3 -> 45689
A5: Premium information - historical GNEPI projections
A7: ='Premium Information'!A7 -> Data as of: | B7: ='Premium Information'!B7 -> 45565
A8: ='Premium Information'!A8 -> Currency: | B8: ='Premium Information'!B8 -> USD
B10: historical actual GNEPI | P10: historical projected GNEPI
C11: Commercial Property | I11: Personal Property | O11: actual total GNEPI | P11: original projection
B12: State | C12: CA | D12: FL | E12: IL | F12: NY | G12: TX | I12: CA | J12: FL | K12: IL | L12: NY | M12: TX
A13: Year | B13: 2010 | C13: 11250524 | D13: 10003211 | E13: 1826059.5 | F13: 4855881.4 | G13: 8810428.7 | I13: 1670258.1 | J13: 1801618.6 | K13: 369793.93 | L13: 1032137.6 | M13: 1500410.5 | O13: =SUM(C13:M13) -> 43120323 | P13: 40680000
B14: 2011 | C14: 13804806 | D14: 13877409 | E14: 2575252.1 | F14: 7317284.5 | G14: 11660529 | I14: 2351547.1 | J14: 2240008.8 | K14: 488267.87 | L14: 1123487.2 | M14: 1677754.6 | O14: =SUM(C14:M14) -> 57116346 | P14: 56190000
B15: 2012 | C15: 16886488 | D15: 16642161 | E15: 3636778.8 | F15: 9382592.8 | G15: 13657298 | I15: 3052862.9 | J15: 3198506 | K15: 688829.01 | L15: 1687781.4 | M15: 2470750.9 | O15: =SUM(C15:M15) -> 71304049 | P15: 73750000
B16: 2013 | C16: 19350411 | D16: 18116913 | E16: 4315221.5 | F16: 10444962 | G16: 15699794 | I16: 4301219.9 | J16: 3533289.7 | K16: 879509.38 | L16: 2048319.7 | M16: 3318160.8 | O16: =SUM(C16:M16) -> 82007801 | P16: 81580000
B17: 2014 | C17: 22280986 | D17: 21627839 | E17: 4882427.7 | F17: 12526646 | G17: 19136047 | I17: 6227373.4 | J17: 5650779 | K17: 1348693.6 | L17: 3204112.1 | M17: 4998552.6 | O17: =SUM(C17:M17) -> 1.0188346e+08 | P17: 114920000
B18: 2015 | C18: 24722005 | D18: 22133484 | E18: 5118916.4 | F18: 12732735 | G18: 19624877 | I18: 7766690.3 | J18: 7653707.5 | K18: 2104141.8 | L18: 3876605.7 | M18: 6611475.5 | O18: =SUM(C18:M18) -> 1.1234464e+08 | P18: 119270000
B19: 2016 | C19: 27042923 | D19: 24101982 | E19: 5738344.9 | F19: 14407143 | G19: 21959862 | I19: 11992876 | J19: 11338597 | K19: 2902114.5 | L19: 5566843.2 | M19: 9720822.9 | O19: =SUM(C19:M19) -> 1.3477151e+08 | P19: 125340000
B20: 2017 | C20: 34435637 | D20: 29799347 | E20: 6822095.9 | F20: 18371312 | G20: 26852374 | I20: 14895546 | J20: 13722266 | K20: 3942396.4 | L20: 6942297.2 | M20: 11254544 | O20: =SUM(C20:M20) -> 1.6703782e+08 | P20: 168710000
B21: 2018 | C21: 36203453 | D21: 31533403 | E21: 7631426.2 | F21: 18134106 | G21: 28458131 | I21: 19973554 | J21: 17812099 | K21: 4935939.8 | L21: 9286256.1 | M21: 13400885 | O21: =SUM(C21:M21) -> 1.8736925e+08 | P21: 194860000
B22: 2019 | C22: 36140699 | D22: 32949772 | E22: 7766717.8 | F22: 18710418 | G22: 28244334 | I22: 23226845 | J22: 20207799 | K22: 5418757.9 | L22: 10276961 | M22: 15104884 | O22: =SUM(C22:M22) -> 1.9804719e+08 | P22: 176260000
B23: 2020 | C23: 45597540 | D23: 45003588 | E23: 10504059 | F23: 23625161 | G23: 35411276 | I23: 29120289 | J23: 23485455 | K23: 6157252.9 | L23: 13092987 | M23: 17492501 | O23: =SUM(C23:M23) -> 2.4949011e+08 | P23: 237020000
B24: 2021 | C24: 45830021 | D24: 47716872 | E24: 10309699 | F24: 24394074 | G24: 36864621 | I24: 31951143 | J24: 26447557 | K24: 6467371.6 | L24: 13293965 | M24: 19449098 | O24: =SUM(C24:M24) -> 2.6272442e+08 | P24: 286370000
B25: 2022 | C25: 46724285 | D25: 50262815 | E25: 10911181 | F25: 24982873 | G25: 36679257 | I25: 40568605 | J25: 32327075 | K25: 8536367.1 | L25: 16331649 | M25: 25463472 | O25: =SUM(C25:M25) -> 2.9278758e+08 | P25: 304500000
B26: 2023 | C26: 53036945 | D26: 58925026 | E26: 12108593 | F26: 29316658 | G26: 43408873 | I26: 42522609 | J26: 34708772 | K26: 8821811.7 | L26: 16084928 | M26: 24728749 | O26: =SUM(C26:M26) -> 3.2366297e+08 | P26: 322070000

Sheet Limit Profile (Commercial)
A1: ='Premium Information'!A1 -> Insurer We
A2: ='Premium Information'!A2 -> 2025 Property Per risk Excess of Loss
A3: ='Premium Information'!A3 -> effective date: | B3: ='Premium Information'!B3 -> 45689
A5: Exposure information - limits profile - Commercial Property
A7: ='Premium Information'!A7 -> Data as of: | B7: ='Premium Information'!B7 -> 45565
A8: ='Premium Information'!A8 -> Currency: | B8: ='Premium Information'!B8 -> USD
E9: by policies | G9: by locations | I9: by buildings
E10: premiums | F10: number of policies | G10: premiums | H10: number of locations | I10: premiums | J10: number of buildings
B11: gross limits range
B12: 1 | C12: to | D12: 500000 | E12: 1237689 | F12: 224 | G12: 4012799 | H12: 958 | I12: 9033534.8 | J12: 2369
B13: =D12+1 -> 500001 | C13: to | D13: =D12+500000 -> 1000000 | E13: 4204553.5 | F13: 367 | G13: 12581541 | H13: 1269 | I13: 22257594 | J13: 2365
B14: =D13+1 -> 1000001 | C14: to | D14: =D13+500000 -> 1500000 | E14: 3424164.8 | F14: 205 | G14: 13500660 | H14: 866 | I14: 15952367 | J14: 1070
B15: =D14+1 -> 1500001 | C15: to | D15: =D14+500000 -> 2000000 | E15: 13852210 | F15: 612 | G15: 21806558 | H15: 1047 | I15: 24425340 | J15: 1201
B16: =D15+1 -> 2000001 | C16: to | D16: =D15+500000 -> 2500000 | E16: 6036346.2 | F16: 212 | G16: 16297728 | H16: 599 | I16: 29883492 | J16: 1091
B17: =D16+1 -> 2500001 | C17: to | D17: =D16+500000 -> 3000000 | E17: 6710789 | F17: 201 | G17: 3297635.8 | H17: 97 | I17: 1829365.2 | J17: 54
B18: =D17+1 -> 3000001 | C18: to | D18: =D17+500000 -> 3500000 | E18: 7464312.8 | F18: 189 | G18: 21741255 | H18: 581 | I18: 14054213 | J18: 372
B19: =D18+1 -> 3500001 | C19: to | D19: =D18+500000 -> 4000000 | E19: 19026305 | F19: 427 | G19: 9948990.9 | H19: 222 | I19: 5897072.5 | J19: 132
B20: =D19+1 -> 4000001 | C20: to | D20: =D19+500000 -> 4500000 | E20: 11980815 | F20: 231 | G20: 5636881.3 | H20: 108 | I20: 3452695.4 | J20: 65
B21: =D20+1 -> 4500001 | C21: to | D21: =D20+500000 -> 5000000 | E21: 34939167 | F21: 627 | G21: 45415201 | H21: 802 | I21: 46178162 | J21: 816
B22: ="greater than "&D21 -> greater than 5000000 | E22: 92457311 | F22: 820 | G22: 47094414 | H22: 418 | I22: 28369828 | J22: 250
B23: total | E23: =SUM(E12:E22) -> 2.0133366e+08 | F23: =SUM(F12:F22) -> 4115 | G23: =SUM(G12:G22) -> 2.0133366e+08 | H23: =SUM(H12:H22) -> 6967 | I23: =SUM(I12:I22) -> 2.0133366e+08 | J23: =SUM(J12:J22) -> 9785
A25: =A7 -> Data as of: | B25: 45199
A26: =A8 -> Currency:
E27: by policies | G27: by locations | I27: by buildings
E28: premiums | F28: number of policies | G28: premiums | H28: number of locations | I28: premiums | J28: number of buildings
B29: gross limits range
B30: 1 | C30: to | D30: 500000 | E30: 1192867.6 | F30: 219 | G30: 3714631.3 | H30: 905 | I30: 8205905.2 | J30: 2197
B31: =D30+1 -> 500001 | C31: to | D31: =D30+500000 -> 1000000 | E31: 3927267.5 | F31: 348 | G31: 11752926 | H31: 1204 | I31: 20667699 | J31: 2204
B32: =D31+1 -> 1000001 | C32: to | D32: =D31+500000 -> 1500000 | E32: 3242939.8 | F32: 195 | G32: 12573142 | H32: 820 | I32: 15106709 | J32: 1023
B33: =D32+1 -> 1500001 | C33: to | D33: =D32+500000 -> 2000000 | E33: 12841138 | F33: 573 | G33: 21049889 | H33: 1016 | I33: 24135310 | J33: 1196
B34: =D33+1 -> 2000001 | C34: to | D34: =D33+500000 -> 2500000 | E34: 5633239.4 | F34: 198 | G34: 15027487 | H34: 557 | I34: 28596669 | J34: 1055
B35: =D34+1 -> 2500001 | C35: to | D35: =D34+500000 -> 3000000 | E35: 6149789.2 | F35: 188 | G35: 2741082.7 | H35: 82 | I35: 1728285.4 | J35: 52
B36: =D35+1 -> 3000001 | C36: to | D36: =D35+500000 -> 3500000 | E36: 7313415.3 | F36: 187 | G36: 20506988 | H36: 552 | I36: 12430872 | J36: 334
B37: =D36+1 -> 3500001 | C37: to | D37: =D36+500000 -> 4000000 | E37: 17749808 | F37: 405 | G37: 8989162 | H37: 203 | I37: 5428739.3 | J37: 125
B38: =D37+1 -> 4000001 | C38: to | D38: =D37+500000 -> 4500000 | E38: 11040092 | F38: 214 | G38: 5163090 | H38: 99 | I38: 3077835.5 | J38: 58
B39: =D38+1 -> 4500001 | C39: to | D39: =D38+500000 -> 5000000 | E39: 32755668 | F39: 592 | G39: 43469681 | H39: 778 | I39: 43583320 | J39: 779
B40: ="greater than "&D39 -> greater than 5000000 | E40: 87733330 | F40: 784 | G40: 44591476 | H40: 397 | I40: 26618211 | J40: 235
B41: total | E41: =SUM(E30:E40) -> 1.8957955e+08 | F41: =SUM(F30:F40) -> 3903 | G41: =SUM(G30:G40) -> 1.8957955e+08 | H41: =SUM(H30:H40) -> 6613 | I41: =SUM(I30:I40) -> 1.8957955e+08 | J41: =SUM(J30:J40) -> 9258

Sheet Limit Profile (Personal)
A1: ='Premium Information'!A1 -> Insurer We
A2: ='Premium Information'!A2 -> 2025 Property Per risk Excess of Loss
A3: ='Premium Information'!A3 -> effective date: | B3: ='Premium Information'!B3 -> 45689
A5: Exposure information - limits profile - Personal Property
A7: ='Premium Information'!A7 -> Data as of: | B7: ='Premium Information'!B7 -> 45565
A8: ='Premium Information'!A8 -> Currency: | B8: ='Premium Information'!B8 -> USD
E9: by policies | G9: by locations | I9: by buildings
E10: premiums | F10: number of policies | G10: premiums | H10: number of locations | I10: premiums | J10: number of buildings
B11: gross limits range
B12: 1 | C12: to | D12: 500000 | E12: 1107141.7 | F12: 177 | G12: 5345387.1 | H12: 1085 | I12: 11587809 | J12: 2574
B13: =D12+1 -> 500001 | C13: to | D13: =D12+500000 -> 1000000 | E13: 6567207.2 | F13: 518 | G13: 16116671 | H13: 1429 | I13: 25014563 | J13: 2370
B14: =D13+1 -> 1000001 | C14: to | D14: =D13+500000 -> 1500000 | E14: 2974656.9 | F14: 159 | G14: 15746729 | H14: 901 | I14: 16959250 | J14: 987
B15: =D14+1 -> 1500001 | C15: to | D15: =D14+500000 -> 2000000 | E15: 16873364 | F15: 670 | G15: 20024368 | H15: 855 | I15: 18863845 | J15: 810
B16: =D15+1 -> 2000001 | C16: to | D16: =D15+500000 -> 2500000 | E16: 5984854.7 | F16: 190 | G16: 14515775 | H16: 455 | I16: 21402730 | J16: 674
B17: =D16+1 -> 2500001 | C17: to | D17: =D16+500000 -> 3000000 | E17: 13778412 | F17: 364 | G17: 6049924.2 | H17: 160 | I17: 3716769.8 | J17: 100
B18: =D17+1 -> 3000001 | C18: to | D18: =D17+500000 -> 3500000 | E18: 7833344.2 | F18: 176 | G18: 13031706 | H18: 306 | I18: 9004202.1 | J18: 215
B19: =D18+1 -> 3500001 | C19: to | D19: =D18+500000 -> 4000000 | E19: 18113589 | F19: 365 | G19: 8807810.8 | H19: 178 | I19: 5319095.3 | J19: 106
B20: =D19+1 -> 4000001 | C20: to | D20: =D19+500000 -> 4500000 | E20: 9794056 | F20: 169 | G20: 4500043.7 | H20: 78 | I20: 2671520.1 | J20: 48
B21: =D20+1 -> 4500001 | C21: to | D21: =D20+500000 -> 5000000 | E21: 23763939 | F21: 370 | G21: 24356744 | H21: 385 | I21: 22963305 | J21: 367
B22: ="greater than "&D21 -> greater than 5000000 | E22: 44570201 | F22: 362 | G22: 22865606 | H22: 188 | I22: 13857675 | J22: 115
B23: total | E23: =SUM(E12:E22) -> 1.5136077e+08 | F23: 3376 | G23: =SUM(G12:G22) -> 1.5136077e+08 | H23: 5842 | I23: =SUM(I12:I22) -> 1.5136077e+08 | J23: 8156
A25: =A7 -> Data as of: | B25: ='Limit Profile (Commercial)'!B25 -> 45199
A26: =A8 -> Currency:
E27: by policies | G27: by locations | I27: by buildings
E28: premiums | F28: number of policies | G28: premiums | H28: number of locations | I28: premiums | J28: number of buildings
B29: gross limits range
B30: 1 | C30: to | D30: 500000 | E30: 970205.12 | F30: 171 | G30: 4461097.5 | H30: 1000 | I30: 9889446.8 | J30: 2438
B31: =D30+1 -> 500001 | C31: to | D31: =D30+500000 -> 1000000 | E31: 5432464.6 | F31: 471 | G31: 13737012 | H31: 1354 | I31: 20653031 | J31: 2168
B32: =D31+1 -> 1000001 | C32: to | D32: =D31+500000 -> 1500000 | E32: 2487065.8 | F32: 147 | G32: 12556560 | H32: 803 | I32: 13744918 | J32: 897
B33: =D32+1 -> 1500001 | C33: to | D33: =D32+500000 -> 2000000 | E33: 13939437 | F33: 614 | G33: 16654365 | H33: 792 | I33: 16682662 | J33: 794
B34: =D33+1 -> 2000001 | C34: to | D34: =D33+500000 -> 2500000 | E34: 4972632 | F34: 178 | G34: 12274154 | H34: 427 | I34: 17862843 | J34: 623
B35: =D34+1 -> 2500001 | C35: to | D35: =D34+500000 -> 3000000 | E35: 11890612 | F35: 350 | G35: 5388311.2 | H35: 158 | I35: 3297655.3 | J35: 97
B36: =D35+1 -> 3000001 | C36: to | D36: =D35+500000 -> 3500000 | E36: 6845718.9 | F36: 167 | G36: 11672354 | H36: 300 | I36: 7837651.4 | J36: 205
B37: =D36+1 -> 3500001 | C37: to | D37: =D36+500000 -> 4000000 | E37: 14537319 | F37: 329 | G37: 6898733.9 | H37: 156 | I37: 3766364 | J37: 86
B38: =D37+1 -> 4000001 | C38: to | D38: =D37+500000 -> 4500000 | E38: 8070321 | F38: 152 | G38: 3634772.6 | H38: 69 | I38: 1983193 | J38: 39
B39: =D38+1 -> 4500001 | C39: to | D39: =D38+500000 -> 5000000 | E39: 19283709 | F39: 335 | G39: 20393179 | H39: 357 | I39: 19240650 | J39: 338
B40: ="greater than "&D39 -> greater than 5000000 | E40: 37626066 | F40: 335 | G40: 18385011 | H40: 166 | I40: 11097135 | J40: 102
B41: total | E41: =SUM(E30:E40) -> 1.2605555e+08 | F41: 3107 | G41: =SUM(G30:G40) -> 1.2605555e+08 | H41: 5421 | I41: =SUM(I30:I40) -> 1.2605555e+08 | J41: 7487

Sheet Exposure Listing (Commercial)
A1: ='Premium Information'!A1 -> Insurer We
A2: ='Premium Information'!A2 -> 2025 Property Per risk Excess of Loss
A3: ='Premium Information'!A3 -> effective date: | B3: ='Premium Information'!B3 -> 45689
A5: Exposure Listing - Commercial Property
A7: ='Premium Information'!A7 -> Data as of: | B7: ='Premium Information'!B7 -> 45565
A8: ='Premium Information'!A8 -> Currency: | B8: ='Premium Information'!B8 -> USD
A10: Notes: | B10: ="Policies incepting between "&TEXT(EOMONTH(B7,-12)+1,"Mmmm dd, yyyy")&" and "&TEXT(B7,"Mmmm dd, yyyy") -> Policies incepting between October 01, 2023 and September 30, 2024
A13: Policy ID | B13: Insured ID | C13: Policy Year | D13: Effective Date | E13: Expiration Date | F13: New/Renewed | G13: State | H13: # Locations | I13: # Buildings | J13: Written Premium | K13: Limit
A14: P1-232999 | B14: L1-230751 | C14: 2023 | D14: 45200 | E14: 45565 | F14: New | G14: NY | H14: 3 | I14: 6 | J14: 8380.52
A15: P1-233001 | B15: L1-220367 | C15: 2023 | D15: 45200 | E15: 45565 | F15: Renewed | G15: FL | H15: 1 | I15: 1 | J15: 30637.5 | K15: 2000000
A16: P1-233002 | B16: L1-170674 | C16: 2023 | D16: 45200 | E16: 45565 | F16: Renewed | G16: NY | H16: 1 | I16: 1 | J16: 21771.01 | K16: 2500000
A17: P1-233004 | B17: L1-200762 | C17: 2023 | D17: 45200 | E17: 45565 | F17: Renewed | G17: FL | H17: 1 | I17: 1 | J17: 30565.18 | K17: 2000000
A18: P1-233005 | B18: L1-200763 | C18: 2023 | D18: 45200 | E18: 45565 | F18: Renewed | G18: NY | H18: 2 | I18: 2 | J18: 82948.71 | K18: 10000000
A19: P1-233006 | B19: L1-220369 | C19: 2023 | D19: 45200 | E19: 45565 | F19: Renewed | G19: IL | H19: 2 | I19: 2 | J19: 23089.46 | K19: 3000000
A20: P1-233007 | B20: L1-220368 | C20: 2023 | D20: 45200 | E20: 45565 | F20: Renewed | G20: TX | H20: 1 | I20: 2 | J20: 62320.35 | K20: 5000000
A21: P1-233009 | B21: L1-230754 | C21: 2023 | D21: 45201 | E21: 45566 | F21: New | G21: NY | H21: 1 | I21: 2 | J21: 16374.1 | K21: 2000000
A22: P1-233010 | B22: L1-230755 | C22: 2023 | D22: 45201 | E22: 45566 | F22: New | G22: FL | H22: 1 | I22: 1 | J22: 44612.23 | K22: 3000000
A23: P1-233011 | B23: L1-230756 | C23: 2023 | D23: 45201 | E23: 45566 | F23: New | G23: IL | H23: 3 | I23: 6 | J23: 33704.03 | K23: 4500000
A24: P1-233012 | B24: L1-230757 | C24: 2023 | D24: 45201 | E24: 45566 | F24: New | G24: IL | H24: 1 | I24: 1 | J24: 10350.03 | K24: 1500000
A25: P1-233014 | B25: L1-180420 | C25: 2023 | D25: 45201 | E25: 45566 | F25: Renewed | G25: FL | H25: 2 | I25: 4 | J25: 33672.38 | K25: 2000000
A26: P1-233015 | B26: L1-200764 | C26: 2023 | D26: 45201 | E26: 45566 | F26: Renewed | G26: IL | H26: 2 | I26: 2 | J26: 25906.46 | K26: 3500000
... A124: P1-233150 | B124: L1-170717 | C124: 2023 | D124: 45214 | E124: 45579 | F124: Renewed | G124: NY | H124: 3 | I124: 3 | J124: 90303.47 | K124: 10000000
A125: P1-233152 | B125: L1-170718 | C125: 2023 | D125: 45214 | E125: 45579 | F125: Renewed | G125: TX | H125: 1 | I125: 1 | J125: 5808.51
A126: P1-233154 | B126: L1-200799 | C126: 2023 | D126: 45214 | E126: 45579 | F126: Renewed | G126: FL | H126: 3 | I126: 3 | J126: 76653.69 | K126: 5000000
A127: P1-233156 | B127: L1-150327 | C127: 2023 | D127: 45214 | E127: 45579 | F127: Renewed | G127: FL | H127: 2 | I127: 2 | J127: 153742.13 | K127: 10000000
A128: P1-233157 | B128: L1-170715 | C128: 2023 | D128: 45214 | E128: 45579 | F128: Renewed | G128: FL | H128: 1 | I128: 2 | J128: 58061.83 | K128: 4000000
A129: P1-233159 | B129: L1-220382 | C129: 2023 | D129: 45214 | E129: 45579 | F129: Renewed | G129: TX | H129: 2 | I129: 2 | J129: 50220.48 | K129: 4500000
A130: P1-233160 | B130: L1-200797 | C130: 2023 | D130: 45214 | E130: 45579 | F130: Renewed | G130: TX | H130: 2 | I130: 2 | J130: 37003.45 | K130: 3000000
A131: P1-233161 | B131: L1-180437 | C131: 2023 | D131: 45214 | E131: 45579 | F131: Renewed | G131: IL | H131: 1 | I131: 1 | J131: 35044.22 | K131: 5000000
A132: P1-233163 | B132: L1-200796 | C132: 2023 | D132: 45214 | E132: 45579 | F132: Renewed | G132: TX | H132: 1 | I132: 2 | J132: 59680.59 | K132: 4500000
A133: P1-233165 | B133: L1-230802 | C133: 2023 | D133: 45215 | E133: 45580 | F133: New | G133: IL | H133: 2 | I133: 2 | J133: 38415.33 | K133: 5000000
A134: P1-233168 | B134: L1-140394 | C134: 2023 | D134: 45215 | E134: 45580 | F134: Renewed | G134: NY | H134: 1 | I134: 1 | J134: 39631.03 | K134: 5000000
A135: P1-233170 | B135: L1-190265 | C135: 2023 | D135: 45215 | E135: 45580 | F135: Renewed | G135: FL | H135: 1 | I135: 2 | J135: 52518.25 | K135: 3500000
A136: P1-233171 | B136: L1-200803 | C136: 2023 | D136: 45215 | E136: 45580 | F136: Renewed | G136: NY | H136: 3 | I136: 3 | J136: 32377.21 | K136: 4000000
A137: P1-233172 | B137: L1-200805 | C137: 2023 | D137: 45215 | E137: 45580 | F137: Renewed | G137: FL | H137: 3 | I137: 6 | J137: 68374.83 | K137: 4000000
... A203: P1-233266 | B203: L1-230829 | C203: 2023 | D203: 45225 | E203: 45590 | F203: New | G203: IL | H203: 3 | I203: 6 | J203: 31324.89 | K203: 4000000
A204: P1-233267 | B204: L1-230830 | C204: 2023 | D204: 45225 | E204: 45590 | F204: New | G204: NY | H204: 1 | I204: 1 | J204: 4352.84
A205: P1-233271 | B205: L1-200842 | C205: 2023 | D205: 45225 | E205: 45590 | F205: Renewed | G205: TX | H205: 3 | I205: 3 | J205: 63345.59 | K205: 5000000
A206: P1-233272 | B206: L1-210446 | C206: 2023 | D206: 45225 | E206: 45590 | F206: Renewed | G206: FL | H206: 1 | I206: 2 | J206: 7593.81 | K206: 500000
A207: P1-233274 | B207: L1-180457 | C207: 2023 | D207: 45225 | E207: 45590 | F207: Renewed | G207: TX | H207: 1 | I207: 2 | J207: 119711.81 | K207: 10000000
...

Sheet Exposure Listing (Personal)
A1: ='Premium Information'!A1 -> Insurer We
A2: ='Premium Information'!A2 -> 2025 Property Per risk Excess of Loss
A3: ='Premium Information'!A3 -> effective date: | B3: ='Premium Information'!B3 -> 45689
A5: Exposure Listing - Personal Property
A7: ='Premium Information'!A7 -> Data as of: | B7: ='Premium Information'!B7 -> 45565
A8: ='Premium Information'!A8 -> Currency: | B8: ='Premium Information'!B8 -> USD
A10: Notes: | B10: ="Policies incepting between "&TEXT(EOMONTH(B7,-12)+1,"Mmmm dd, yyyy")&" and "&TEXT(B7,"Mmmm dd, yyyy") -> Policies incepting between October 01, 2023 and September 30, 2024
A13: Policy ID | B13: Insured ID | C13: Policy Year | D13: Effective Date | E13: Expiration Date | F13: New/Renewed | G13: State | H13: # Locations | I13: # Buildings | J13: Written Premium | K13: Limit
A14: P2-232444 | B14: L2-200508 | C14: 2023 | D14: 45200 | E14: 45565 | F14: Renewed | G14: NY | H14: 1 | I14: 2 | J14: 27709.15 | K14: 4000000
A15: P2-232445 | B15: L2-210269 | C15: 2023 | D15: 45200 | E15: 45565 | F15: Renewed | G15: NY | H15: 2 | I15: 2 | J15: 20536.09 | K15: 3000000
A16: P2-232446 | B16: L2-170480 | C16: 2023 | D16: 45200 | E16: 45565 | F16: Renewed | G16: FL | H16: 1 | I16: 1 | J16: 53442.03 | K16: 3500000
A17: P2-232448 | B17: L2-200509 | C17: 2023 | D17: 45200 | E17: 45565 | F17: Renewed | G17: TX | H17: 3 | I17: 3 | J17: 18546.59 | K17: 1500000
A18: P2-232449 | B18: L2-230423 | C18: 2023 | D18: 45201 | E18: 45566 | F18: New | G18: TX | H18: 1 | I18: 1 | J18: 16590.25 | K18: 1500000
A19: P2-232450 | B19: L2-230424 | C19: 2023 | D19: 45201 | E19: 45566 | F19: New | G19: NY | H19: 2 | I19: 2 | J19: 14098.53 | K19: 2000000
A20: P2-232451 | B20: L2-150340 | C20: 2023 | D20: 45201 | E20: 45566 | F20: Renewed | G20: FL | H20: 1 | I20: 2 | J20: 31017.23 | K20: 2000000
A21: P2-232453 | B21: L2-140284 | C21: 2023 | D21: 45201 | E21: 45566 | F21: Renewed | G21: FL | H21: 1 | I21: 1 | J21: 41672.96 | K21: 2500000
A22: P2-232454 | B22: L2-200510 | C22: 2023 | D22: 45201 | E22: 45566 | F22: Renewed | G22: NY | H22: 1 | I22: 1 | J22: 33125.91 | K22: 4500000
A23: P2-232456 | B23: L2-230426 | C23: 2023 | D23: 45202 | E23: 45567 | F23: New | G23: FL | H23: 1 | I23: 1 | J23: 65397.96 | K23: 4000000
A24: P2-232457 | B24: L2-230427 | C24: 2023 | D24: 45202 | E24: 45567 | F24: New | G24: IL | H24: 1 | I24: 2 | J24: 17064.08 | K24: 2000000
A25: P2-232459 | B25: L2-210270 | C25: 2023 | D25: 45202 | E25: 45567 | F25: Renewed | G25: NY | H25: 1 | I25: 1 | J25: 64510.59 | K25: 10000000
... A2474: P2-242718 | B2474: L2-180487 | C2474: 2024 | D2474: 45565 | E2474: 45929 | F2474: Renewed | G2474: NY | H2474: 2 | I2474: 4 | J2474: 81759.67 | K2474: 10000000

Sheet Claim (Non-Cat Commercial)
A1: ='Premium Information'!A1 -> Insurer We
A2: ='Premium Information'!A2 -> 2025 Property Per risk Excess of Loss
A3: ='Premium Information'!A3 -> effective date: | B3: ='Premium Information'!B3 -> 45689
A5: Experience information - Commercial Property - Non-Cat losses
A7: ='Premium Information'!A7 -> Data as of: | B7: ='Premium Information'!B7 -> 45565
A8: ='Premium Information'!A8 -> Currency: | B8: ='Premium Information'!B8 -> USD
A10: Notes: gross incurred losses greater than $50000 excluding large catastrophe (from AY 2020 to 2024); paid/outstanding/gross incurred losses include expense and can be greater than policy limit
A12: Claim No. | B12: Open/Closed | C12: Effective Date | D12: Risk Location | E12: Policy Limit | F12: Loss Date | G12: Report Date | H12: AY | I12: Cat/Non-Cat | J12: Paid Loss | K12: Outstanding Loss | L12: Gross Incurred Loss | M12: Description | N12: Cat Type | O12: comments - whether we would write again (yes/no) | P12: restated loss on go forward basis
A13: C1-1037 | B13: Closed | C13: 43506 | D13: CA | E13: 3000000 | F13: 43833 | G13: 43884 | H13: 2020 | I13: Non-Cat | J13: 192331.24 | K13: 0 | L13: 192331.24 | M13: Main electrical bus failure caused heavy smoke, heat damage, and prolonged shutdown. | O13: no | P13: 0
A14: C1-1046 | B14: Closed | C14: 43543 | D14: NY | E14: 2500000 | F14: 43852 | G14: 43900 | H14: 2020 | I14: Non-Cat | J14: 92079.1 | K14: 0 | L14: 92079.1 | M14: Sprinkler head impact flooded archive room, destroying paper files and finishes. | O14: yes | P14: 92079.1
A15: C1-1055 | B15: Closed | C15: 43631 | D15: CA | E15: 3000000 | F15: 43877 | G15: 43936 | H15: 2020 | I15: Non-Cat | J15: 114460.54 | K15: 0 | L15: 114460.54 | M15: Pump failure flooded basement storage, electrical rooms, and lower mechanical systems. | O15: no | P15: 0
A16: C1-1064 | B16: Closed | C16: 43840 | D16: TX | E16: 2000000 | F16: 43911 | G16: 43960 | H16: 2020 | I16: Non-Cat | J16: 480816.49 | K16: 0 | L16: 480816.49 | M16: Large fire in packaging area destroyed stock and heavily damaged warehouse interior. | O16: yes | P16: 480816.49
A17: C1-1065 | B17: Closed | C17: 43889 | D17: FL | E17: 2000000 | F17: 43896 | G17: 43963 | H17: 2020 | I17: Non-Cat | J17: 129952.08 | K17: 0 | L17: 129952.08 | M17: Tenant improvement fire damaged corridor finishes and multiple suite entrances. | O17: yes | P17: 129952.08
A18: C1-1067 | B18: Closed | C18: 43805 | D18: TX | E18: 3500000 | F18: 43898 | G18: 43967 | H18: 2020 | I18: Non-Cat | J18: 635585.11 | K18: 0 | L18: 635585.11 | M18: Large kitchen fire spread through multiple tenant spaces and roof assembly. | O18: yes | P18: 635585.11
A19: C1-1068 | B19: Closed | C19: 43748 | D19: CA | E19: 4000000 | F19: 43874 | G19: 43968 | H19: 2020 | I19: Non-Cat | J19: 113974.93 | K19: 0 | L19: 113974.93 | M19: Facade seal failure allowed persistent water infiltration into upper-floor offices. | O19: no | P19: 0
A20: C1-1070 | B20: Closed | C20: 43566 | D20: FL | E20: 10000000 | F20: 43926 | G20: 43971 | H20: 2020 | I20: Non-Cat | J20: 201081.21 | K20: 0 | L20: 201081.21 | M20: Roof drain blockage led to widespread ponding, interior leaks, and ceiling failures. | O20: yes | P20: 201081.21
A21: C1-1071 | B21: Closed | C21: 43870 | D21: FL | E21: 4000000 | F21: 43870 | G21: 43973 | H21: 2020 | I21: Non-Cat | J21: 256038.65 | K21: 0 | L21: 256038.65 | M21: Large ductwork fire spread smoke throughout hotel tower and common areas. | O21: no | P21: 0
A22: C1-1079 | B22: Closed | C22: 43640 | D22: CA | E22: 3000000 | F22: 43954 | G22: 43993 | H22: 2020 | I22: Non-Cat | J22: 184784.32 | K22: 0 | L22: 184784.32 | M22: Main electrical bus failure caused heavy smoke, heat damage, and prolonged shutdown. | O22: no | P22: 0
A23: C1-1087 | B23: Closed | C23: 43797 | D23: CA | E23: 2000000 | F23: 43869 | G23: 44001 | H23: 2020 | I23: Non-Cat | J23: 213242.84 | K23: 0 | L23: 213242.84 | M23: Roof drain blockage led to widespread ponding, interior leaks, and ceiling failures. | O23: no | P23: 0
A24: C1-1089 | B24: Closed | C24: 43897 | D24: NY | E24: 2000000 | F24: 43967 | G24: 44002 | H24: 2020 | I24: Non-Cat | J24: 121344.63 | K24: 0 | L24: 121344.63 | M24: Facade seal failure allowed persistent water infiltration into upper-floor offices. | O24: yes | P24: 121344.63
... A420: C1-1852 | B420: Open | C420: 45082 | D420: CA | E420: 2000000 | F420: 45217 | G420: 45561 | H420: 2023 | I420: Non-Cat | J420: 0 | K420: 117057.41 | L420: 117116.04 | M420: Facade failure allowed sustained water entry across several tenant floors. | O420: no | P420: 0

Sheet Claim (Cat Commercial)
A1: ='Premium Information'!A1 -> Insurer We
A2: ='Premium Information'!A2 -> 2025 Property Per risk Excess of Loss
A3: ='Premium Information'!A3 -> effective date: | B3: ='Premium Information'!B3 -> 45689
A5: Experience information - Commercial Property - large losses from cat events
A7: ='Premium Information'!A7 -> Data as of: | B7: ='Premium Information'!B7 -> 45565
A8: ='Premium Information'!A8 -> Currency: | B8: ='Premium Information'!B8 -> USD
A10: Notes: gross incurred losses greater than $250000 for large catastrophe only (from AY 2020 to 2024); paid/outstanding/gross incurred losses include expense and can be greater than policy limit
A12: Claim No. | B12: Open/Closed | C12: Effective Date | D12: Risk Location | E12: Policy Limit | F12: Loss Date | G12: Report Date | H12: AY | I12: Cat/Non-Cat | J12: Paid Loss | K12: Outstanding Loss | L12: Gross Incurred Loss | M12: Description | N12: Cat Type | O12: comments - whether we would write again (yes/no) | P12: restated loss on go forward basis
A13: C1-1051 | B13: Closed | C13: 43630 | D13: TX | E13: 5000000 | F13: 43865 | G13: 43917 | H13: 2020 | I13: Cat | J13: 1911101.7 | K13: 0 | L13: 1911101.7 | M13: Wildfire destroyed multiple commercial buildings, with ember-driven roof ignition and heavy smoke contamination throughout the complex. | N13: wildfire | O13: yes | P13: 1911101.7
A14: C1-1069 | B14: Closed | C14: 43828 | D14: CA | E14: 4500000 | F14: 43901 | G14: 43970 | H14: 2020 | I14: Cat | J14: 2575075.5 | K14: 0 | L14: 2575075.5 | M14: Wildfire heat and flying embers ignited the warehouse exterior, causing major fire loss and widespread stock damage. | N14: wildfire | O14: no | P14: 0
A15: C1-1107 | B15: Closed | C15: 43817 | D15: FL | E15: 10000000 | F15: 43956 | G15: 44045 | H15: 2020 | I15: Cat | J15: 1147764.2 | K15: 0 | L15: 1147764.2 | M15: Mudflow after wildfire overwhelmed the commercial site, filling ground floors with debris and causing major property damage. | N15: mudflow | O15: no | P15: 0
A16: C1-1119 | B16: Closed | C16: 43988 | D16: FL | E16: 2000000 | F16: 44039 | G16: 44095 | H16: 2020 | I16: Cat | J16: 1470472.1 | K16: 0 | L16: 1470472.1 | M16: Wildfire heat and flying embers ignited the warehouse exterior, causing major fire loss and widespread stock damage. | N16: wildfire | O16: no | P16: 0
A17: C1-1148 | B17: Closed | C17: 44015 | D17: TX | E17: 4000000 | F17: 44087 | G17: 44153 | H17: 2020 | I17: Cat | J17: 974536.9 | K17: 0 | L17: 974536.9 | M17: Flood from intense rainfall submerged the shopping center, causing severe damage to tenant buildouts and equipment. | N17: flood | O17: yes | P17: 974536.9
A18: C1-1154 | B18: Closed | C18: 43631 | D18: TX | E18: 4500000 | F18: 43981 | G18: 44173 | H18: 2020 | I18: Cat | J18: 310086.38 | K18: 0 | L18: 310086.38 | M18: Earthquake triggered partial facade collapse and extensive interior damage across several occupied commercial units. | N18: earthquake | O18: no | P18: 0
A19: C1-1178 | B19: Closed | C19: 43952 | D19: TX | E19: 4000000 | F19: 44009 | G19: 44231 | H19: 2020 | I19: Cat | J19: 2523271.8 | K19: 0 | L19: 2523271.8 | M19: Wildfire destroyed multiple commercial buildings, with ember-driven roof ignition and heavy smoke contamination throughout the complex. | N19: wildfire | O19: no | P19: 0
A20: C1-1188 | B20: Closed | C20: 43878 | D20: CA | E20: 5000000 | F20: 44132 | G20: 44253 | H20: 2020 | I20: Cat | J20: 860752.42 | K20: 0 | L20: 860752.42 | M20: Earthquake shifted the foundation and fractured utility lines, leading to extensive structural and water damage. | N20: earthquake | O20: no | P20: 0
A21: C1-1190 | B21: Closed | C21: 43776 | D21: NY | E21: 10000000 | F21: 44009 | G21: 44255 | H21: 2020 | I21: Cat | J21: 2534035.6 | K21: 0 | L21: 2534035.6 | M21: Wildfire smoke and suppression water rendered a hotel property heavily damaged and temporarily unusable. | N21: wildfire | O21: no | P21: 0
A22: C1-1202 | B22: Closed | C22: 43850 | D22: NY | E22: 10000000 | F22: 44103 | G22: 44273 | H22: 2020 | I22: Cat | J22: 1638281.2 | K22: 0 | L22: 1638281.2 | M22: Earthquake triggered partial facade collapse and extensive interior damage across several occupied commercial units. | N22: earthquake | O22: yes | P22: 1638281.2
A23: C1-1203 | B23: Closed | C23: 44184 | D23: TX | E23: 2500000 | F23: 44203 | G23: 44274 | H23: 2021 | I23: Cat | J23: 781815.58 | K23: 0 | L23: 781815.58 | M23: Wildfire smoke and suppression water rendered a hotel property heavily damaged and temporarily unusable. | N23: wildfire | O23: yes | P23: 781815.58
A24: C1-1214 | B24: Closed | C24: 44171 | D24: FL | E24: 4000000 | F24: 44262 | G24: 44308 | H24: 2021 | I24: Cat | J24: 552832.06 | K24: 0 | L24: 552832.06 | M24: Severe convective storm tore off roofing and allowed heavy rain intrusion, damaging inventory, ceilings, and electrical systems. | N24: convective storm | O24: yes | P24: 552832.06
... A97: C1-1854 | B97: Open | C97: 45379 | D97: NY | E97: 10000000 | F97: 45496 | G97: 45562 | H97: 2024 | I97: Cat | J97: 81292.72 | K97: 258949.64 | L97: 340242.36 | M97: Earthquake caused severe structural cracking, partial collapse, and major interior damage to a multi-tenant commercial property. | N97: earthquake | O97: yes | P97: 340242.36

Sheet Claim (Non-Cat Personal)
A1: ='Premium Information'!A1 -> Insurer We
A2: ='Premium Information'!A2 -> 2025 Property Per risk Excess of Loss
A3: ='Premium Information'!A3 -> effective date: | B3: ='Premium Information'!B3 -> 45689
A5: Experience information - Commercial Property - Non-Cat losses
A7: ='Premium Information'!A7 -> Data as of: | B7: ='Premium Information'!B7 -> 45565
A8: ='Premium Information'!A8 -> Currency: | B8: ='Premium Information'!B8 -> USD
A10: Notes: gross incurred losses greater than $50000 excluding large catastrophe (from AY 2020 to 2024); paid/outstanding/gross incurred losses include expense and can be greater than policy limit
A12: Claim No. | B12: Open/Closed | C12: Effective Date | D12: Risk Location | E12: Policy Limit | F12: Loss Date | G12: Report Date | H12: AY | I12: Cat/Non-Cat | J12: Paid Loss | K12: Outstanding Loss | L12: Gross Incurred Loss | M12: Description | N12: Cat Type | O12: comments - whether we would write again (yes/no) | P12: restated loss on go forward basis
A13: C2-0364 | B13: Closed | C13: 43788 | D13: CA | E13: 4000000 | F13: 43837 | G13: 43889 | H13: 2020 | I13: Non-Cat | J13: 359750.91 | K13: 0 | L13: 359750.91 | M13: Major water intrusion damaged artwork, electronics, flooring, and luxury furnishings. | O13: yes | P13: 359750.91
A14: C2-0365 | B14: Closed | C14: 43498 | D14: FL | E14: 3000000 | F14: 43857 | G14: 43908 | H14: 2020 | I14: Non-Cat | J14: 207046.49 | K14: 0 | L14: 207046.49 | M14: Second-floor plumbing failure soaked ceilings, walls, and furniture below. | O14: no | P14: 0
A15: C2-0371 | B15: Closed | C15: 43627 | D15: NY | E15: 10000000 | F15: 43878 | G15: 43936 | H15: 2020 | I15: Non-Cat | J15: 1698322.5 | K15: 0 | L15: 1698322.5 | M15: Severe collapse and water intrusion destroyed interiors, contents, and built-ins. | O15: yes | P15: 1698322.5
A16: C2-0378 | B16: Closed | C16: 43736 | D16: CA | E16: 2000000 | F16: 43897 | G16: 43972 | H16: 2020 | I16: Non-Cat | J16: 73843.45 | K16: 0 | L16: 73843.45 | M16: Water intrusion through windows damaged upholstery, rugs, and wood flooring. | O16: yes | P16: 73843.45
A17: C2-0380 | B17: Closed | C17: 43663 | D17: NY | E17: 3000000 | F17: 43892 | G17: 43980 | H17: 2020 | I17: Non-Cat | J17: 91318.6 | K17: 0 | L17: 91318.6 | M17: Burst pipe behind wall caused mold damage and demolition of finishes. | O17: yes | P17: 91318.6
A18: C2-0381 | B18: Closed | C18: 43612 | D18: TX | E18: 1000000 | F18: 43944 | G18: 43980 | H18: 2020 | I18: Non-Cat | J18: 140999.64 | K18: 0 | L18: 140999.64 | M18: Kitchen fire spread into ceiling, damaging appliances, cabinets, and adjacent rooms. | O18: yes | P18: 140999.64
A19: C2-0382 | B19: Closed | C19: 43506 | D19: IL | E19: 2500000 | F19: 43862 | G19: 43983 | H19: 2020 | I19: Non-Cat | J19: 555191.47 | K19: 0 | L19: 555191.47 | M19: Severe fire destroyed kitchen, living spaces, and most contents on one floor. | O19: no | P19: 0
A20: C2-0385 | B20: Closed | C20: 43861 | D20: FL | E20: 2000000 | F20: 43934 | G20: 44003 | H20: 2020 | I20: Non-Cat | J20: 270954.08 | K20: 0 | L20: 270954.08 | M20: Attic fire caused heavy smoke damage and destruction of stored possessions. | O20: yes | P20: 270954.08
A21: C2-0387 | B21: Closed | C21: 43559 | D21: TX | E21: 2000000 | F21: 43836 | G21: 44028 | H21: 2020 | I21: Non-Cat | J21: 588016.47 | K21: 0 | L21: 588016.47 | M21: Major plumbing failure caused widespread damage to interiors and valuable furnishings. | O21: yes | P21: 588016.47
A22: C2-0390 | B22: Closed | C22: 43612 | D22: CA | E22: 5000000 | F22: 43967 | G22: 44041 | H22: 2020 | I22: Non-Cat | J22: 142641.93 | K22: 0 | L22: 142641.93 | M22: Localized fire in media room damaged electronics, seating, and wall finishes. | O22: yes | P22: 142641.93
A23: C2-0391 | B23: Closed | C23: 43771 | D23: NY | E23: 2000000 | F23: 44005 | G23: 44043 | H23: 2020 | I23: Non-Cat | J23: 168892.33 | K23: 0 | L23: 168892.33 | M23: Burst pipe flooded several rooms, damaging wood floors and upholstered furniture. | O23: yes | P23: 168892.33
A24: C2-0393 | B24: Closed | C24: 43845 | D24: CA | E24: 3500000 | F24: 43928 | G24: 44054 | H24: 2020 | I24: Non-Cat | J24: 148690.78 | K24: 0 | L24: 148690.78 | M24: Kitchen fire spread into ceiling, damaging appliances, cabinets, and adjacent rooms. | O24: yes | P24: 148690.78
... A209: C2-0761 | B209: Open | C209: 44524 | D209: IL | E209: 5000000 | F209: 44798 | G209: 45565 | H209: 2022 | I209: Non-Cat | J209: 0 | K209: 123126.54 | L209: 123126.54 | M209: Water damage required replacement of flooring, cabinetry, and extensive personal property. | O209: yes | P209: 123126.54

Sheet Claim (Cat Personal)
A1: ='Premium Information'!A1 -> Insurer We
A2: ='Premium Information'!A2 -> 2025 Property Per risk Excess of Loss
A3: ='Premium Information'!A3 -> effective date: | B3: ='Premium Information'!B3 -> 45689
A5: Experience information - Commercial Property - large losses from cat events
A7: ='Premium Information'!A7 -> Data as of: | B7: ='Premium Information'!B7 -> 45565
A8: ='Premium Information'!A8 -> Currency: | B8: ='Premium Information'!B8 -> USD
A10: Notes: gross incurred losses greater than $250000 for large catastrophe only (from AY 2020 to 2024); paid/outstanding/gross incurred losses include expense and can be greater than policy limit
A12: Claim No. | B12: Open/Closed | C12: Effective Date | D12: Risk Location | E12: Policy Limit | F12: Loss Date | G12: Report Date | H12: AY | I12: Cat/Non-Cat | J12: Paid Loss | K12: Outstanding Loss | L12: Gross Incurred Loss | M12: Description | N12: Cat Type | O12: comments - whether we would write again (yes/no) | P12: restated loss on go forward basis
A13: C2-0377 | B13: Closed | C13: 43883 | D13: TX | E13: 10000000 | F13: 43918 | G13: 43968 | H13: 2020 | I13: Cat | J13: 1606934 | K13: 0 | L13: 1606934 | M13: Wildfire smoke and suppression water caused severe damage to interiors, appliances, and personal property. | N13: wildfire | O13: yes | P13: 1606934
A14: C2-0384 | B14: Closed | C14: 43637 | D14: FL | E14: 3000000 | F14: 43875 | G14: 43988 | H14: 2020 | I14: Cat | J14: 810563.8 | K14: 0 | L14: 810563.8 | M14: Flood from atmospheric river inundated the home, destroying flooring, furnishings, and stored belongings. | N14: flood | O14: yes | P14: 810563.8
A15: C2-0386 | B15: Closed | C15: 43684 | D15: TX | E15: 10000000 | F15: 43890 | G15: 44022 | H15: 2020 | I15: Cat | J15: 12845836 | K15: 0 | L15: 12845836 | M15: Flood from atmospheric river inundated the home, destroying flooring, furnishings, and stored belongings. | N15: flood | O15: no | P15: 0
A16: C2-0392 | B16: Closed | C16: 43823 | D16: FL | E16: 10000000 | F16: 44012 | G16: 44047 | H16: 2020 | I16: Cat | J16: 21663311 | K16: 0 | L16: 21663311 | M16: Severe convective storm tore off roofing, allowing major rain damage to furniture and household goods. | N16: convective storm | O16: no | P16: 0
A17: C2-0404 | B17: Closed | C17: 43809 | D17: CA | E17: 5000000 | F17: 43937 | G17: 44097 | H17: 2020 | I17: Cat | J17: 689281.3 | K17: 0 | L17: 689281.3 | M17: Wildfire destroyed the residence interior, with ember-driven ignition consuming furniture, clothing, and electronics. | N17: wildfire | O17: yes | P17: 689281.3
A18: C2-0421 | B18: Closed | C18: 43897 | D18: FL | E18: 10000000 | F18: 44128 | G18: 44185 | H18: 2020 | I18: Cat | J18: 3232487.4 | K18: 0 | L18: 3232487.4 | M18: Earthquake shifted the foundation, toppling furniture and shattering built-ins, electronics, and contents. | N18: earthquake | O18: no | P18: 0
A19: C2-0446 | B19: Closed | C19: 43995 | D19: NY | E19: 4000000 | F19: 44211 | G19: 44268 | H19: 2021 | I19: Cat | J19: 2401172 | K19: 0 | L19: 2401172 | M19: Earthquake triggered partial collapse, causing severe damage to interiors and nearly all personal belongings. | N19: earthquake | O19: yes | P19: 2401172
A20: C2-0451 | B20: Closed | C20: 43999 | D20: FL | E20: 2500000 | F20: 44062 | G20: 44288 | H20: 2020 | I20: Cat | J20: 454035.99 | K20: 0 | L20: 454035.99 | M20: Flood from atmospheric river inundated the home, destroying flooring, furnishings, and stored belongings. | N20: flood | O20: yes | P20: 454035.99
A21: C2-0455 | B21: Closed | C21: 43878 | D21: FL | E21: 10000000 | F21: 44139 | G21: 44296 | H21: 2020 | I21: Cat | J21: 2645808.1 | K21: 0 | L21: 2645808.1 | M21: Wildfire smoke and suppression water caused severe damage to interiors, appliances, and personal property. | N21: wildfire | O21: yes | P21: 2645808.1
A22: C2-0469 | B22: Closed | C22: 43939 | D22: CA | E22: 10000000 | F22: 44264 | G22: 44330 | H22: 2021 | I22: Cat | J22: 1827761.2 | K22: 0 | L22: 1827761.2 | M22: Earthquake triggered partial collapse, causing severe damage to interiors and nearly all personal belongings. | N22: earthquake | O22: no | P22: 0
A23: C2-0470 | B23: Closed | C23: 43922 | D23: TX | E23: 4500000 | F23: 44159 | G23: 44341 | H23: 2020 | I23: Cat | J23: 1687183.4 | K23: 0 | L23: 1687183.4 | M23: Severe convective storm tore off roofing, allowing major rain damage to furniture and household goods. | N23: convective storm | O23: yes | P23: 1687183.4
A24: C2-0474 | B24: Closed | C24: 44239 | D24: IL | E24: 3500000 | F24: 44297 | G24: 44352 | H24: 2021 | I24: Cat | J24: 280891.87 | K24: 0 | L24: 280891.87 | M24: Earthquake caused severe structural cracking and collapse, crushing household contents throughout multiple rooms. | N24: earthquake | O24: no | P24: 0
... A80: C2-0759 | B80: Open | C80: 45322 | D80: TX | E80: 5000000 | F80: 45340 | G80: 45556 | H80: 2024 | I80: Cat | J80: 65393.07 | K80: 288937.77 | L80: 354330.84 | M80: Mudflow after wildfire filled the lower level, severely damaging contents, flooring, and walls. | N80: mudflow | O80: yes | P80: 354330.84

Sheet Rate Change
A1: ='Premium Information'!A1 -> Insurer We
A2: ='Premium Information'!A2 -> 2025 Property Per risk Excess of Loss
A3: ='Premium Information'!A3 -> effective date: | B3: ='Premium Information'!B3 -> 45689
A5: exposure information - rate changes
A7: ='Premium Information'!A7 -> Data as of: | B7: ='Premium Information'!B7 -> 45565
A8: ='Premium Information'!A8 -> Currency: | B8: ='Premium Information'!B8 -> USD
E10: Rate Change (%)
B11: Class of business | D11: State/ Year | E11: 2010 | F11: =E11+1 -> 2011 | G11: =F11+1 -> 2012 | H11: =G11+1 -> 2013 | I11: =H11+1 -> 2014 | J11: =I11+1 -> 2015 | K11: =J11+1 -> 2016 | L11: =K11+1 -> 2017 | M11: =L11+1 -> 2018 | ... R11: =Q11+1 -> 2023 | S11: 2024 | T11: 2025 Projected
B12: Commercial Property | D12: CA | E12: 6.4 | F12: 2.7 | G12: 6.1 | H12: 5.8 | I12: 6.8 | J12: 2.8 | K12: 5.3 | L12: -0.4 | M12: 1.6 | N12: 5 | O12: 6.3 | P12: 1.8 | Q12: 5.3 | R12: 3.2 | S12: -2.8 | T12: 4
D13: FL | E13: 7 | F13: 3.3 | G13: 5.3 | H13: 5.3 | I13: 6 | J13: 1 | K13: 3.8 | L13: 1 | M13: 2.1 | N13: 4.4 | O13: 7.1 | P13: 2.6 | Q13: 5.3 | R13: 1.9 | S13: -2 | T13: 3.7
D14: IL | E14: 8.1 | F14: 5.1 | G14: 8.1 | H14: 5.5 | I14: 5.5 | J14: 0.3 | K14: 3.7 | L14: -1.1 | M14: 2.7 | N14: 4.6 | O14: 5.3 | P14: 3.2 | Q14: 3.2 | R14: 0.9 | S14: -1.9 | T14: 3.8
D15: NY | E15: 6 | F15: 4.6 | G15: 8.3 | H15: 3.1 | I15: 6.4 | J15: -0.2 | K15: 4 | L15: 1.4 | M15: 0.8 | N15: 6.9 | O15: 5.5 | P15: 4.5 | Q15: 4.2 | R15: 0.8 | S15: -2.1 | T15: 3.8
D16: TX | E16: 8.1 | F16: 2.9 | G16: 5.5 | H16: 5.8 | I16: 7.8 | J16: -0.6 | K16: 4.5 | L16: 1.6 | M16: 2.9 | N16: 3.6 | O16: 3.3 | P16: 3.8 | Q16: 3.7 | R16: 1.4 | S16: -3.7 | T16: 3.7
D17: LoB Average | E17: =SUMPRODUCT(E12:E16,'Premium Information'!E12:E16)/SUM('Premium Information'!E12:E16) -> 7.0025565 | F17: =SUMPRODUCT(F12:F16,'Premium Information'!F12:F16)/SUM('Premium Information'!F12:F16) -> 3.3243896 | G17: =SUMPRODUCT(G12:G16,'Premium Information'!G12:G16)/SUM('Premium Information'!G12:G16) -> 6.2064217 | H17: =SUMPRODUCT(H12:H16,'Premium Information'!H12:H16)/SUM('Premium Information'!H12:H16) -> 5.2324164 | I17: =SUMPRODUCT(I12:I16,'Premium Information'!I12:I16)/SUM('Premium Information'!I12:I16) -> 6.6816212 | J17: =SUMPRODUCT(J12:J16,'Premium Information'!J12:J16)/SUM('Premium Information'!J12:J16) -> 0.93166632 | K17: =SUMPRODUCT(K12:K16,'Premium Information'!K12:K16)/SUM('Premium Information'!K12:K16) -> 4.4245976 | L17: =SUMPRODUCT(L12:L16,'Premium Information'!L12:L16)/SUM('Premium Information'!L12:L16) -> 0.66394834 | ... R17: =SUMPRODUCT(R12:R16,'Premium Information'!R12:R16)/SUM('Premium Information'!R12:R16) -> 1.9146684 | S17: =SUMPRODUCT(S12:S16,'Premium Information'!T12:T16)/SUM('Premium Information'!T12:T16) -> -2.4647533 | T17: =SUMPRODUCT(T12:T16,'Premium Information'!U12:U16)/SUM('Premium Information'!U12:U16) -> 3.7295805
B19: Personal Property | D19: CA | E19: 10.9 | F19: -2 | G19: 6 | H19: 18.6 | I19: 17.4 | J19: 2.5 | K19: -3.1 | L19: 6.4 | M19: 15.4 | N19: 9.9 | O19: 12.7 | P19: 9.2 | Q19: 16.2 | R19: 2.7 | S19: 18.2 | T19: 9.2
D20: FL | E20: 7.9 | F20: -4.6 | G20: 5.4 | H20: 16.1 | I20: 13.7 | J20: 1.2 | K20: -2.6 | L20: 5.7 | M20: 12.8 | N20: 8.5 | O20: 9.4 | P20: 8.9 | Q20: 15.5 | R20: 3.8 | S20: 14.3 | T20: 7.5
D21: IL | E21: 9.2 | F21: 0.1 | G21: 5.3 | H21: 13 | I21: 16.7 | J21: 5.1 | K21: 0.1 | L21: 7.6 | M21: 13.8 | N21: 5.4 | O21: 9.3 | P21: 8.7 | Q21: 11.4 | R21: 2.6 | S21: 12.6 | T21: 7.9
D22: NY | E22: 7.5 | F22: -2.3 | G22: 3.7 | H22: 12.9 | I22: 13.1 | J22: 1.3 | K22: -4.2 | L22: 4.3 | M22: 11.3 | N22: 5.6 | O22: 9.9 | P22: 8.9 | Q22: 10.6 | R22: 1.9 | S22: 17.2 | T22: 6.6
D23: TX | E23: 8.1 | F23: -5.5 | G23: 2.1 | H23: 14.6 | I23: 16.3 | J23: 2.1 | K23: -4 | L23: 7.7 | M23: 13.1 | N23: 5.4 | O23: 9.1 | P23: 12 | Q23: 12.9 | R23: -1.1 | S23: 16.5 | T23: 7.1
D24: LoB Average | E24: =SUMPRODUCT(E19:E23,'Premium Information'!E19:E23)/SUM('Premium Information'!E19:E23) -> 8.7438263 | F24: =SUMPRODUCT(F19:F23,'Premium Information'!F19:F23)/SUM('Premium Information'!F19:F23) -> -3.3967461 | G24: =SUMPRODUCT(G19:G23,'Premium Information'!G19:G23)/SUM('Premium Information'!G19:G23) -> 4.5656819 | H24: =SUMPRODUCT(H19:H23,'Premium Information'!H19:H23)/SUM('Premium Information'!H19:H23) -> 15.851053 | I24: =SUMPRODUCT(I19:I23,'Premium Information'!I19:I23)/SUM('Premium Information'!I19:I23) -> 15.480775 | J24: =SUMPRODUCT(J19:J23,'Premium Information'!J19:J23)/SUM('Premium Information'!J19:J23) -> 2.0796335 | K24: =SUMPRODUCT(K19:K23,'Premium Information'!K19:K23)/SUM('Premium Information'!K19:K23) -> -3.0979818 | L24: =SUMPRODUCT(L19:L23,'Premium Information'!L19:L23)/SUM('Premium Information'!L19:L23) -> 6.3049861 | ... R24: =SUMPRODUCT(R19:R23,'Premium Information'!R19:R23)/SUM('Premium Information'!R19:R23) -> 2.1518686 | S24: =SUMPRODUCT(S19:S23,'Premium Information'!T19:T23)/SUM('Premium Information'!T19:T23) -> 16.196371 | T24: =SUMPRODUCT(T19:T23,'Premium Information'!U19:U23)/SUM('Premium Information'!U19:U23) -> 7.9220747
