Workbook

Sheet Intro
A1: ="Broker Fung is pleased to present the reinsurance underwriting information for the Insurer Atlanta Umbrella XOL reinsurance program effective "&TEXT(C7,"mm/dd/yyyy") -> Broker Fung is pleased to present the reinsurance underwriting information for the Insurer Atlanta Umbrella XOL reinsurance program effective 04/01/2025
A2: In recent years we have already seen meaningful improvements such as:
A5: Umbrella XOL Structure
A6: Basis: | B6: ="Risk attaching, new & renewal policies on or after "&TEXT(C7,"Mmmm dd, yyyy") -> Risk attaching, new & renewal policies on or after April 01, 2025
A7: Term: | B7: From | C7: 45748 | D7: To | E7: 46112
A8: ="Estimated " &TEXT(C7,"yyyy")& " Subject Written Premium" -> Estimated 2025 Subject Written Premium
A9: Retention & Limit: | B9: $5,000,000 xs $5,000,000
A10: Reinstatements: | B10: 2 free; 2 @ 100%
A12: Sublines
A13: Subline 1 | B13: Retail / Main Street Commercial Umbrella
A14: Subline 2 | B14: Middle Market Umbrella

Sheet WP by State & Segment
A1: Insurer NJ Umbrella
A2: Umbrella Excess of Loss reinsurance program
A3: ="Effective: "&TEXT(Intro!C7,"mm/dd/yyyy") -> Effective: 04/01/2025
A4: Data as of: 11/30/2024
A6: Combined Umbrella Historical Written premium by state
A7: State | B7: 2015 | C7: =B7+1 -> 2016 | D7: =C7+1 -> 2017 | E7: =D7+1 -> 2018 | F7: =E7+1 -> 2019 | G7: =F7+1 -> 2020 | H7: =G7+1 -> 2021 | I7: =H7+1 -> 2022 | J7: =I7+1 -> 2023 | K7: =J7+1 -> 2024 | L7: Proj. 4/1/25- 3/31/26
A8: AK | B8: 174499.16 | C8: 149515.02 | D8: 165500.49 | E8: 177016.98 | F8: 174765.33 | G8: 179830.95 | H8: 233083 | I8: 175021.99 | J8: 200039.59 | K8: 212048.33 | L8: 108000
A9: AL | B9: 330234.25 | C9: 298900.22 | D9: 366308.09 | E9: 389495.73 | F9: 392553.06 | G9: 668726.13 | H9: 870450.26 | I9: 945497.75 | J9: 1017354.9 | K9: 930957.99 | L9: 533113.04
A10: AR | B10: 88154.57 | C10: 144432.03 | D10: 200546.76 | E10: 176390.05 | F10: 191990.4 | G10: 500856.04 | H10: 674843.03 | I10: 658360.15 | J10: 781223.3 | K10: 805148.81 | L10: 393182.61
A11: AZ | B11: 516312.88 | C11: 500923.74 | D11: 782261.06 | E11: 941062.58 | F11: 1095115.8 | G11: 1873939.5 | H11: 2313946.6 | I11: 2473048.5 | J11: 2724157.1 | K11: 2758702.8 | L11: 1246852.2
A12: CA | B12: 4757162.6 | C12: 4629743.1 | D12: 6427005.5 | E12: 6687595.8 | F12: 7276359.8 | G12: 11830545 | H12: 14180589 | I12: 14982404 | J12: 17863930 | K12: 17250039 | L12: 8336347.8
A13: CO | B13: 537467.28 | C13: 633920.28 | D13: 731576.44 | E13: 819183.18 | F13: 910972.22 | G13: 1646058.2 | H13: 2074806.5 | I13: 2189397.8 | J13: 2404043.8 | K13: 2382484.5 | L13: 1115687
A14: CT | B14: 350032.48 | C14: 324355.63 | D14: 435006.95 | E14: 479178.15 | F14: 636440.69 | G14: 1014158.7 | H14: 1539673 | I14: 1677718.2 | J14: 2038762.9 | K14: 1825607.9 | L14: 954782.61
A15: DC | B15: 113736.58 | C15: 45433.63 | D15: 124268.19 | E15: 124137.33 | F15: 126487.56 | G15: 109539.87 | H15: 142918.66 | I15: 190684.15 | J15: 202887.03 | K15: 183028.52 | L15: 78886.957
A16: DE | B16: 72072.05 | C16: 96188.42 | D16: 147985.78 | E16: 103739.82 | F16: 74415.77 | G16: 191021.39 | H16: 330477.9 | I16: 391007.32 | J16: 427450.18 | K16: 492844.24 | L16: 190956.52
A17: FL | B17: 1651382.6 | C17: 1544385 | D17: 1876206.6 | E17: 2220157 | F17: 2088281.3 | G17: 4006289.2 | H17: 4704331.9 | I17: 5026883 | J17: 5893492.8 | K17: 6168191 | L17: 2833043.5
A18: GA | B18: 1051859.5 | C18: 958020.72 | D18: 1318955.6 | E18: 1461936.6 | F18: 1409492.5 | G18: 2499208.2 | H18: 3163979.5 | I18: 3753312 | J18: 4159195.3 | K18: 3947961.5 | L18: 2092069.6
A19: IA | B19: 313600.45 | C19: 359852.72 | D19: 357430.1 | E19: 439741.65 | F19: 392351.58 | G19: 677143.69 | H19: 890265.19 | I19: 958891.81 | J19: 998351.29 | K19: 1003282.4 | L19: 486782.61
... A57: WY | B57: 86856.04 | C57: 103598.98 | D57: 129698.8 | E57: 137387.41 | F57: 118936.56 | G57: 198316.12 | H57: 262435.07 | I57: 264812.58 | J57: 103643.52 | K57: 91226.02 | L57: 50400
A58: Total | B58: =SUM(B8:B57) -> 32646705 | C58: =SUM(C8:C57) -> 31260789 | D58: =SUM(D8:D57) -> 39880999 | E58: =SUM(E8:E57) -> 43025171 | F58: =SUM(F8:F57) -> 45283999 | G58: =SUM(G8:G57) -> 75423378 | H58: =SUM(H8:H57) -> 95217555 | I58: =SUM(I8:I57) -> 1.0212183e+08 | ... L58: =SUM(L8:L57) -> 56811443
A60: (1) Premium is by Calendar Year unless stated
A62: Legacy Subline1 Historical Written Premium by State
A63: State | B63: 2015 | C63: =B63+1 -> 2016 | D63: =C63+1 -> 2017 | E63: =D63+1 -> 2018 | F63: =E63+1 -> 2019 | G63: =F63+1 -> 2020 | H63: =G63+1 -> 2021 | I63: =H63+1 -> 2022 | J63: =I63+1 -> 2023 | K63: =J63+1 -> 2024 | L63: =L7 -> Proj. 4/1/25- 3/31/26
A64: AK | B64: 174499.16 | C64: 149515.02 | D64: 165500.49 | E64: 177016.98 | F64: 174765.33 | G64: 113472.37 | H64: 127708.93 | I64: 63476.388 | J64: 84712.373 | K64: 111801.22 | L64: 33495.652
A65: AL | B65: 330234.25 | C65: 298900.22 | D65: 366308.09 | E65: 389495.73 | F65: 392553.06 | G65: 503271.07 | H65: 465775.87 | I65: 367583.83 | J65: 386396.97 | K65: 408630.76 | L65: 133669.57
A66: AR | B66: 88154.57 | C66: 144432.03 | D66: 200546.76 | E66: 176390.05 | F66: 191990.4 | G66: 416198.15 | H66: 413171.24 | I66: 321365.18 | J66: 404610.99 | K66: 442843.98 | L66: 141495.65
A67: AZ | B67: 516312.88 | C67: 500923.74 | D67: 782261.06 | E67: 941062.58 | F67: 1095115.8 | G67: 1352301.9 | H67: 1483021.2 | I67: 1511815.1 | J67: 1687362.8 | K67: 1826507.5 | L67: 576313.04
A68: CA | B68: 4757162.6 | C68: 42974631 | D68: 6427005.5 | E68: 6687595.8 | F68: 7276359.8 | G68: 9390488.7 | H68: 9359343.7 | I68: 8829503.8 | J68: 10782581 | K68: 10244165 | L68: 3551165.2
A69: CO | B69: 537467.28 | C69: 633920.28 | D69: 731576.44 | E69: 819183.18 | F69: 910972.22 | G69: 1287202.9 | H69: 1327977.1 | I69: 1312029.7 | J69: 1488569.8 | K69: 1409599.3 | L69: 479582.61
A70: CT | B70: 350032.48 | C70: 324355.63 | D70: 435006.95 | E70: 479178.15 | F70: 636440.69 | G70: 778852.9 | H70: 930856.65 | I70: 965681.93 | J70: 1154804.5 | K70: 955969.59 | L70: 359373.91
A71: DC | B71: 113736.58 | C71: 45433.63 | D71: 124268.19 | E71: 124137.33 | F71: 126487.56 | G71: 95529.94 | H71: 118707.47 | I71: 154140.97 | J71: 150220.55 | K71: 145741.18 | L71: 49460.87
A72: DE | B72: 72072.05 | C72: 96188.42 | D72: 147985.78 | E72: 103739.82 | F72: 74415.77 | G72: 153520.61 | H72: 234178.48 | I72: 327329.26 | J72: 340600.26 | K72: 380474.71 | L72: 121460.87
A73: FL | B73: 1651382.6 | C73: 1544385 | D73: 1876206.6 | E73: 2220157 | F73: 2088281.3 | G73: 2919685.2 | H73: 2911909.6 | I73: 2782996.7 | J73: 3452926.3 | K73: 3686698 | L73: 1196452.2
A74: GA | B74: 1051859.5 | C74: 958020.72 | D74: 1318955.6 | E74: 1461936.6 | F74: 1409492.5 | G74: 1779483.4 | H74: 1753533.5 | I74: 1744703 | J74: 2016716.7 | K74: 1964407.7 | L74: 662713.04
A75: IA | B75: 313600.45 | C75: 359852.72 | D75: 357430.1 | E75: 439741.65 | F75: 392351.58 | G75: 495241.49 | H75: 494034.74 | I75: 511119.27 | J75: 565118.78 | K75: 590886.63 | L75: 193147.83
... A113: WY | B113: 86856.04 | C113: 103598.98 | D113: 129698.8 | E113: 137387.41 | F113: 118936.56 | G113: 150452.08 | H113: 164758.87 | I113: 153139.53 | J113: 59764.036 | K113: 34604.85 | L113: 15339.13
A114: Total | B114: =SUM(B64:B113) -> 32646705 | C114: =SUM(C64:C113) -> 69605677 | D114: =SUM(D64:D113) -> 39880999 | E114: =SUM(E64:E113) -> 43025171 | F114: =SUM(F64:F113) -> 45283999 | G114: =SUM(G64:G113) -> 57797907 | H114: =SUM(H64:H113) -> 59142392 | I114: =SUM(I64:I113) -> 56083644 | ... L114: =SUM(L64:L113) -> 22927617
A115: (1) Premium is by Calendar Year unless stated
A117: subline2 Historical Written Premium by State
A118: State | B118: 2020 | C118: 2021 | D118: 2022 | E118: =D118+1 -> 2023 | F118: =E118+1 -> 2024 | G118: =L63 -> Proj. 4/1/25- 3/31/26
...

Sheet Large Claims (subline 1)
A1: ='WP by State & Segment'!A1 -> Insurer NJ Umbrella
A2: ='WP by State & Segment'!A2 -> Umbrella Excess of Loss reinsurance program
A3: ='WP by State & Segment'!A3 -> Effective: 04/01/2025
A4: ='WP by State & Segment'!A4 -> Data as of: 11/30/2024
A6: Subline1 Claims - Risks Attaching
A7: Claim Number | B7: Policy Number | C7: Company Name | D7: Claim Status | E7: Policy Eff Date | F7: Umbrella Limit | G7: Accident Date | H7: Accident Year | I7: Expense | J7: Paid Loss | K7: Reserve Change | L7: Total Incurred | M7: Describtion
A8: C1--00635 | B8: P19-1-00792 | C8: 17-1-00280 | D8: Closed | E8: 43562 | F8: 5000000 | G8: 43840 | H8: 2020 | I8: 27424.58 | J8: 179283.28 | K8: 0 | L8: 206707.86 | M8: Punitive damages sought; prior incidents documented
A9: C1--00646 | B9: P20-1-00093 | C9: 16-1-00010 | D9: Closed | E9: 43839 | F9: 5000000 | G9: 43874 | H9: 2020 | I9: 28369.81 | J9: 125820.34 | K9: 0 | L9: 154190.15 | M9: Catastrophic burn injury; long hospitalization
A10: C1--00648 | B10: P19-1-00696 | C10: 17-1-00233 | D10: Closed | E10: 43551 | F10: 1000000 | G10: 43873 | H10: 2020 | I10: 22660.41 | J10: 119970.39 | K10: 0 | L10: 142630.8 | M10: Catastrophic burn injury; long hospitalization
A11: C1--00650 | B11: P19-1-02019 | C11: 15-1-01610 | D11: Closed | E11: 43710 | F11: 3000000 | G11: 43836 | H11: 2020 | I11: 34739.53 | J11: 227058.35 | K11: 0 | L11: 261797.88 | M11: Venue unfavorable; nuclear verdict risk flagged
A12: C1--00651 | B12: P19-1-00980 | C12: 19-1-00147 | D12: Closed | E12: 43586 | F12: 5000000 | G12: 43881 | H12: 2020 | I12: 20526.19 | J12: 144044.09 | K12: 0 | L12: 164570.28 | M12: Sexual assault claim; negligent security alleged
A13: C1--00652 | B13: P19-1-02970 | C13: 15-1-02391 | D13: Closed | E13: 43822 | F13: 3000000 | G13: 43867 | H13: 2020 | I13: 248726.79 | J13: 1517646.2 | K13: 0 | L13: 1766373 | M13: Global resolution; umbrella exhausted; final settlement
A14: C1--00656 | B14: P19-1-01213 | C14: 17-1-00408 | D14: Closed | E14: 43616 | F14: 1000000 | G14: 43877 | H14: 2020 | I14: 436317.71 | J14: 1727502.2 | K14: 0 | L14: 2163819.9 | M14: Global resolution; umbrella exhausted; final settlement
A15: C1--00658 | B15: P19-1-02373 | C15: 17-1-00762 | D15: Closed | E15: 43750 | F15: 1000000 | G15: 43880 | H15: 2020 | I15: 12646.38 | J15: 80518.9 | K15: 0 | L15: 93165.28 | M15: Wrongful death; negligent security; punitive demand
A16: C1--00659 | B16: P19-1-02269 | C16: 17-1-00730 | D16: Closed | E16: 43740 | F16: 5000000 | G16: 43872 | H16: 2020 | I16: 39214.78 | J16: 262385.62 | K16: 0 | L16: 301600.4 | M16: Mass illness allegation; class counsel engaged
A17: C1--00660 | B17: P19-1-01555 | C17: 15-1-01250 | D17: Closed | E17: 43655 | F17: 3000000 | G17: 43869 | H17: 2020 | I17: 14965.33 | J17: 69557.4 | K17: 0 | L17: 84522.73 | M17: Chemical spill; exposure claim; medical monitoring
A18: C1--00661 | B18: P19-1-00355 | C18: 15-1-00269 | D18: Closed | E18: 43509 | F18: 5000000 | G18: 43839 | H18: 2020 | I18: 51892.12 | J18: 175291.88 | K18: 0 | L18: 227184 | M18: Punitive damages sought; prior incidents documented
A19: C1--00664 | B19: P20-1-00292 | C19: 19-1-00038 | D19: Closed | E19: 43861 | F19: 4000000 | G19: 43924 | H19: 2020 | I19: 9844.73 | J19: 66556.12 | K19: 0 | L19: 76400.85 | M19: Chemical spill; exposure claim; medical monitoring
... A458: C1--01513 | B458: P23-1-03064 | C458: 20-1-00830 | D458: Open | E458: 45208 | F458: 5000000 | G458: 45412 | H458: 2024 | I458: 0 | J458: 0 | K458: 356183.93 | L458: 356183.93 | M458: Excess layers exposed; structured settlement discussed

Sheet Large Claims (subline 2)
A1: ='WP by State & Segment'!A1 -> Insurer NJ Umbrella
A2: ='WP by State & Segment'!A2 -> Umbrella Excess of Loss reinsurance program
A3: ='WP by State & Segment'!A3 -> Effective: 04/01/2025
A4: ='WP by State & Segment'!A4 -> Data as of: 11/30/2024
A6: Subline2 Claims - Risks Attaching
A7: Claim Number | B7: Policy Number | C7: Company Name | D7: Claim Status | E7: Policy Eff Date | F7: Loss State | G7: Umbrella Limit | H7: Accident Date | I7: Accident Year | J7: ANO | K7: DCC | L7: Paid Loss | M7: Reserve Change | N7: Total Incurred | O7: Describtion
A8: C1--00005 | B8: P20-2-00035 | C8: 20-2-00035 | D8: Closed | E8: 43841 | F8: IL | G8: 1000000 | H8: 43999 | I8: 2020 | J8: 2714.1466 | K8: 8046.8434 | L8: 71539.53 | M8: 0 | N8: 82300.52 | O8: Product liability; high-venue counsel; trial set
A9: C1--00006 | B9: P20-2-00146 | C9: 20-2-00146 | D9: Closed | E9: 43868 | F9: UT | G9: 1000000 | H9: 44018 | I9: 2020 | J9: 3735.6033 | K9: 13809.577 | L9: 84563.23 | M9: 0 | N9: 102108.41 | O9: Punitive damages sought; internal emails produced
A10: C1--00007 | B10: P20-2-00217 | C10: 20-2-00217 | D10: Closed | E10: 43883 | F10: MI | G10: 5000000 | H10: 44034 | I10: 2020 | J10: 2156.7921 | K10: 7579.1379 | L10: 80104.96 | M10: 0 | N10: 89840.89 | O10: Reptile theory; corporate safety indifference alleged
A11: C1--00009 | B11: P20-2-00744 | C11: 20-2-00744 | D11: Closed | E11: 44007 | F11: FL | G11: 1000000 | H11: 44031 | I11: 2020 | J11: 4039.2198 | K11: 9673.9002 | L11: 120166.86 | M11: 0 | N11: 133879.98 | O11: Mass tort counsel; coordinated litigation filed
A12: C1--00010 | B12: P20-2-00422 | C12: 20-2-00422 | D12: Closed | E12: 43932 | F12: IN | G12: 1000000 | H12: 43960 | I12: 2020 | J12: 3224.8394 | K12: 7555.9506 | L12: 58734.46 | M12: 0 | N12: 69515.25 | O12: Wrongful death; negligent security; punitive demand
A13: C1--00011 | B13: P20-2-00546 | C13: 20-2-00546 | D13: Closed | E13: 43962 | F13: FL | G13: 1000000 | H13: 43977 | I13: 2020 | J13: 7922.3268 | K13: 20821.563 | L13: 102224.33 | M13: 0 | N13: 130968.22 | O13: Venue unfavorable; nuclear verdict risk flagged
A14: C1--00013 | B14: P20-2-00236 | C14: 20-2-00236 | D14: Closed | E14: 43887 | F14: NC | G14: 1000000 | H14: 44061 | I14: 2020 | J14: 4413.1164 | K14: 12768.074 | L14: 130137.98 | M14: 0 | N14: 147319.17 | O14: Mass tort counsel; coordinated litigation filed
A15: C1--00020 | B15: P20-2-00180 | C15: 20-2-00180 | D15: Closed | E15: 43876 | F15: DC | G15: 1000000 | H15: 44086 | I15: 2020 | J15: 8855.2641 | K15: 29379.906 | L15: 136157.35 | M15: 0 | N15: 174392.52 | O15: Catastrophic burn injury; long-term disability claimed
A16: C1--00021 | B16: P20-2-00124 | C16: 20-2-00124 | D16: Closed | E16: 43864 | F16: PA | G16: 1000000 | H16: 44121 | I16: 2020 | J16: 5859.2713 | K16: 14584.279 | L16: 97574.95 | M16: 0 | N16: 118018.5 | O16: Time-limit demand; excess exposure; mediation failed
A17: C1--00022 | B17: P20-2-00027 | C17: 20-2-00027 | D17: Closed | E17: 43839 | F17: NY | G17: 5000000 | H17: 44119 | I17: 2020 | J17: 23021.693 | K17: 60695.667 | L17: 325236.16 | M17: 0 | N17: 408953.52 | O17: Severe disfigurement; emotional distress claims added
A18: C1--00026 | B18: P20-2-00106 | C18: 20-2-00106 | D18: Closed | E18: 43859 | F18: AL | G18: 5000000 | H18: 44141 | I18: 2020 | J18: 7862.1025 | K18: 19487.788 | L18: 99973.07 | M18: 0 | N18: 127322.96 | O18: Venue unfavorable; nuclear verdict risk flagged
A19: C1--00027 | B19: P20-2-00570 | C19: 20-2-00570 | D19: Closed | E19: 43968 | F19: IL | G19: 1000000 | H19: 44171 | I19: 2020 | J19: 32263.938 | K19: 78408.212 | L19: 483876.28 | M19: 0 | N19: 594548.43 | O19: Catastrophic spinal injury; lifetime care; high demand
... A254: C1--00633 | B254: P24-2-00540 | C254: 21-2-00243 | D254: Open | E254: 45350 | F254: IL | G254: 1000000 | H254: 45449 | I254: 2024 | J254: 295.24071 | K254: 1064.2093 | L254: 30345.66 | M254: 63524.29 | N254: 95229.4 | O254: Product liability; high-venue counsel; trial set

Sheet Rate Change (subline 1)
A1: ='WP by State & Segment'!A1 -> Insurer NJ Umbrella
A2: ='WP by State & Segment'!A2 -> Umbrella Excess of Loss reinsurance program
A3: ='WP by State & Segment'!A3 -> Effective: 04/01/2025
A4: ='WP by State & Segment'!A4 -> Data as of: 11/30/2024
A6: Subline1 Historical Rate Action by State & Product
A8: State | B8: Year | C8: Rate change (%)
A9: AK | B9: 2015 | C9: 3.5
A10: AL | B10: 2015 | C10: 3.4
A11: AR | B11: 2015 | C11: 6.5
A12: AZ | B12: 2015 | C12: 6.6
A13: CA | B13: 2015 | C13: 6.7
A14: CO | B14: 2015 | C14: 6.5
A15: CT | B15: 2015 | C15: 4.9
A16: DC | B16: 2015 | C16: 6.4
A17: DE | B17: 2015 | C17: 6.2
A18: FL | B18: 2015 | C18: 4.8
A19: GA | B19: 2015 | C19: 3.1
A20: IA | B20: 2015 | C20: 5.5
... A508: WY | B508: 2024 | C508: -0.3

Sheet Rate Change (subline 2)
A1: ='WP by State & Segment'!A1 -> Insurer NJ Umbrella
A2: ='WP by State & Segment'!A2 -> Umbrella Excess of Loss reinsurance program
A3: ='WP by State & Segment'!A3 -> Effective: 04/01/2025
A4: ='WP by State & Segment'!A4 -> Data as of: 11/30/2024
A6: Subline2 Historical Rate Action by State & Product
A8: State | B8: Year | C8: Rate change (%)
A9: AK | B9: 2015 | C9: 3.1
A10: AL | B10: 2015 | C10: 5
A11: AR | B11: 2015 | C11: 5.3
A12: AZ | B12: 2015 | C12: 1.9
A13: CA | B13: 2015 | C13: 0.7
A14: CO | B14: 2015 | C14: 3.4
A15: CT | B15: 2015 | C15: 4.3
A16: DC | B16: 2015 | C16: 2.2
A17: DE | B17: 2015 | C17: 2.9
A18: FL | B18: 2015 | C18: 0
A19: GA | B19: 2015 | C19: 5.5
A20: IA | B20: 2015 | C20: 3.6
... A508: WY | B508: 2024 | C508: 10.5

Sheet Limit Profile (in-force)
A1: ='WP by State & Segment'!A1 -> Insurer NJ Umbrella
A2: ='WP by State & Segment'!A2 -> Umbrella Excess of Loss reinsurance program
A3: ='WP by State & Segment'!A3 -> Effective: 04/01/2025
A4: ='WP by State & Segment'!A4 -> Data as of: 11/30/2024
A6: combined inforce limit profile
A7: limit | B7: inforce premium | C7: policy count
A8: =1000000 -> 1000000 | B8: 13235750 | C8: 3753 | D8: =B8/SUM($B$8:$B$13) -> 0.20608555
A9: =A8+1000000 -> 2000000 | B9: 7231030.3 | C9: 1116 | D9: =B9/SUM($B$8:$B$13) -> 0.11258983
A10: =A9+1000000 -> 3000000 | B10: 5469959.8 | C10: 567 | D10: =B10/SUM($B$8:$B$13) -> 0.085169311
A11: =A10+1000000 -> 4000000 | B11: 5325024.2 | C11: 392 | D11: =B11/SUM($B$8:$B$13) -> 0.082912609
A12: =A11+1000000 -> 5000000 | B12: 19665257 | C12: 1287 | D12: =B12/SUM($B$8:$B$13) -> 0.30619537
A13: 10000000 | B13: 13297519 | C13: 394 | D13: =B13/SUM($B$8:$B$13) -> 0.20704732
A15: legacy subline 1 inforce limit profile
A16: limit | B16: inforce premium | C16: policy count
A17: =1000000 -> 1000000 | B17: 9046920.5 | C17: 1576 | D17: =B17/SUM($B$17:$B$22) -> 0.12266585
A18: =A17+1000000 -> 2000000 | B18: 8609362.5 | C18: 747 | D18: =B18/SUM($B$17:$B$22) -> 0.11673306
A19: =A18+1000000 -> 3000000 | B19: 6889565.2 | C19: 399 | D19: =B19/SUM($B$17:$B$22) -> 0.09341459
A20: =A19+1000000 -> 4000000 | B20: 5207147.4 | C20: 222 | D20: =B20/SUM($B$17:$B$22) -> 0.070602937
A21: =A20+1000000 -> 5000000 | B21: 31024414 | C21: 1077 | D21: =B21/SUM($B$17:$B$22) -> 0.42065542
A22: 10000000 | B22: 12975151 | C22: 224 | D22: =B22/SUM($B$17:$B$22) -> 0.17592814
A24: subline 2 inforce limit profile
A25: limit | B25: inforce premium | C25: policy count
A26: 1000000 | B26: 17424579 | C26: 2177 | D26: =B26/SUM($B$26:$B$31) -> 0.31856833
A27: =A26+1000000 -> 2000000 | B27: 5852698.1 | C27: 369 | D27: =B27/SUM($B$26:$B$31) -> 0.10700312
A28: =A27+1000000 -> 3000000 | B28: 4050354.5 | C28: 168 | D28: =B28/SUM($B$26:$B$31) -> 0.074051411
A29: =A28+1000000 -> 4000000 | B29: 5442901 | C29: 170 | D29: =B29/SUM($B$26:$B$31) -> 0.09951092
A30: =A29+1000000 -> 5000000 | B30: 8306099.7 | C30: 210 | D30: =B30/SUM($B$26:$B$31) -> 0.15185792
A31: 10000000 | B31: 13619888 | C31: 170 | D31: =B31/SUM($B$26:$B$31) -> 0.2490083
