Workbook

Sheet Email
B4: layer 1: 500K xs 500K | C4: layer 2: 4M xs 1M | D4: layer 3: 5M xs 5M
A5: Layer Status | B5: Authorization Requested
A6: Reinsurer Quote response
A7: Authorization Requested by Date
A8: Information
A9: Currency
A10: Coverage Effective Date | B10: ='Premium Information'!B3 -> 45689
A11: Coverage Expiration Date | B11: =B10+365-1 -> 46053
A12: Territorial Scope | B12: US (CA, NY, TX, FL, IL states)
A13: Treaty Basis | B13: Losses occurring or risk attaching
A14: Class Of Business | B14: Property
A15: Line Of Business | B15: Commercial and Personal
A16: Contract Nature | B16: non-proportional
A17: Coverage Type | B17: per risk excess of loss
A19: Basis of Lines
A20: Basis Of Lines | B20: 100% basis
A21: Basis Of Lines Pot | B21: 35% available
A22: Coverage Details
A23: unlimited | B23: No
A24: Coverage Terms Currency | B24: USD
A25: Risk Definition | B25: per risk
A26: coverage limit | B26: layer 1: 500K; layer 2: 4M; layer 3: 5M
A27: coverage retention | B27: layer 1: 500K; layer 2: 1M; layer 3: 5M
A28: Other Contract Limits
A29: type | B29: Occurrence limit
A30: other: description | B30: One event involving multiple risks capped at $10,000,000
A31: limit amount | B31: 10000000
A32: currency | B32: USD
A33: risk definition | B33: per occurrence per event
A34: description | B34: occurrence limit
A35: qualifying attachments
A36: type | B36: annual aggregate deductible
A37: amount | B37: 1000000
A38: currency | B38: USD
A39: risk definition | B39: occurrence
A40: pricing
A41: type | B41: adj rate
A42: adj rate % | B42: Layer 1: 5.50%; Layer 2: 3.25%; Layer 3: 1.85%
A43: subject base type | B43: estimated gross net premium income
A44: subject base amount | B44: ='Premium Information'!U26 -> 1136600000
...

Sheet Premium Information
A1: Insurer We
A2: 2025 Property Per risk Excess of Loss
A3: effective date: | B3: 45689
A5: Premium Information - Gross Net Earned Premium Income
A7: Data as of: | B7: 45565
A8: Currency: | B8: USD
B10: Gross net earned premium income
B11: Class of business | D11: State/ Year | E11: 2010 | F11: =E11+1 -> 2011 | G11: =F11+1 -> 2012 | H11: =G11+1 -> 2013 | I11: =H11+1 -> 2014 | J11: =I11+1 -> 2015 | K11: =J11+1 -> 2016 | L11: =K11+1 -> 2017 | M11: =L11+1 -> 2018 | ... R11: =Q11+1 -> 2023 | S11: 2024 Projected | T11: 2024 (as of 9/30/2024) | U11: 2025 projected
B12: Commercial Property | D12: CA | E12: 30842099 | F12: 41252079 | G12: 48330016 | H12: 54086496 | I12: 61973741 | J12: 67992367 | K12: 72418088 | L12: 94170148 | M12: 1.0066069e+08 | N12: 97959561 | O12: 1.1522933e+08 | P12: 1.2282359e+08 | Q12: 1.2495963e+08 | R12: 1.4539004e+08 | S12: 154640000 | T12: 1.1756147e+08 | U12: 164590000
D13: FL | E13: 29419754 | F13: 39146600 | G13: 46991021 | H13: 50288586 | I13: 57503804 | J13: 64995407 | K13: 72554921 | L13: 94893569 | M13: 1.0140873e+08 | N13: 98768766 | O13: 1.1743685e+08 | P13: 1.2492547e+08 | Q13: 1.3360427e+08 | R13: 1.544955e+08 | S13: 165980000 | T13: 1.2392585e+08 | U13: 173500000
D14: IL | E14: 6689670.6 | F14: 9096659.3 | G14: 10690990 | H14: 12070865 | I14: 13457186 | J14: 15159469 | K14: 15887061 | L14: 21247963 | M14: 22508105 | N14: 22215710 | O14: 26438512 | P14: 29082992 | Q14: 30052344 | R14: 34618350 | S14: 36270000 | T14: 27731356 | U14: 38820000
D15: NY | E15: 15041920 | F15: 21127315 | G15: 25958309 | H15: 27830157 | I15: 30815670 | J15: 34431496 | K15: 37544185 | L15: 47374139 | M15: 50156699 | N15: 51733685 | O15: 60153980 | P15: 64957311 | Q15: 68046668 | R15: 79721592 | S15: 81540000 | T15: 61566976 | U15: 86190000
D16: TX | E16: 24253837 | F16: 31664001 | G16: 39009937 | H16: 43963254 | I16: 48554648 | J16: 53179048 | K16: 58491942 | L16: 72764480 | M16: 80774821 | N16: 80233872 | O16: 98887741 | P16: 1.0373731e+08 | Q16: 1.0645626e+08 | R16: 1.2114642e+08 | S16: 127840000 | T16: 94704926 | U16: 132590000
D17: LoB Total | E17: =SUM(E12:E16) -> 1.0624728e+08 | F17: =SUM(F12:F16) -> 1.4228665e+08 | G17: =SUM(G12:G16) -> 1.7098027e+08 | H17: =SUM(H12:H16) -> 1.8823936e+08 | I17: =SUM(I12:I16) -> 2.1230505e+08 | J17: =SUM(J12:J16) -> 2.3575779e+08 | K17: =SUM(K12:K16) -> 2.568962e+08 | L17: =SUM(L12:L16) -> 3.304503e+08 | ... U17: =SUM(U12:U16) -> 595690000
B19: Personal Property | D19: CA | E19: 4840483.6 | F19: 6235549.7 | G19: 8294300 | H19: 10215307 | I19: 15771637 | J19: 22189623 | K19: 36148481 | L19: 45861057 | M19: 59996123 | N19: 62629673 | O19: 76356547 | P19: 76282373 | Q19: 91217848 | R19: 1.0446214e+08 | S19: 107530000 | T19: 93358168 | U19: 130700000
D20: FL | E20: 4503378.8 | F20: 6710185.6 | G20: 9345435.6 | H20: 12104619 | I20: 18057949 | J20: 25537596 | K20: 44239808 | L20: 55316496 | M20: 70278383 | N20: 75958172 | O20: 93440620 | P20: 93524107 | Q20: 1.1800832e+08 | R20: 1.4419845e+08 | S20: 151480000 | T20: 1.2728795e+08 | U20: 178200000
D21: IL | E21: 1254132.2 | F21: 1505866.7 | G21: 2101814.3 | H21: 2692284.6 | I21: 3816690 | J21: 5536214.1 | K21: 8609094.2 | L21: 10841405 | M21: 14263741 | N21: 15585477 | O21: 18805850 | P21: 18916482 | Q21: 24593439 | R21: 28918489 | S21: 30540000 | T21: 26102335 | U21: 36540000
D22: NY | E22: 3275230.8 | F22: 4203616.6 | G22: 5318166.8 | H22: 6269493 | I22: 9017861.4 | J22: 12627934 | K22: 21653171 | L22: 28422230 | M22: 34997230 | N22: 37032222 | O22: 44809876 | P22: 43362299 | Q22: 53904733 | R22: 62087099 | S22: 64940000 | T22: 56674520 | U22: 79340000
D23: TX | E23: 4675718.4 | F23: 5993375.6 | G23: 7594882.8 | H23: 8916970.8 | I23: 13072735 | J23: 17793107 | K23: 29226588 | L23: 37767657 | M23: 47149437 | N23: 50800272 | O23: 59831302 | P23: 58096004 | Q23: 71703762 | R23: 89003241 | S23: 95910000 | T23: 82950094 | U23: 116130000
D24: LoB Total | E24: =SUM(E19:E23) -> 18548944 | F24: =SUM(F19:F23) -> 24648594 | G24: =SUM(G19:G23) -> 32654599 | H24: =SUM(H19:H23) -> 40198675 | I24: =SUM(I19:I23) -> 59736873 | J24: =SUM(J19:J23) -> 83684474 | K24: =SUM(K19:K23) -> 1.3987714e+08 | L24: =SUM(L19:L23) -> 1.7820885e+08 | ... U24: =SUM(U19:U23) -> 540910000
B26: total subject GNEPI | E26: =E17+E24 -> 1.2479622e+08 | F26: =F17+F24 -> 1.6693525e+08 | G26: =G17+G24 -> 2.0363487e+08 | H26: =H17+H24 -> 2.2843803e+08 | I26: =I17+I24 -> 2.7204192e+08 | J26: =J17+J24 -> 3.1944226e+08 | K26: =K17+K24 -> 3.9677334e+08 | L26: =L17+L24 -> 5.0865914e+08 | ... U26: =U17+U24 -> 1136600000
B27: % change total | F27: =F26/E26-1 -> 0.33766265 | G27: =G26/F26-1 -> 0.21984347 | H27: =H26/G26-1 -> 0.12180213 | I27: =I26/H26-1 -> 0.1908784 | J27: =J26/I26-1 -> 0.1742391 | K27: =K26/J26-1 -> 0.24208156 | L27: =L26/K26-1 -> 0.28198922 | M27: =M26/L26-1 -> 0.14456598 | ... R27: =R26/Q26-1 -> 0.17201933

Sheet Premium Projection
A1: ='Premium Information'!A1 -> Insurer We
A2: ='Premium Information'!A2 -> 2025 Property Per risk Excess of Loss
A3: ='Premium Information'!A3 -> effective date: | B3: ='Premium Information'!B3 -> 45689
A5: Premium information - historical GNEPI projections
A7: ='Premium Information'!A7 -> Data as of: | B7: ='Premium Information'!B7 -> 45565
A8: ='Premium Information'!A8 -> Currency: | B8: ='Premium Information'!B8 -> USD
B10: historical actual GNEPI | P10: historical projected GNEPI
C11: Commercial Property | I11: Personal Property | O11: actual total GNEPI | P11: original projection
B12: State | C12: CA | D12: FL | E12: IL | F12: NY | G12: TX | I12: CA | J12: FL | K12: IL | L12: NY | M12: TX
A13: Year | B13: 2010 | C13: 30842099 | D13: 29419754 | E13: 6689670.6 | F13: 15041920 | G13: 24253837 | I13: 4840483.6 | J13: 4503378.8 | K13: 1254132.2 | L13: 3275230.8 | M13: 4675718.4 | O13: =SUM(C13:M13) -> 1.2479622e+08 | P13: 117310000
B14: 2011 | C14: 41252079 | D14: 39146600 | E14: 9096659.3 | F14: 21127315 | G14: 31664001 | I14: 6235549.7 | J14: 6710185.6 | K14: 1505866.7 | L14: 4203616.6 | M14: 5993375.6 | O14: =SUM(C14:M14) -> 1.6693525e+08 | P14: 163600000
B15: 2012 | C15: 48330016 | D15: 46991021 | E15: 10690990 | F15: 25958309 | G15: 39009937 | I15: 8294300 | J15: 9345435.6 | K15: 2101814.3 | L15: 5318166.8 | M15: 7594882.8 | O15: =SUM(C15:M15) -> 2.0363487e+08 | P15: 209740000
B16: 2013 | C16: 54086496 | D16: 50288586 | E16: 12070865 | F16: 27830157 | G16: 43963254 | I16: 10215307 | J16: 12104619 | K16: 2692284.6 | L16: 6269493 | M16: 8916970.8 | O16: =SUM(C16:M16) -> 2.2843803e+08 | P16: 226150000
B17: 2014 | C17: 61973741 | D17: 57503804 | E17: 13457186 | F17: 30815670 | G17: 48554648 | I17: 15771637 | J17: 18057949 | K17: 3816690 | L17: 9017861.4 | M17: 13072735 | O17: =SUM(C17:M17) -> 2.7204192e+08 | P17: 304690000
B18: 2015 | C18: 67992367 | D18: 64995407 | E18: 15159469 | F18: 34431496 | G18: 53179048 | I18: 22189623 | J18: 25537596 | K18: 5536214.1 | L18: 12627934 | M18: 17793107 | O18: =SUM(C18:M18) -> 3.1944226e+08 | P18: 335410000
B19: 2016 | C19: 72418088 | D19: 72554921 | E19: 15887061 | F19: 37544185 | G19: 58491942 | I19: 36148481 | J19: 44239808 | K19: 8609094.2 | L19: 21653171 | M19: 29226588 | O19: =SUM(C19:M19) -> 3.9677334e+08 | P19: 369000000
B20: 2017 | C20: 94170148 | D20: 94893569 | E20: 21247963 | F20: 47374139 | G20: 72764480 | I20: 45861057 | J20: 55316496 | K20: 10841405 | L20: 28422230 | M20: 37767657 | O20: =SUM(C20:M20) -> 5.0865914e+08 | P20: 513750000
B21: 2018 | C21: 1.0066069e+08 | D21: 1.0140873e+08 | E21: 22508105 | F21: 50156699 | G21: 80774821 | I21: 59996123 | J21: 70278383 | K21: 14263741 | L21: 34997230 | M21: 47149437 | O21: =SUM(C21:M21) -> 5.8219395e+08 | P21: 605480000
B22: 2019 | C22: 97959561 | D22: 98768766 | E22: 22215710 | F22: 51733685 | G22: 80233872 | I22: 62629673 | J22: 75958172 | K22: 15585477 | L22: 37032222 | M22: 50800272 | O22: =SUM(C22:M22) -> 5.9291741e+08 | P22: 527700000
B23: 2020 | C23: 1.1522933e+08 | D23: 1.1743685e+08 | E23: 26438512 | F23: 60153980 | G23: 98887741 | I23: 76356547 | J23: 93440620 | K23: 18805850 | L23: 44809876 | M23: 59831302 | O23: =SUM(C23:M23) -> 7.113906e+08 | P23: 675820000
B24: 2021 | C24: 1.2282359e+08 | D24: 1.2492547e+08 | E24: 29082992 | F24: 64957311 | G24: 1.0373731e+08 | I24: 76282373 | J24: 93524107 | K24: 18916482 | L24: 43362299 | M24: 58096004 | O24: =SUM(C24:M24) -> 7.3570794e+08 | P24: 801920000
B25: 2022 | C25: 1.2495963e+08 | D25: 1.3360427e+08 | E25: 30052344 | F25: 68046668 | G25: 1.0645626e+08 | I25: 91217848 | J25: 1.1800832e+08 | K25: 24593439 | L25: 53904733 | M25: 71703762 | O25: =SUM(C25:M25) -> 8.2254728e+08 | P25: 855450000
B26: 2023 | C26: 1.4539004e+08 | D26: 1.544955e+08 | E26: 34618350 | F26: 79721592 | G26: 1.2114642e+08 | I26: 1.0446214e+08 | J26: 1.4419845e+08 | K26: 28918489 | L26: 62087099 | M26: 89003241 | O26: =SUM(C26:M26) -> 9.6404131e+08 | P26: 904800000

Sheet Limit Profile (Commercial)
A1: ='Premium Information'!A1 -> Insurer We
A2: ='Premium Information'!A2 -> 2025 Property Per risk Excess of Loss
A3: ='Premium Information'!A3 -> effective date: | B3: ='Premium Information'!B3 -> 45689
A5: Exposure information - limits profile - Commercial Property
A7: ='Premium Information'!A7 -> Data as of: | B7: ='Premium Information'!B7 -> 45565
A8: ='Premium Information'!A8 -> Currency: | B8: ='Premium Information'!B8 -> USD
E9: by policies | G9: by locations | I9: by buildings
E10: premiums | F10: number of policies | G10: premiums | H10: number of locations | I10: premiums | J10: number of buildings
B11: gross limits range
B12: 1 | C12: to | D12: 500000 | E12: 3457223.4 | F12: 660 | G12: 12285558 | H12: 3071 | I12: 25770581 | J12: 7435
B13: =D12+1 -> 500001 | C13: to | D13: =D12+500000 -> 1000000 | E13: 12827918 | F13: 1224 | G13: 33672187 | H13: 3767 | I13: 59580557 | J13: 6872
B14: =D13+1 -> 1000001 | C14: to | D14: =D13+500000 -> 1500000 | E14: 9324623.4 | F14: 598 | G14: 35462262 | H14: 2543 | I14: 44394526 | J14: 3296
B15: =D14+1 -> 1500001 | C15: to | D15: =D14+500000 -> 2000000 | E15: 36955015 | F15: 1771 | G15: 60657821 | H15: 3189 | I15: 69604300 | J15: 3717
B16: =D15+1 -> 2000001 | C16: to | D16: =D15+500000 -> 2500000 | E16: 16266169 | F16: 624 | G16: 47610827 | H16: 1856 | I16: 87857341 | J16: 3404
B17: =D16+1 -> 2500001 | C17: to | D17: =D16+500000 -> 3000000 | E17: 19075573 | F17: 620 | G17: 9449915.8 | H17: 304 | I17: 5163469 | J17: 167
B18: =D17+1 -> 3000001 | C18: to | D18: =D17+500000 -> 3500000 | E18: 24792505 | F18: 684 | G18: 63367125 | H18: 1814 | I18: 39205679 | J18: 1129
B19: =D18+1 -> 3500001 | C19: to | D19: =D18+500000 -> 4000000 | E19: 52647158 | F19: 1269 | G19: 27929463 | H19: 662 | I19: 17672506 | J19: 413
B20: =D19+1 -> 4000001 | C20: to | D20: =D19+500000 -> 4500000 | E20: 28858040 | F20: 628 | G20: 14558352 | H20: 316 | I20: 8684864.6 | J20: 188
B21: =D20+1 -> 4500001 | C21: to | D21: =D20+500000 -> 5000000 | E21: 97157687 | F21: 1867 | G21: 1.2480476e+08 | H21: 2405 | I21: 1.2017864e+08 | J21: 2315
B22: ="greater than "&D21 -> greater than 5000000 | E22: 2.5500921e+08 | F22: 2441 | G22: 1.2657285e+08 | H22: 1203 | I22: 78258659 | J22: 742
B23: total | E23: =SUM(E12:E22) -> 5.5637113e+08 | F23: =SUM(F12:F22) -> 12386 | G23: =SUM(G12:G22) -> 5.5637113e+08 | H23: =SUM(H12:H22) -> 21130 | I23: =SUM(I12:I22) -> 5.5637113e+08 | J23: =SUM(J12:J22) -> 29678
A25: =A7 -> Data as of: | B25: 45199
A26: =A8 -> Currency:
E27: by policies | G27: by locations | I27: by buildings
E28: premiums | F28: number of policies | G28: premiums | H28: number of locations | I28: premiums | J28: number of buildings
B29: gross limits range
B30: 1 | C30: to | D30: 500000 | E30: 3125441.1 | F30: 609 | G30: 10873362 | H30: 2790 | I30: 23171463 | J30: 6768
B31: =D30+1 -> 500001 | C31: to | D31: =D30+500000 -> 1000000 | E31: 11520445 | F31: 1132 | G31: 31768570 | H31: 3613 | I31: 56841189 | J31: 6684
B32: =D31+1 -> 1000001 | C32: to | D32: =D31+500000 -> 1500000 | E32: 8679440.1 | F32: 565 | G32: 32885615 | H32: 2406 | I32: 40685275 | J32: 3073
B33: =D32+1 -> 1500001 | C33: to | D33: =D32+500000 -> 2000000 | E33: 35335924 | F33: 1733 | G33: 57912843 | H33: 3095 | I33: 64942707 | J33: 3526
B34: =D33+1 -> 2000001 | C34: to | D34: =D33+500000 -> 2500000 | E34: 14716343 | F34: 576 | G34: 43721676 | H34: 1734 | I34: 81150255 | J34: 3198
B35: =D34+1 -> 2500001 | C35: to | D35: =D34+500000 -> 3000000 | E35: 17846363 | F35: 587 | G35: 8711029.1 | H35: 284 | I35: 4861349.1 | J35: 162
B36: =D35+1 -> 3000001 | C36: to | D36: =D35+500000 -> 3500000 | E36: 22839496 | F36: 646 | G36: 58255593 | H36: 1688 | I36: 35989355 | J36: 1044
B37: =D36+1 -> 3500001 | C37: to | D37: =D36+500000 -> 4000000 | E37: 48154177 | F37: 1192 | G37: 25051472 | H37: 611 | I37: 15759872 | J37: 380
B38: =D37+1 -> 4000001 | C38: to | D38: =D37+500000 -> 4500000 | E38: 27276459 | F38: 604 | G38: 14067176 | H38: 311 | I38: 8301431.4 | J38: 180
B39: =D38+1 -> 4500001 | C39: to | D39: =D38+500000 -> 5000000 | E39: 89622325 | F39: 1760 | G39: 1.1499749e+08 | H39: 2257 | I39: 1.1393631e+08 | J39: 2242
B40: ="greater than "&D39 -> greater than 5000000 | E40: 2.3894361e+08 | F40: 2331 | G40: 1.1981519e+08 | H40: 1170 | I40: 72420816 | J40: 708
B41: total | E41: =SUM(E30:E40) -> 5.1806002e+08 | F41: =SUM(F30:F40) -> 11735 | G41: =SUM(G30:G40) -> 5.1806002e+08 | H41: =SUM(H30:H40) -> 19959 | I41: =SUM(I30:I40) -> 5.1806002e+08 | J41: =SUM(J30:J40) -> 27965

Sheet Limit Profile (Personal)
A1: ='Premium Information'!A1 -> Insurer We
A2: ='Premium Information'!A2 -> 2025 Property Per risk Excess of Loss
A3: ='Premium Information'!A3 -> effective date: | B3: ='Premium Information'!B3 -> 45689
A5: Exposure information - limits profile - Personal Property
A7: ='Premium Information'!A7 -> Data as of: | B7: ='Premium Information'!B7 -> 45565
A8: ='Premium Information'!A8 -> Currency: | B8: ='Premium Information'!B8 -> USD
E9: by policies | G9: by locations | I9: by buildings
E10: premiums | F10: number of policies | G10: premiums | H10: number of locations | I10: premiums | J10: number of buildings
B11: gross limits range
B12: 1 | C12: to | D12: 500000 | E12: 3675208.7 | F12: 545 | G12: 15516403 | H12: 2983 | I12: 37566508 | J12: 7810
B13: =D12+1 -> 500001 | C13: to | D13: =D12+500000 -> 1000000 | E13: 20285755 | F13: 1477 | G13: 54006704 | H13: 4448 | I13: 76116391 | J13: 6518
B14: =D13+1 -> 1000001 | C14: to | D14: =D13+500000 -> 1500000 | E14: 10103086 | F14: 501 | G14: 49269264 | H14: 2608 | I14: 56160370 | J14: 3027
B15: =D14+1 -> 1500001 | C15: to | D15: =D14+500000 -> 2000000 | E15: 57951342 | F15: 2104 | G15: 68582249 | H15: 2628 | I15: 71955823 | J15: 2787
B16: =D15+1 -> 2000001 | C16: to | D16: =D15+500000 -> 2500000 | E16: 18584895 | F16: 534 | G16: 38993065 | H16: 1165 | I16: 59208465 | J16: 1746
B17: =D16+1 -> 2500001 | C17: to | D17: =D16+500000 -> 3000000 | E17: 43257249 | F17: 1057 | G17: 21900185 | H17: 535 | I17: 13122794 | J17: 325
B18: =D17+1 -> 3000001 | C18: to | D18: =D17+500000 -> 3500000 | E18: 25960064 | F18: 532 | G18: 43188227 | H18: 904 | I18: 25410622 | J18: 531
B19: =D18+1 -> 3500001 | C19: to | D19: =D18+500000 -> 4000000 | E19: 62174389 | F19: 1107 | G19: 30746798 | H19: 542 | I19: 19293612 | J19: 339
B20: =D19+1 -> 4000001 | C20: to | D20: =D19+500000 -> 4500000 | E20: 32826421 | F20: 523 | G20: 16670831 | H20: 265 | I20: 10380963 | J20: 164
B21: =D20+1 -> 4500001 | C21: to | D21: =D20+500000 -> 5000000 | E21: 70062038 | F21: 1025 | G21: 78860734 | H21: 1140 | I21: 77776523 | J21: 1132
B22: ="greater than "&D21 -> greater than 5000000 | E22: 1.4844536e+08 | F22: 1072 | G22: 75591352 | H22: 551 | I22: 46333742 | J22: 339
B23: total | E23: =SUM(E12:E22) -> 4.9332581e+08 | F23: =SUM(F12:F22) -> 10477 | G23: =SUM(G12:G22) -> 4.9332581e+08 | H23: =SUM(H12:H22) -> 17769 | I23: =SUM(I12:I22) -> 4.9332581e+08 | J23: =SUM(J12:J22) -> 24718
A25: =A7 -> Data as of: | B25: ='Limit Profile (Commercial)'!B25 -> 45199
A26: =A8 -> Currency:
E27: by policies | G27: by locations | I27: by buildings
E28: premiums | F28: number of policies | G28: premiums | H28: number of locations | I28: premiums | J28: number of buildings
B29: gross limits range
B30: 1 | C30: to | D30: 500000 | E30: 2999405.1 | F30: 495 | G30: 12860039 | H30: 2724 | I30: 30732871 | J30: 7163
B31: =D30+1 -> 500001 | C31: to | D31: =D30+500000 -> 1000000 | E31: 17053903 | F31: 1372 | G31: 45342486 | H31: 4160 | I31: 64516056 | J31: 6177
B32: =D31+1 -> 1000001 | C32: to | D32: =D31+500000 -> 1500000 | E32: 8312889.3 | F32: 456 | G32: 42002758 | H32: 2475 | I32: 45941711 | J32: 2768
B33: =D32+1 -> 1500001 | C33: to | D33: =D32+500000 -> 2000000 | E33: 48348834 | F33: 1958 | G33: 56074618 | H33: 2403 | I33: 60444173 | J33: 2633
B34: =D33+1 -> 2000001 | C34: to | D34: =D33+500000 -> 2500000 | E34: 15756872 | F34: 514 | G34: 32354481 | H34: 1080 | I34: 50126414 | J34: 1663
B35: =D34+1 -> 2500001 | C35: to | D35: =D34+500000 -> 3000000 | E35: 36591275 | F35: 995 | G35: 18356559 | H35: 497 | I35: 10800117 | J35: 297
B36: =D35+1 -> 3000001 | C36: to | D36: =D35+500000 -> 3500000 | E36: 21416346 | F36: 493 | G36: 36957014 | H36: 875 | I36: 21646207 | J36: 507
B37: =D36+1 -> 3500001 | C37: to | D37: =D36+500000 -> 4000000 | E37: 50537806 | F37: 991 | G37: 25455112 | H37: 488 | I37: 16034387 | J37: 303
B38: =D37+1 -> 4000001 | C38: to | D38: =D37+500000 -> 4500000 | E38: 27467147 | F38: 485 | G38: 13988248 | H38: 246 | I38: 8556985.3 | J38: 150
B39: =D38+1 -> 4500001 | C39: to | D39: =D38+500000 -> 5000000 | E39: 58915179 | F39: 967 | G39: 65308694 | H39: 1072 | I39: 63627111 | J39: 1043
B40: ="greater than "&D39 -> greater than 5000000 | E40: 1.2460235e+08 | F40: 1009 | G40: 63301995 | H40: 511 | I40: 39575969 | J40: 319
B41: total | E41: =SUM(E30:E40) -> 4.12002e+08 | F41: =SUM(F30:F40) -> 9735 | G41: =SUM(G30:G40) -> 4.12002e+08 | H41: =SUM(H30:H40) -> 16531 | I41: =SUM(I30:I40) -> 4.12002e+08 | J41: =SUM(J30:J40) -> 23023

Sheet Exposure Listing (Commercial)
A1: ='Premium Information'!A1 -> Insurer We
A2: ='Premium Information'!A2 -> 2025 Property Per risk Excess of Loss
A3: ='Premium Information'!A3 -> effective date: | B3: ='Premium Information'!B3 -> 45689
A5: Exposure Listing - Commercial Property
A7: ='Premium Information'!A7 -> Data as of: | B7: ='Premium Information'!B7 -> 45565
A8: ='Premium Information'!A8 -> Currency: | B8: ='Premium Information'!B8 -> USD
A10: Notes: | B10: ="Policies incepting between "&TEXT(EOMONTH(B7,-12)+1,"Mmmm dd, yyyy")&" and "&TEXT(B7,"Mmmm dd, yyyy") -> Policies incepting between October 01, 2023 and September 30, 2024
A13: Policy ID | B13: Insured ID | C13: Policy Year | D13: Effective Date | E13: Expiration Date | F13: New/Renewed | G13: State | H13: # Locations | I13: # Buildings | J13: Written Premium | K13: Limit
A14: P1-239063 | B14: L1-232241 | C14: 2023 | D14: 45200 | E14: 45565 | F14: New | G14: NY | H14: 2 | I14: 4 | J14: 14729.4 | K14: 2000000
A15: P1-239064 | B15: L1-232242 | C15: 2023 | D15: 45200 | E15: 45565 | F15: New | G15: FL | H15: 3 | I15: 6 | J15: 15388.68 | K15: 1000000
A16: P1-239065 | B16: L1-232243 | C16: 2023 | D16: 45200 | E16: 45565 | F16: New | G16: NY | H16: 1 | I16: 1 | J16: 35473.98 | K16: 5000000
A17: P1-239066 | B17: L1-232244 | C17: 2023 | D17: 45200 | E17: 45565 | F17: New | G17: CA | H17: 1 | I17: 2 | J17: 14782.58 | K17: 1500000
A18: P1-239067 | B18: L1-232245 | C18: 2023 | D18: 45200 | E18: 45565 | F18: New | G18: CA | H18: 2 | I18: 2 | J18: 18007.56 | K18: 2000000
A19: P1-239068 | B19: L1-211184 | C19: 2023 | D19: 45200 | E19: 45565 | F19: Renewed | G19: IL | H19: 2 | I19: 4 | J19: 31484.16 | K19: 5000000
A20: P1-239069 | B20: L1-211181 | C20: 2023 | D20: 45200 | E20: 45565 | F20: Renewed | G20: NY | H20: 1 | I20: 1 | J20: 17948.27 | K20: 2500000
A21: P1-239070 | B21: L1-172135 | C21: 2023 | D21: 45200 | E21: 45565 | F21: Renewed | G21: TX | H21: 2 | I21: 2 | J21: 116099.12 | K21: 10000000
A22: P1-239071 | B22: L1-172139 | C22: 2023 | D22: 45200 | E22: 45565 | F22: Renewed | G22: TX | H22: 3 | I22: 3 | J22: 40191.23 | K22: 3500000
A23: P1-239072 | B23: L1-221115 | C23: 2023 | D23: 45200 | E23: 45565 | F23: Renewed | G23: CA | H23: 1 | I23: 1 | J23: 27405.4 | K23: 3000000
A24: P1-239073 | B24: L1-141116 | C24: 2023 | D24: 45200 | E24: 45565 | F24: Renewed | G24: TX | H24: 1 | I24: 1 | J24: 22411.63 | K24: 2000000
A25: P1-239074 | B25: L1-172138 | C25: 2023 | D25: 45200 | E25: 45565 | F25: Renewed | G25: TX | H25: 2 | I25: 4 | J25: 32281.82 | K25: 3000000
... A12399: P1-249381 | B12399: L1-121041 | C12399: 2024 | D12399: 45565 | E12399: 45929 | F12399: Renewed | G12399: TX | H12399: 2 | I12399: 2 | J12399: 54093.93 | K12399: 5000000

Sheet Exposure Listing (Personal)
A1: ='Premium Information'!A1 -> Insurer We
A2: ='Premium Information'!A2 -> 2025 Property Per risk Excess of Loss
A3: ='Premium Information'!A3 -> effective date: | B3: ='Premium Information'!B3 -> 45689
A5: Exposure Listing - Personal Property
A7: ='Premium Information'!A7 -> Data as of: | B7: ='Premium Information'!B7 -> 45565
A8: ='Premium Information'!A8 -> Currency: | B8: ='Premium Information'!B8 -> USD
A10: Notes: | B10: ="Policies incepting between "&TEXT(EOMONTH(B7,-12)+1,"Mmmm dd, yyyy")&" and "&TEXT(B7,"Mmmm dd, yyyy") -> Policies incepting between October 01, 2023 and September 30, 2024
A13: Policy ID | B13: Insured ID | C13: Policy Year | D13: Effective Date | E13: Expiration Date | F13: New/Renewed | G13: State | H13: # Locations | I13: # Buildings | J13: Written Premium | K13: Limit
A14: P2-237339 | B14: L2-231280 | C14: 2023 | D14: 45200 | E14: 45565 | F14: New | G14: CA | H14: 3 | I14: 6 | J14: 34811.69 | K14: 3000000
A15: P2-237340 | B15: L2-231281 | C15: 2023 | D15: 45200 | E15: 45565 | F15: New | G15: CA | H15: 1 | I15: 2 | J15: 39918.54 | K15: 4000000
A16: P2-237341 | B16: L2-231282 | C16: 2023 | D16: 45200 | E16: 45565 | F16: New | G16: CA | H16: 2 | I16: 2 | J16: 114392.61 | K16: 10000000
A17: P2-237342 | B17: L2-231283 | C17: 2023 | D17: 45200 | E17: 45565 | F17: New | G17: FL | H17: 1 | I17: 1 | J17: 205444.28 | K17: 10000000
A18: P2-237343 | B18: L2-231284 | C18: 2023 | D18: 45200 | E18: 45565 | F18: New | G18: IL | H18: 1 | I18: 1 | J18: 8542.86 | K18: 1000000
A19: P2-237344 | B19: L2-231285 | C19: 2023 | D19: 45200 | E19: 45565 | F19: New | G19: CA | H19: 1 | I19: 1 | J19: 46690.68 | K19: 4000000
A20: P2-237345 | B20: L2-231286 | C20: 2023 | D20: 45200 | E20: 45565 | F20: New | G20: CA | H20: 1 | I20: 1 | J20: 39218.34 | K20: 4000000
A21: P2-237346 | B21: L2-231287 | C21: 2023 | D21: 45200 | E21: 45565 | F21: New | G21: CA | H21: 2 | I21: 2 | J21: 10358.03 | K21: 1000000
A22: P2-237347 | B22: L2-161931 | C22: 2023 | D22: 45200 | E22: 45565 | F22: Renewed | G22: NY | H22: 1 | I22: 2 | J22: 29473.54 | K22: 3000000
A23: P2-237348 | B23: L2-161928 | C23: 2023 | D23: 45200 | E23: 45565 | F23: Renewed | G23: TX | H23: 1 | I23: 2 | J23: 45261.26 | K23: 4000000
A24: P2-237349 | B24: L2-210991 | C24: 2023 | D24: 45200 | E24: 45565 | F24: Renewed | G24: CA | H24: 1 | I24: 2 | J24: 22790.76 | K24: 2000000
A25: P2-237350 | B25: L2-191235 | C25: 2023 | D25: 45200 | E25: 45565 | F25: Renewed | G25: NY | H25: 2 | I25: 2 | J25: 9893.49 | K25: 1000000
... A10490: P2-248009 | B10490: L2-161922 | C10490: 2024 | D10490: 45565 | E10490: 45929 | F10490: Renewed | G10490: NY | H10490: 1 | I10490: 2 | J10490: 58724.15 | K10490: 5000000

Sheet Claim (Non-Cat Commercial)
A1: ='Premium Information'!A1 -> Insurer We
A2: ='Premium Information'!A2 -> 2025 Property Per risk Excess of Loss
A3: ='Premium Information'!A3 -> effective date: | B3: ='Premium Information'!B3 -> 45689
A5: Experience information - Commercial Property - Non-Cat losses
A7: ='Premium Information'!A7 -> Data as of: | B7: ='Premium Information'!B7 -> 45565
A8: ='Premium Information'!A8 -> Currency: | B8: ='Premium Information'!B8 -> USD
A10: Notes: gross incurred losses greater than $50000 excluding large catastrophe (from AY 2015 to 2024); paid/outstanding/gross incurred losses include expense and can be greater than policy limit
A12: Claim No. | B12: Open/Closed | C12: Effective Date | D12: Risk Location | E12: Policy Limit | F12: Loss Date | G12: Report Date | H12: AY | I12: Cat/Non-Cat | J12: Paid Loss | K12: Outstanding Loss | L12: Gross Incurred Loss | M12: Description | N12: Cat Type | O12: comments - whether we would write again (yes/no) | P12: restated loss on go forward basis
A13: C1-0999 | B13: Closed | C13: 41788 | D13: NY | E13: 2000000 | F13: 42023 | G13: 42058 | H13: 2015 | I13: Non-Cat | J13: 352700.35 | K13: 0 | L13: 352700.35 | M13: Extensive water loss from failed riser damaged multiple floors and vertical shafts. | O13: no | P13: 0
A14: C1-1000 | B14: Closed | C14: 41674 | D14: CA | E14: 2000000 | F14: 42028 | G14: 42059 | H14: 2015 | I14: Non-Cat | J14: 238075.83 | K14: 0 | L14: 238075.83 | M14: Production line fire damaged structure, controls, and finished goods inventory. | O14: no | P14: 0
A15: C1-1007 | B15: Closed | C15: 42013 | D15: IL | E15: 3000000 | F15: 42032 | G15: 42064 | H15: 2015 | I15: Non-Cat | J15: 928521.7 | K15: 0 | L15: 928521.7 | M15: Large explosion and ensuing fire gutted distribution center and contents. | O15: no | P15: 0
A16: C1-1019 | B16: Closed | C16: 41799 | D16: FL | E16: 5000000 | F16: 42021 | G16: 42071 | H16: 2015 | I16: Non-Cat | J16: 224789.21 | K16: 0 | L16: 224789.21 | M16: Large ductwork fire spread smoke throughout hotel tower and common areas. | O16: yes | P16: 224789.21
A17: C1-1025 | B17: Closed | C17: 41731 | D17: FL | E17: 1000000 | F17: 42008 | G17: 42079 | H17: 2015 | I17: Non-Cat | J17: 68238.63 | K17: 0 | L17: 68238.63 | M17: Partial ceiling collapse damaged furniture showroom inventory and decorative fixtures. | O17: yes | P17: 68238.63
A18: C1-1029 | B18: Closed | C18: 41863 | D18: TX | E18: 2500000 | F18: 42044 | G18: 42082 | H18: 2015 | I18: Non-Cat | J18: 78403.71 | K18: 0 | L18: 78403.71 | M18: Sprinkler head impact flooded archive room, destroying paper files and finishes. | O18: yes | P18: 78403.71
A19: C1-1033 | B19: Closed | C19: 41954 | D19: CA | E19: 3000000 | F19: 42052 | G19: 42088 | H19: 2015 | I19: Non-Cat | J19: 121131.51 | K19: 0 | L19: 121131.51 | M19: Collapsing mezzanine section damaged machinery, stock, and lower-level workstations. | O19: yes | P19: 121131.51
A20: C1-1037 | B20: Closed | C20: 41968 | D20: NY | E20: 5000000 | F20: 42040 | G20: 42092 | H20: 2015 | I20: Non-Cat | J20: 99276.51 | K20: 0 | L20: 99276.51 | M20: Facade seal failure allowed persistent water infiltration into upper-floor offices. | O20: yes | P20: 99276.51
A21: C1-1040 | B21: Closed | C21: 41776 | D21: TX | E21: 10000000 | F21: 42024 | G21: 42094 | H21: 2015 | I21: Non-Cat | J21: 68657.09 | K21: 0 | L21: 68657.09 | M21: Pipe leak behind wall spread mold requiring remediation and buildback in several rooms. | O21: yes | P21: 68657.09
A22: C1-1041 | B22: Closed | C22: 41887 | D22: CA | E22: 2000000 | F22: 42065 | G22: 42096 | H22: 2015 | I22: Non-Cat | J22: 141234.41 | K22: 0 | L22: 141234.41 | M22: Fire in laundry area spread smoke and heat damage through several floors. | O22: yes | P22: 141234.41
A23: C1-1046 | B23: Closed | C23: 41984 | D23: FL | E23: 4000000 | F23: 42026 | G23: 42104 | H23: 2015 | I23: Non-Cat | J23: 65833.02 | K23: 0 | L23: 65833.02 | M23: Storm-related water entry damaged common areas, fitness room, and leasing office. | O23: yes | P23: 65833.02
A24: C1-1051 | B24: Closed | C24: 41787 | D24: TX | E24: 10000000 | F24: 42065 | G24: 42107 | H24: 2015 | I24: Non-Cat | J24: 118514.52 | K24: 0 | L24: 118514.52 | M24: Collapsing mezzanine section damaged machinery, stock, and lower-level workstations. | O24: yes | P24: 118514.52
... A2258: C1-5514 | B2258: Open | C2258: 45339 | D2258: FL | E2258: 5000000 | F2258: 45512 | G2258: 45565 | H2258: 2024 | I2258: Non-Cat | J2258: 0 | K2258: 86112.24 | L2258: 86112.24 | M2258: Fire in laundry area spread smoke and heat damage through several floors. | O2258: yes | P2258: 86112.24

Sheet Claim (Cat Commercial)
A1: ='Premium Information'!A1 -> Insurer We
A2: ='Premium Information'!A2 -> 2025 Property Per risk Excess of Loss
A3: ='Premium Information'!A3 -> effective date: | B3: ='Premium Information'!B3 -> 45689
A5: Experience information - Commercial Property - large losses from cat events
A7: ='Premium Information'!A7 -> Data as of: | B7: ='Premium Information'!B7 -> 45565
A8: ='Premium Information'!A8 -> Currency: | B8: ='Premium Information'!B8 -> USD
A10: Notes: gross incurred losses greater than $250000 for large catastrophe only (from AY 2015 to 2024); paid/outstanding/gross incurred losses include expense and can be greater than policy limit
A12: Claim No. | B12: Open/Closed | C12: Effective Date | D12: Risk Location | E12: Policy Limit | F12: Loss Date | G12: Report Date | H12: AY | I12: Cat/Non-Cat | J12: Paid Loss | K12: Outstanding Loss | L12: Gross Incurred Loss | M12: Description | N12: Cat Type | O12: comments - whether we would write again (yes/no) | P12: restated loss on go forward basis
A13: C1-1028 | B13: Closed | C13: 41675 | D13: FL | E13: 10000000 | F13: 42028 | G13: 42081 | H13: 2015 | I13: Cat | J13: 775419.31 | K13: 0 | L13: 775419.31 | M13: Mudflow after wildfire overwhelmed the commercial site, filling ground floors with debris and causing major property damage. | N13: mudflow | O13: yes | P13: 775419.31
A14: C1-1042 | B14: Closed | C14: 41729 | D14: FL | E14: 3000000 | F14: 42025 | G14: 42097 | H14: 2015 | I14: Cat | J14: 989713.04 | K14: 0 | L14: 989713.04 | M14: Wildfire destroyed multiple commercial buildings, with ember-driven roof ignition and heavy smoke contamination throughout the complex. | N14: wildfire | O14: no | P14: 0
A15: C1-1044 | B15: Closed | C15: 42042 | D15: FL | E15: 3000000 | F15: 42045 | G15: 42100 | H15: 2015 | I15: Cat | J15: 889929.71 | K15: 0 | L15: 889929.71 | M15: Earthquake shifted the foundation and fractured utility lines, leading to extensive structural and water damage. | N15: earthquake | O15: yes | P15: 889929.71
A16: C1-1052 | B16: Closed | C16: 41990 | D16: FL | E16: 2000000 | F16: 42059 | G16: 42108 | H16: 2015 | I16: Cat | J16: 762408.45 | K16: 0 | L16: 762408.45 | M16: Earthquake triggered partial facade collapse and extensive interior damage across several occupied commercial units. | N16: earthquake | O16: yes | P16: 762408.45
A17: C1-1062 | B17: Closed | C17: 41918 | D17: CA | E17: 5000000 | F17: 42054 | G17: 42117 | H17: 2015 | I17: Cat | J17: 1035824.5 | K17: 0 | L17: 1035824.5 | M17: Earthquake caused severe structural cracking, partial collapse, and major interior damage to a multi-tenant commercial property. | N17: earthquake | O17: no | P17: 0
A18: C1-1083 | B18: Closed | C18: 41856 | D18: CA | E18: 4000000 | F18: 42106 | G18: 42145 | H18: 2015 | I18: Cat | J18: 604302.16 | K18: 0 | L18: 604302.16 | M18: Earthquake triggered partial facade collapse and extensive interior damage across several occupied commercial units. | N18: earthquake | O18: yes | P18: 604302.16
A19: C1-1110 | B19: Closed | C19: 41889 | D19: TX | E19: 10000000 | F19: 42147 | G19: 42178 | H19: 2015 | I19: Cat | J19: 360001.94 | K19: 0 | L19: 360001.94 | M19: Atmospheric river flood inundated retail and office space, destroying interiors, equipment, and lower-level mechanical systems. | N19: flood | O19: yes | P19: 360001.94
A20: C1-1115 | B20: Closed | C20: 41787 | D20: NY | E20: 10000000 | F20: 42120 | G20: 42180 | H20: 2015 | I20: Cat | J20: 1015181.8 | K20: 0 | L20: 1015181.8 | M20: Atmospheric river flood inundated retail and office space, destroying interiors, equipment, and lower-level mechanical systems. | N20: flood | O20: no | P20: 0
A21: C1-1137 | B21: Closed | C21: 42100 | D21: CA | E21: 10000000 | F21: 42133 | G21: 42198 | H21: 2015 | I21: Cat | J21: 1613394.9 | K21: 0 | L21: 1613394.9 | M21: Atmospheric river flood inundated retail and office space, destroying interiors, equipment, and lower-level mechanical systems. | N21: flood | O21: yes | P21: 1613394.9
A22: C1-1160 | B22: Closed | C22: 41948 | D22: FL | E22: 4000000 | F22: 42148 | G22: 42231 | H22: 2015 | I22: Cat | J22: 364100.71 | K22: 0 | L22: 364100.71 | M22: Atmospheric river flood inundated retail and office space, destroying interiors, equipment, and lower-level mechanical systems. | N22: flood | O22: yes | P22: 364100.71
A23: C1-1169 | B23: Closed | C23: 42192 | D23: CA | E23: 10000000 | F23: 42194 | G23: 42244 | H23: 2015 | I23: Cat | J23: 1902695.1 | K23: 0 | L23: 1902695.1 | M23: Mudflow after wildfire overwhelmed the commercial site, filling ground floors with debris and causing major property damage. | N23: mudflow | O23: no | P23: 0
A24: C1-1171 | B24: Closed | C24: 41833 | D24: NY | E24: 10000000 | F24: 42183 | G24: 42246 | H24: 2015 | I24: Cat | J24: 3925750.7 | K24: 0 | L24: 3925750.7 | M24: Wildfire smoke and suppression water rendered a hotel property heavily damaged and temporarily unusable. | N24: wildfire | O24: no | P24: 0
... A534: C1-5503 | B534: Open | C534: 44876 | D534: NY | E534: 4000000 | F534: 45194 | G534: 45558 | H534: 2023 | I534: Cat | J534: 0 | K534: 400971.51 | L534: 400971.51 | M534: Severe convective storm tore off roofing and allowed heavy rain intrusion, damaging inventory, ceilings, and electrical systems. | N534: convective storm | O534: no | P534: 0

Sheet Claim (Non-Cat Personal)
A1: ='Premium Information'!A1 -> Insurer We
A2: ='Premium Information'!A2 -> 2025 Property Per risk Excess of Loss
A3: ='Premium Information'!A3 -> effective date: | B3: ='Premium Information'!B3 -> 45689
A5: Experience information - Personal Property - Non-Cat losses
A7: ='Premium Information'!A7 -> Data as of: | B7: ='Premium Information'!B7 -> 45565
A8: ='Premium Information'!A8 -> Currency: | B8: ='Premium Information'!B8 -> USD
A10: Notes: gross incurred losses greater than $50000 excluding large catastrophe (from AY 2015 to 2024); paid/outstanding/gross incurred losses include expense and can be greater than policy limit
A12: Claim No. | B12: Open/Closed | C12: Effective Date | D12: Risk Location | E12: Policy Limit | F12: Loss Date | G12: Report Date | H12: AY | I12: Cat/Non-Cat | J12: Paid Loss | K12: Outstanding Loss | L12: Gross Incurred Loss | M12: Description | N12: Cat Type | O12: comments - whether we would write again (yes/no) | P12: restated loss on go forward basis
A13: C2-0235 | B13: Closed | C13: 41962 | D13: CA | E13: 4500000 | F13: 42006 | G13: 42043 | H13: 2015 | I13: Non-Cat | J13: 253094.94 | K13: 0 | L13: 253094.94 | M13: Roof collapse over bedroom damaged furnishings, clothing, and structural finishes. | O13: yes | P13: 253094.94
A14: C2-0249 | B14: Closed | C14: 41979 | D14: FL | E14: 2500000 | F14: 42055 | G14: 42107 | H14: 2015 | I14: Non-Cat | J14: 273428.74 | K14: 0 | L14: 273428.74 | M14: Attic fire caused heavy smoke damage and destruction of stored possessions. | O14: yes | P14: 273428.74
A15: C2-0253 | B15: Closed | C15: 41985 | D15: CA | E15: 3000000 | F15: 42047 | G15: 42129 | H15: 2015 | I15: Non-Cat | J15: 114700.83 | K15: 0 | L15: 114700.83 | M15: Roof leak damaged custom drapes, furniture, and hardwood flooring below. | O15: yes | P15: 114700.83
A16: C2-0254 | B16: Closed | C16: 41753 | D16: FL | E16: 2000000 | F16: 42088 | G16: 42135 | H16: 2015 | I16: Non-Cat | J16: 124067.53 | K16: 0 | L16: 124067.53 | M16: Leak from radiant heating system damaged flooring and built-in cabinetry. | O16: yes | P16: 124067.53
A17: C2-0259 | B17: Closed | C17: 41733 | D17: TX | E17: 10000000 | F17: 42071 | G17: 42160 | H17: 2015 | I17: Non-Cat | J17: 177542.94 | K17: 0 | L17: 177542.94 | M17: Garage fire spread into living area, damaging contents and structural finishes. | O17: yes | P17: 177542.94
A18: C2-0272 | B18: Closed | C18: 41819 | D18: FL | E18: 2000000 | F18: 42138 | G18: 42194 | H18: 2015 | I18: Non-Cat | J18: 112684.43 | K18: 0 | L18: 112684.43 | M18: Sump pump failure flooded basement, damaging furniture, rugs, and appliances. | O18: yes | P18: 112684.43
A19: C2-0274 | B19: Closed | C19: 41758 | D19: CA | E19: 4000000 | F19: 42044 | G19: 42204 | H19: 2015 | I19: Non-Cat | J19: 180848.43 | K19: 0 | L19: 180848.43 | M19: Appliance fire damaged kitchen, dining room, and smoke-affected upper-level rooms. | O19: yes | P19: 180848.43
A20: C2-0275 | B20: Closed | C20: 42012 | D20: NY | E20: 5000000 | F20: 42125 | G20: 42204 | H20: 2015 | I20: Non-Cat | J20: 1527767.5 | K20: 0 | L20: 1527767.5 | M20: Catastrophic fire loss consumed most rooms and nearly all household belongings. | O20: yes | P20: 1527767.5
A21: C2-0277 | B21: Closed | C21: 42091 | D21: NY | E21: 10000000 | F21: 42167 | G21: 42207 | H21: 2015 | I21: Non-Cat | J21: 1548038.5 | K21: 0 | L21: 1548038.5 | M21: Catastrophic fire loss consumed most rooms and nearly all household belongings. | O21: yes | P21: 1548038.5
A22: C2-0280 | B22: Closed | C22: 41912 | D22: CA | E22: 2000000 | F22: 42162 | G22: 42220 | H22: 2015 | I22: Non-Cat | J22: 428616.79 | K22: 0 | L22: 428616.79 | M22: Washer hose failure flooded upper floor and ruined furniture below. | O22: yes | P22: 428616.79
A23: C2-0281 | B23: Closed | C23: 42038 | D23: FL | E23: 4000000 | F23: 42152 | G23: 42223 | H23: 2015 | I23: Non-Cat | J23: 197910.45 | K23: 0 | L23: 197910.45 | M23: Appliance fire damaged kitchen, dining room, and smoke-affected upper-level rooms. | O23: yes | P23: 197910.45
A24: C2-0286 | B24: Closed | C24: 42091 | D24: TX | E24: 10000000 | F24: 42166 | G24: 42240 | H24: 2015 | I24: Non-Cat | J24: 455276.89 | K24: 0 | L24: 455276.89 | M24: Washer hose failure flooded upper floor and ruined furniture below. | O24: yes | P24: 455276.89
... A1090: C2-2283 | B1090: Open | C1090: 43456 | D1090: NY | E1090: 2000000 | F1090: 43560 | G1090: 45563 | H1090: 2019 | I1090: Non-Cat | J1090: 0 | K1090: 88008.56 | L1090: 88008.56 | M1090: Burst pipe flooded several rooms, damaging wood floors and upholstered furniture. | O1090: yes | P1090: 88008.56

Sheet Claim (Cat Personal)
A1: ='Premium Information'!A1 -> Insurer We
A2: ='Premium Information'!A2 -> 2025 Property Per risk Excess of Loss
A3: ='Premium Information'!A3 -> effective date: | B3: ='Premium Information'!B3 -> 45689
A5: Experience information - Personal Property - large losses from cat events
A7: ='Premium Information'!A7 -> Data as of: | B7: ='Premium Information'!B7 -> 45565
A8: ='Premium Information'!A8 -> Currency: | B8: ='Premium Information'!B8 -> USD
A10: Notes: gross incurred losses greater than $250000 for large catastrophe only (from AY 2015 to 2024); paid/outstanding/gross incurred losses include expense and can be greater than policy limit
A12: Claim No. | B12: Open/Closed | C12: Effective Date | D12: Risk Location | E12: Policy Limit | F12: Loss Date | G12: Report Date | H12: AY | I12: Cat/Non-Cat | J12: Paid Loss | K12: Outstanding Loss | L12: Gross Incurred Loss | M12: Description | N12: Cat Type | O12: comments - whether we would write again (yes/no) | P12: restated loss on go forward basis
A13: C2-0244 | B13: Closed | C13: 41925 | D13: NY | E13: 4500000 | F13: 42029 | G13: 42081 | H13: 2015 | I13: Cat | J13: 4189545 | K13: 0 | L13: 4189545 | M13: Severe convective storm tore off roofing, allowing major rain damage to furniture and household goods. | N13: convective storm | O13: yes | P13: 4189545
A14: C2-0292 | B14: Closed | C14: 41998 | D14: CA | E14: 4500000 | F14: 42204 | G14: 42256 | H14: 2015 | I14: Cat | J14: 1012854.1 | K14: 0 | L14: 1012854.1 | M14: Flood entered the residence and submerged most contents, including appliances, furniture, and clothing. | N14: flood | O14: no | P14: 0
A15: C2-0312 | B15: Closed | C15: 42030 | D15: FL | E15: 10000000 | F15: 42181 | G15: 42333 | H15: 2015 | I15: Cat | J15: 1563120.4 | K15: 0 | L15: 1563120.4 | M15: Mudflow after wildfire filled the lower level, severely damaging contents, flooring, and walls. | N15: mudflow | O15: yes | P15: 1563120.4
A16: C2-0313 | B16: Closed | C16: 42190 | D16: CA | E16: 3500000 | F16: 42287 | G16: 42337 | H16: 2015 | I16: Cat | J16: 481456.54 | K16: 0 | L16: 481456.54 | M16: Flood entered the residence and submerged most contents, including appliances, furniture, and clothing. | N16: flood | O16: yes | P16: 481456.54
A17: C2-0323 | B17: Closed | C17: 42075 | D17: NY | E17: 4000000 | F17: 42287 | G17: 42366 | H17: 2015 | I17: Cat | J17: 3011458.8 | K17: 0 | L17: 3011458.8 | M17: Severe convective storm tore off roofing, allowing major rain damage to furniture and household goods. | N17: convective storm | O17: no | P17: 0
A18: C2-0328 | B18: Closed | C18: 41989 | D18: TX | E18: 2500000 | F18: 42324 | G18: 42379 | H18: 2015 | I18: Cat | J18: 691814.82 | K18: 0 | L18: 691814.82 | M18: Earthquake triggered partial collapse, causing severe damage to interiors and nearly all personal belongings. | N18: earthquake | O18: yes | P18: 691814.82
A19: C2-0367 | B19: Closed | C19: 42099 | D19: FL | E19: 4500000 | F19: 42422 | G19: 42496 | H19: 2016 | I19: Cat | J19: 655000.93 | K19: 0 | L19: 655000.93 | M19: Flood entered the residence and submerged most contents, including appliances, furniture, and clothing. | N19: flood | O19: yes | P19: 655000.93
A20: C2-0392 | B20: Closed | C20: 42404 | D20: FL | E20: 4000000 | F20: 42524 | G20: 42560 | H20: 2016 | I20: Cat | J20: 1354817.3 | K20: 0 | L20: 1354817.3 | M20: Mudflow after wildfire filled the lower level, severely damaging contents, flooring, and walls. | N20: mudflow | O20: yes | P20: 1354817.3
A21: C2-0393 | B21: Closed | C21: 42238 | D21: NY | E21: 3500000 | F21: 42451 | G21: 42563 | H21: 2016 | I21: Cat | J21: 1039572.9 | K21: 0 | L21: 1039572.9 | M21: Wildfire destroyed the residence interior, with ember-driven ignition consuming furniture, clothing, and electronics. | N21: wildfire | O21: yes | P21: 1039572.9
A22: C2-0394 | B22: Closed | C22: 42242 | D22: TX | E22: 5000000 | F22: 42286 | G22: 42564 | H22: 2015 | I22: Cat | J22: 1071338.4 | K22: 0 | L22: 1071338.4 | M22: Earthquake caused severe structural cracking and collapse, crushing household contents throughout multiple rooms. | N22: earthquake | O22: yes | P22: 1071338.4
A23: C2-0409 | B23: Closed | C23: 42179 | D23: FL | E23: 3000000 | F23: 42402 | G23: 42610 | H23: 2016 | I23: Cat | J23: 763782.64 | K23: 0 | L23: 763782.64 | M23: Wildfire smoke and suppression water caused severe damage to interiors, appliances, and personal property. | N23: wildfire | O23: yes | P23: 763782.64
A24: C2-0417 | B24: Closed | C24: 42364 | D24: NY | E24: 10000000 | F24: 42455 | G24: 42625 | H24: 2016 | I24: Cat | J24: 662676.07 | K24: 0 | L24: 662676.07 | M24: Flood entered the residence and submerged most contents, including appliances, furniture, and clothing. | N24: flood | O24: yes | P24: 662676.07
... A302: C2-2270 | B302: Open | C302: 44944 | D302: FL | E302: 5000000 | F302: 45286 | G302: 45551 | H302: 2023 | I302: Cat | J302: 0 | K302: 1570133.4 | L302: 1570133.4 | M302: Severe convective storm tore off roofing, allowing major rain damage to furniture and household goods. | N302: convective storm | O302: no | P302: 0

Sheet Rate Change
A1: ='Premium Information'!A1 -> Insurer We
A2: ='Premium Information'!A2 -> 2025 Property Per risk Excess of Loss
A3: ='Premium Information'!A3 -> effective date: | B3: ='Premium Information'!B3 -> 45689
A5: Exposure information - dated rate-change history
A7: ='Premium Information'!A7 -> Data as of: | B7: ='Premium Information'!B7 -> 45565
A8: ='Premium Information'!A8 -> Currency: | B8: ='Premium Information'!B8 -> USD
B10: Rate Change History (2015-2024)
B11: Date | C11: State | D11: Class of business | E11: Rate Change (%)
B12: 42045 | C12: FL | D12: Personal Property | E12: 16.7
B13: 42076 | C13: CA | D13: Personal Property | E13: 23.3
B14: 42238 | C14: TX | D14: Personal Property | E14: 15.2
B15: 42307 | C15: TX | D15: Commercial Property | E15: 9.9
B16: 42328 | C16: CA | D16: Commercial Property | E16: 5.1
B17: 42409 | C17: NY | D17: Commercial Property | E17: 5.7
B18: 42464 | C18: FL | D18: Commercial Property | E18: 6.2
B19: 42617 | C19: TX | D19: Personal Property | E19: 12.7
B20: 42672 | C20: NY | D20: Personal Property | E20: 16.7
B21: 42720 | C21: IL | D21: Personal Property | E21: 18.9
B22: 42844 | C22: NY | D22: Commercial Property | E22: 6.5
B23: 42957 | C23: CA | D23: Commercial Property | E23: 4.8
... B64: 45484 | C64: IL | D64: Commercial Property | E64: 8.3
